<?xml version="1.0" encoding="UTF-8"?>
<testng-results ignored="0" total="66" passed="52" failed="14" skipped="0">
  <reporter-output>
  </reporter-output>
  <suite started-at="2024-03-09T05:07:21Z" name="Gringotts Wizarding Bank" finished-at="2024-03-09T05:08:59Z" duration-ms="98161">
    <groups>
    </groups>
    <test started-at="2024-03-09T05:07:21Z" name="GWB-Tests" finished-at="2024-03-09T05:08:02Z" duration-ms="41335">
      <class name="com.crm.qa.testcases.CustomerLoginFunctionalitiesTest">
        <test-method is-config="true" signature="setUp(java.lang.String)[pri:0, instance:com.crm.qa.testcases.CustomerLoginFunctionalitiesTest@5b367418]" started-at="2024-03-09T10:37:49Z" name="setUp" finished-at="2024-03-09T10:37:52Z" duration-ms="2954" status="PASS">
          <params>
            <param index="0">
              <value>
                <![CDATA[chrome]]>
              </value>
            </param>
          </params>
          <reporter-output>
          </reporter-output>
        </test-method> <!-- setUp -->
        <test-method signature="VerifycustLoginBtnFunctionality()[pri:20, instance:com.crm.qa.testcases.CustomerLoginFunctionalitiesTest@5b367418]" started-at="2024-03-09T10:37:52Z" name="VerifycustLoginBtnFunctionality" finished-at="2024-03-09T10:37:53Z" duration-ms="1188" status="PASS">
          <reporter-output>
          </reporter-output>
        </test-method> <!-- VerifycustLoginBtnFunctionality -->
        <test-method signature="VerifyCustomerLogin()[pri:21, instance:com.crm.qa.testcases.CustomerLoginFunctionalitiesTest@5b367418]" started-at="2024-03-09T10:37:53Z" name="VerifyCustomerLogin" finished-at="2024-03-09T10:37:54Z" duration-ms="1060" status="PASS">
          <reporter-output>
          </reporter-output>
        </test-method> <!-- VerifyCustomerLogin -->
        <test-method signature="depositValidAmount()[pri:23, instance:com.crm.qa.testcases.CustomerLoginFunctionalitiesTest@5b367418]" started-at="2024-03-09T10:37:54Z" name="depositValidAmount" finished-at="2024-03-09T10:37:55Z" duration-ms="981" status="PASS">
          <reporter-output>
          </reporter-output>
        </test-method> <!-- depositValidAmount -->
        <test-method signature="depositInValidAmount()[pri:24, instance:com.crm.qa.testcases.CustomerLoginFunctionalitiesTest@5b367418]" started-at="2024-03-09T10:37:55Z" name="depositInValidAmount" finished-at="2024-03-09T10:37:56Z" duration-ms="754" status="FAIL">
          <exception class="java.lang.AssertionError">
            <message>
              <![CDATA[No warning raised. New issue detected expected [Deposit Successful] but found [Invalid Input]]]>
            </message>
            <full-stacktrace>
              <![CDATA[java.lang.AssertionError: No warning raised. New issue detected expected [Deposit Successful] but found [Invalid Input]
	at org.testng.Assert.fail(Assert.java:93)
	at org.testng.Assert.failNotEquals(Assert.java:512)
	at org.testng.Assert.assertEqualsImpl(Assert.java:134)
	at org.testng.Assert.assertEquals(Assert.java:115)
	at org.testng.Assert.assertEquals(Assert.java:189)
	at com.crm.qa.testcases.CustomerLoginFunctionalitiesTest.depositInValidAmount(CustomerLoginFunctionalitiesTest.java:55)
	at java.base/jdk.internal.reflect.NativeMethodAccessorImpl.invoke0(Native Method)
	at java.base/jdk.internal.reflect.NativeMethodAccessorImpl.invoke(NativeMethodAccessorImpl.java:77)
	at java.base/jdk.internal.reflect.DelegatingMethodAccessorImpl.invoke(DelegatingMethodAccessorImpl.java:43)
	at java.base/java.lang.reflect.Method.invoke(Method.java:568)
	at org.testng.internal.MethodInvocationHelper.invokeMethod(MethodInvocationHelper.java:108)
	at org.testng.internal.Invoker.invokeMethod(Invoker.java:661)
	at org.testng.internal.Invoker.invokeTestMethod(Invoker.java:869)
	at org.testng.internal.Invoker.invokeTestMethods(Invoker.java:1193)
	at org.testng.internal.TestMethodWorker.invokeTestMethods(TestMethodWorker.java:126)
	at org.testng.internal.TestMethodWorker.run(TestMethodWorker.java:109)
	at org.testng.TestRunner.privateRun(TestRunner.java:744)
	at org.testng.TestRunner.run(TestRunner.java:602)
	at org.testng.SuiteRunner.runTest(SuiteRunner.java:380)
	at org.testng.SuiteRunner.runSequentially(SuiteRunner.java:375)
	at org.testng.SuiteRunner.privateRun(SuiteRunner.java:340)
	at org.testng.SuiteRunner.run(SuiteRunner.java:289)
	at org.testng.SuiteRunnerWorker.runSuite(SuiteRunnerWorker.java:52)
	at org.testng.SuiteRunnerWorker.run(SuiteRunnerWorker.java:86)
	at org.testng.TestNG.runSuitesSequentially(TestNG.java:1301)
	at org.testng.TestNG.runSuitesLocally(TestNG.java:1226)
	at org.testng.TestNG.runSuites(TestNG.java:1144)
	at org.testng.TestNG.run(TestNG.java:1115)
	at org.testng.remote.AbstractRemoteTestNG.run(AbstractRemoteTestNG.java:115)
	at org.testng.remote.RemoteTestNG.initAndRun(RemoteTestNG.java:251)
	at org.testng.remote.RemoteTestNG.main(RemoteTestNG.java:77)
]]>
            </full-stacktrace>
          </exception> <!-- java.lang.AssertionError -->
          <reporter-output>
          </reporter-output>
        </test-method> <!-- depositInValidAmount -->
        <test-method signature="depositDecimalAmount()[pri:25, instance:com.crm.qa.testcases.CustomerLoginFunctionalitiesTest@5b367418]" started-at="2024-03-09T10:37:56Z" name="depositDecimalAmount" finished-at="2024-03-09T10:37:56Z" duration-ms="620" status="PASS">
          <reporter-output>
          </reporter-output>
        </test-method> <!-- depositDecimalAmount -->
        <test-method signature="withdrawValidAmount()[pri:26, instance:com.crm.qa.testcases.CustomerLoginFunctionalitiesTest@5b367418]" started-at="2024-03-09T10:37:56Z" name="withdrawValidAmount" finished-at="2024-03-09T10:37:58Z" duration-ms="1290" status="PASS">
          <reporter-output>
          </reporter-output>
        </test-method> <!-- withdrawValidAmount -->
        <test-method signature="withdrawInValidAmount()[pri:27, instance:com.crm.qa.testcases.CustomerLoginFunctionalitiesTest@5b367418]" started-at="2024-03-09T10:37:58Z" name="withdrawInValidAmount" finished-at="2024-03-09T10:37:59Z" duration-ms="859" status="FAIL">
          <exception class="java.lang.AssertionError">
            <message>
              <![CDATA[No warning raised. New issue detected expected [Transaction successful] but found [Invalid Input]]]>
            </message>
            <full-stacktrace>
              <![CDATA[java.lang.AssertionError: No warning raised. New issue detected expected [Transaction successful] but found [Invalid Input]
	at org.testng.Assert.fail(Assert.java:93)
	at org.testng.Assert.failNotEquals(Assert.java:512)
	at org.testng.Assert.assertEqualsImpl(Assert.java:134)
	at org.testng.Assert.assertEquals(Assert.java:115)
	at org.testng.Assert.assertEquals(Assert.java:189)
	at com.crm.qa.testcases.CustomerLoginFunctionalitiesTest.withdrawInValidAmount(CustomerLoginFunctionalitiesTest.java:76)
	at java.base/jdk.internal.reflect.NativeMethodAccessorImpl.invoke0(Native Method)
	at java.base/jdk.internal.reflect.NativeMethodAccessorImpl.invoke(NativeMethodAccessorImpl.java:77)
	at java.base/jdk.internal.reflect.DelegatingMethodAccessorImpl.invoke(DelegatingMethodAccessorImpl.java:43)
	at java.base/java.lang.reflect.Method.invoke(Method.java:568)
	at org.testng.internal.MethodInvocationHelper.invokeMethod(MethodInvocationHelper.java:108)
	at org.testng.internal.Invoker.invokeMethod(Invoker.java:661)
	at org.testng.internal.Invoker.invokeTestMethod(Invoker.java:869)
	at org.testng.internal.Invoker.invokeTestMethods(Invoker.java:1193)
	at org.testng.internal.TestMethodWorker.invokeTestMethods(TestMethodWorker.java:126)
	at org.testng.internal.TestMethodWorker.run(TestMethodWorker.java:109)
	at org.testng.TestRunner.privateRun(TestRunner.java:744)
	at org.testng.TestRunner.run(TestRunner.java:602)
	at org.testng.SuiteRunner.runTest(SuiteRunner.java:380)
	at org.testng.SuiteRunner.runSequentially(SuiteRunner.java:375)
	at org.testng.SuiteRunner.privateRun(SuiteRunner.java:340)
	at org.testng.SuiteRunner.run(SuiteRunner.java:289)
	at org.testng.SuiteRunnerWorker.runSuite(SuiteRunnerWorker.java:52)
	at org.testng.SuiteRunnerWorker.run(SuiteRunnerWorker.java:86)
	at org.testng.TestNG.runSuitesSequentially(TestNG.java:1301)
	at org.testng.TestNG.runSuitesLocally(TestNG.java:1226)
	at org.testng.TestNG.runSuites(TestNG.java:1144)
	at org.testng.TestNG.run(TestNG.java:1115)
	at org.testng.remote.AbstractRemoteTestNG.run(AbstractRemoteTestNG.java:115)
	at org.testng.remote.RemoteTestNG.initAndRun(RemoteTestNG.java:251)
	at org.testng.remote.RemoteTestNG.main(RemoteTestNG.java:77)
]]>
            </full-stacktrace>
          </exception> <!-- java.lang.AssertionError -->
          <reporter-output>
          </reporter-output>
        </test-method> <!-- withdrawInValidAmount -->
        <test-method signature="withdrawDecimalAmount()[pri:28, instance:com.crm.qa.testcases.CustomerLoginFunctionalitiesTest@5b367418]" started-at="2024-03-09T10:37:59Z" name="withdrawDecimalAmount" finished-at="2024-03-09T10:37:59Z" duration-ms="492" status="PASS">
          <reporter-output>
          </reporter-output>
        </test-method> <!-- withdrawDecimalAmount -->
        <test-method signature="withdrawInsufficientAmount()[pri:29, instance:com.crm.qa.testcases.CustomerLoginFunctionalitiesTest@5b367418]" started-at="2024-03-09T10:37:59Z" name="withdrawInsufficientAmount" finished-at="2024-03-09T10:38:00Z" duration-ms="530" status="PASS">
          <reporter-output>
          </reporter-output>
        </test-method> <!-- withdrawInsufficientAmount -->
        <test-method signature="transactionResetFunctionalities()[pri:30, instance:com.crm.qa.testcases.CustomerLoginFunctionalitiesTest@5b367418]" started-at="2024-03-09T10:38:00Z" name="transactionResetFunctionalities" finished-at="2024-03-09T10:38:01Z" duration-ms="1455" status="FAIL">
          <exception class="java.lang.AssertionError">
            <message>
              <![CDATA[No warning raised. Major Issue detected. Balance is resetting, too. expected [Data reset successful] but found [Data reset unsuccessful]]]>
            </message>
            <full-stacktrace>
              <![CDATA[java.lang.AssertionError: No warning raised. Major Issue detected. Balance is resetting, too. expected [Data reset successful] but found [Data reset unsuccessful]
	at org.testng.Assert.fail(Assert.java:93)
	at org.testng.Assert.failNotEquals(Assert.java:512)
	at org.testng.Assert.assertEqualsImpl(Assert.java:134)
	at org.testng.Assert.assertEquals(Assert.java:115)
	at org.testng.Assert.assertEquals(Assert.java:189)
	at com.crm.qa.testcases.CustomerLoginFunctionalitiesTest.transactionResetFunctionalities(CustomerLoginFunctionalitiesTest.java:95)
	at java.base/jdk.internal.reflect.NativeMethodAccessorImpl.invoke0(Native Method)
	at java.base/jdk.internal.reflect.NativeMethodAccessorImpl.invoke(NativeMethodAccessorImpl.java:77)
	at java.base/jdk.internal.reflect.DelegatingMethodAccessorImpl.invoke(DelegatingMethodAccessorImpl.java:43)
	at java.base/java.lang.reflect.Method.invoke(Method.java:568)
	at org.testng.internal.MethodInvocationHelper.invokeMethod(MethodInvocationHelper.java:108)
	at org.testng.internal.Invoker.invokeMethod(Invoker.java:661)
	at org.testng.internal.Invoker.invokeTestMethod(Invoker.java:869)
	at org.testng.internal.Invoker.invokeTestMethods(Invoker.java:1193)
	at org.testng.internal.TestMethodWorker.invokeTestMethods(TestMethodWorker.java:126)
	at org.testng.internal.TestMethodWorker.run(TestMethodWorker.java:109)
	at org.testng.TestRunner.privateRun(TestRunner.java:744)
	at org.testng.TestRunner.run(TestRunner.java:602)
	at org.testng.SuiteRunner.runTest(SuiteRunner.java:380)
	at org.testng.SuiteRunner.runSequentially(SuiteRunner.java:375)
	at org.testng.SuiteRunner.privateRun(SuiteRunner.java:340)
	at org.testng.SuiteRunner.run(SuiteRunner.java:289)
	at org.testng.SuiteRunnerWorker.runSuite(SuiteRunnerWorker.java:52)
	at org.testng.SuiteRunnerWorker.run(SuiteRunnerWorker.java:86)
	at org.testng.TestNG.runSuitesSequentially(TestNG.java:1301)
	at org.testng.TestNG.runSuitesLocally(TestNG.java:1226)
	at org.testng.TestNG.runSuites(TestNG.java:1144)
	at org.testng.TestNG.run(TestNG.java:1115)
	at org.testng.remote.AbstractRemoteTestNG.run(AbstractRemoteTestNG.java:115)
	at org.testng.remote.RemoteTestNG.initAndRun(RemoteTestNG.java:251)
	at org.testng.remote.RemoteTestNG.main(RemoteTestNG.java:77)
]]>
            </full-stacktrace>
          </exception> <!-- java.lang.AssertionError -->
          <reporter-output>
          </reporter-output>
        </test-method> <!-- transactionResetFunctionalities -->
        <test-method signature="transactionBackFunctionalities()[pri:31, instance:com.crm.qa.testcases.CustomerLoginFunctionalitiesTest@5b367418]" started-at="2024-03-09T10:38:01Z" name="transactionBackFunctionalities" finished-at="2024-03-09T10:38:01Z" duration-ms="163" status="PASS">
          <reporter-output>
          </reporter-output>
        </test-method> <!-- transactionBackFunctionalities -->
        <test-method signature="VerifyLogoutFunctionality()[pri:32, instance:com.crm.qa.testcases.CustomerLoginFunctionalitiesTest@5b367418]" started-at="2024-03-09T10:38:01Z" name="VerifyLogoutFunctionality" finished-at="2024-03-09T10:38:01Z" duration-ms="192" status="PASS">
          <reporter-output>
          </reporter-output>
        </test-method> <!-- VerifyLogoutFunctionality -->
        <test-method signature="VerifyPostLogoutFunctionality()[pri:33, instance:com.crm.qa.testcases.CustomerLoginFunctionalitiesTest@5b367418]" started-at="2024-03-09T10:38:01Z" name="VerifyPostLogoutFunctionality" finished-at="2024-03-09T10:38:02Z" duration-ms="221" status="FAIL">
          <exception class="java.lang.AssertionError">
            <message>
              <![CDATA[Customer is able to visit the session after logging out. New issue expected [Customer is not able to visit the session after logging out.] but found [Customer is able to visit the session after logging out. New issue]]]>
            </message>
            <full-stacktrace>
              <![CDATA[java.lang.AssertionError: Customer is able to visit the session after logging out. New issue expected [Customer is not able to visit the session after logging out.] but found [Customer is able to visit the session after logging out. New issue]
	at org.testng.Assert.fail(Assert.java:93)
	at org.testng.Assert.failNotEquals(Assert.java:512)
	at org.testng.Assert.assertEqualsImpl(Assert.java:134)
	at org.testng.Assert.assertEquals(Assert.java:115)
	at org.testng.Assert.assertEquals(Assert.java:189)
	at com.crm.qa.testcases.CustomerLoginFunctionalitiesTest.VerifyPostLogoutFunctionality(CustomerLoginFunctionalitiesTest.java:115)
	at java.base/jdk.internal.reflect.NativeMethodAccessorImpl.invoke0(Native Method)
	at java.base/jdk.internal.reflect.NativeMethodAccessorImpl.invoke(NativeMethodAccessorImpl.java:77)
	at java.base/jdk.internal.reflect.DelegatingMethodAccessorImpl.invoke(DelegatingMethodAccessorImpl.java:43)
	at java.base/java.lang.reflect.Method.invoke(Method.java:568)
	at org.testng.internal.MethodInvocationHelper.invokeMethod(MethodInvocationHelper.java:108)
	at org.testng.internal.Invoker.invokeMethod(Invoker.java:661)
	at org.testng.internal.Invoker.invokeTestMethod(Invoker.java:869)
	at org.testng.internal.Invoker.invokeTestMethods(Invoker.java:1193)
	at org.testng.internal.TestMethodWorker.invokeTestMethods(TestMethodWorker.java:126)
	at org.testng.internal.TestMethodWorker.run(TestMethodWorker.java:109)
	at org.testng.TestRunner.privateRun(TestRunner.java:744)
	at org.testng.TestRunner.run(TestRunner.java:602)
	at org.testng.SuiteRunner.runTest(SuiteRunner.java:380)
	at org.testng.SuiteRunner.runSequentially(SuiteRunner.java:375)
	at org.testng.SuiteRunner.privateRun(SuiteRunner.java:340)
	at org.testng.SuiteRunner.run(SuiteRunner.java:289)
	at org.testng.SuiteRunnerWorker.runSuite(SuiteRunnerWorker.java:52)
	at org.testng.SuiteRunnerWorker.run(SuiteRunnerWorker.java:86)
	at org.testng.TestNG.runSuitesSequentially(TestNG.java:1301)
	at org.testng.TestNG.runSuitesLocally(TestNG.java:1226)
	at org.testng.TestNG.runSuites(TestNG.java:1144)
	at org.testng.TestNG.run(TestNG.java:1115)
	at org.testng.remote.AbstractRemoteTestNG.run(AbstractRemoteTestNG.java:115)
	at org.testng.remote.RemoteTestNG.initAndRun(RemoteTestNG.java:251)
	at org.testng.remote.RemoteTestNG.main(RemoteTestNG.java:77)
]]>
            </full-stacktrace>
          </exception> <!-- java.lang.AssertionError -->
          <reporter-output>
          </reporter-output>
        </test-method> <!-- VerifyPostLogoutFunctionality -->
        <test-method signature="VerifyredirectToNonaccessablePageFunctionality()[pri:34, instance:com.crm.qa.testcases.CustomerLoginFunctionalitiesTest@5b367418]" started-at="2024-03-09T10:38:02Z" name="VerifyredirectToNonaccessablePageFunctionality" finished-at="2024-03-09T10:38:02Z" duration-ms="215" status="FAIL">
          <exception class="java.lang.AssertionError">
            <message>
              <![CDATA[Customer is able to access the account after logging out. New issue expected [Customer is not access the account after logging out.] but found [Customer is able to access the account after logging out. New issue]]]>
            </message>
            <full-stacktrace>
              <![CDATA[java.lang.AssertionError: Customer is able to access the account after logging out. New issue expected [Customer is not access the account after logging out.] but found [Customer is able to access the account after logging out. New issue]
	at org.testng.Assert.fail(Assert.java:93)
	at org.testng.Assert.failNotEquals(Assert.java:512)
	at org.testng.Assert.assertEqualsImpl(Assert.java:134)
	at org.testng.Assert.assertEquals(Assert.java:115)
	at org.testng.Assert.assertEquals(Assert.java:189)
	at com.crm.qa.testcases.CustomerLoginFunctionalitiesTest.VerifyredirectToNonaccessablePageFunctionality(CustomerLoginFunctionalitiesTest.java:120)
	at java.base/jdk.internal.reflect.NativeMethodAccessorImpl.invoke0(Native Method)
	at java.base/jdk.internal.reflect.NativeMethodAccessorImpl.invoke(NativeMethodAccessorImpl.java:77)
	at java.base/jdk.internal.reflect.DelegatingMethodAccessorImpl.invoke(DelegatingMethodAccessorImpl.java:43)
	at java.base/java.lang.reflect.Method.invoke(Method.java:568)
	at org.testng.internal.MethodInvocationHelper.invokeMethod(MethodInvocationHelper.java:108)
	at org.testng.internal.Invoker.invokeMethod(Invoker.java:661)
	at org.testng.internal.Invoker.invokeTestMethod(Invoker.java:869)
	at org.testng.internal.Invoker.invokeTestMethods(Invoker.java:1193)
	at org.testng.internal.TestMethodWorker.invokeTestMethods(TestMethodWorker.java:126)
	at org.testng.internal.TestMethodWorker.run(TestMethodWorker.java:109)
	at org.testng.TestRunner.privateRun(TestRunner.java:744)
	at org.testng.TestRunner.run(TestRunner.java:602)
	at org.testng.SuiteRunner.runTest(SuiteRunner.java:380)
	at org.testng.SuiteRunner.runSequentially(SuiteRunner.java:375)
	at org.testng.SuiteRunner.privateRun(SuiteRunner.java:340)
	at org.testng.SuiteRunner.run(SuiteRunner.java:289)
	at org.testng.SuiteRunnerWorker.runSuite(SuiteRunnerWorker.java:52)
	at org.testng.SuiteRunnerWorker.run(SuiteRunnerWorker.java:86)
	at org.testng.TestNG.runSuitesSequentially(TestNG.java:1301)
	at org.testng.TestNG.runSuitesLocally(TestNG.java:1226)
	at org.testng.TestNG.runSuites(TestNG.java:1144)
	at org.testng.TestNG.run(TestNG.java:1115)
	at org.testng.remote.AbstractRemoteTestNG.run(AbstractRemoteTestNG.java:115)
	at org.testng.remote.RemoteTestNG.initAndRun(RemoteTestNG.java:251)
	at org.testng.remote.RemoteTestNG.main(RemoteTestNG.java:77)
]]>
            </full-stacktrace>
          </exception> <!-- java.lang.AssertionError -->
          <reporter-output>
          </reporter-output>
        </test-method> <!-- VerifyredirectToNonaccessablePageFunctionality -->
        <test-method is-config="true" signature="tearDown()[pri:0, instance:com.crm.qa.testcases.CustomerLoginFunctionalitiesTest@5b367418]" started-at="2024-03-09T10:38:02Z" name="tearDown" finished-at="2024-03-09T10:38:02Z" duration-ms="473" status="PASS">
          <reporter-output>
          </reporter-output>
        </test-method> <!-- tearDown -->
      </class> <!-- com.crm.qa.testcases.CustomerLoginFunctionalitiesTest -->
      <class name="com.crm.qa.testcases.HomeDashBoardTest">
        <test-method is-config="true" signature="setUp(java.lang.String)[pri:0, instance:com.crm.qa.testcases.HomeDashBoardTest@3697186]" started-at="2024-03-09T10:37:21Z" name="setUp" finished-at="2024-03-09T10:37:28Z" duration-ms="7101" status="PASS">
          <params>
            <param index="0">
              <value>
                <![CDATA[chrome]]>
              </value>
            </param>
          </params>
          <reporter-output>
          </reporter-output>
        </test-method> <!-- setUp -->
        <test-method signature="VerifyTitle()[pri:1, instance:com.crm.qa.testcases.HomeDashBoardTest@3697186]" started-at="2024-03-09T10:37:28Z" name="VerifyTitle" finished-at="2024-03-09T10:37:28Z" duration-ms="317" status="PASS">
          <reporter-output>
          </reporter-output>
        </test-method> <!-- VerifyTitle -->
        <test-method signature="VerifyHomeBtn()[pri:2, instance:com.crm.qa.testcases.HomeDashBoardTest@3697186]" started-at="2024-03-09T10:37:28Z" name="VerifyHomeBtn" finished-at="2024-03-09T10:37:29Z" duration-ms="123" status="PASS">
          <reporter-output>
          </reporter-output>
        </test-method> <!-- VerifyHomeBtn -->
        <test-method signature="VerifycustLoginBtn()[pri:3, instance:com.crm.qa.testcases.HomeDashBoardTest@3697186]" started-at="2024-03-09T10:37:29Z" name="VerifycustLoginBtn" finished-at="2024-03-09T10:37:29Z" duration-ms="87" status="PASS">
          <reporter-output>
          </reporter-output>
        </test-method> <!-- VerifycustLoginBtn -->
        <test-method signature="VerifybankManagerLoginBtn()[pri:4, instance:com.crm.qa.testcases.HomeDashBoardTest@3697186]" started-at="2024-03-09T10:37:29Z" name="VerifybankManagerLoginBtn" finished-at="2024-03-09T10:37:29Z" duration-ms="73" status="PASS">
          <reporter-output>
          </reporter-output>
        </test-method> <!-- VerifybankManagerLoginBtn -->
        <test-method signature="VerifyHomeBtnFunctionality()[pri:5, instance:com.crm.qa.testcases.HomeDashBoardTest@3697186]" started-at="2024-03-09T10:37:29Z" name="VerifyHomeBtnFunctionality" finished-at="2024-03-09T10:37:29Z" duration-ms="299" status="PASS">
          <reporter-output>
          </reporter-output>
        </test-method> <!-- VerifyHomeBtnFunctionality -->
        <test-method signature="VerifycustLoginBtnFunctionality()[pri:6, instance:com.crm.qa.testcases.HomeDashBoardTest@3697186]" started-at="2024-03-09T10:37:29Z" name="VerifycustLoginBtnFunctionality" finished-at="2024-03-09T10:37:30Z" duration-ms="989" status="PASS">
          <reporter-output>
          </reporter-output>
        </test-method> <!-- VerifycustLoginBtnFunctionality -->
        <test-method signature="VerifybankManagerLoginBtnFunctionality()[pri:7, instance:com.crm.qa.testcases.HomeDashBoardTest@3697186]" started-at="2024-03-09T10:37:30Z" name="VerifybankManagerLoginBtnFunctionality" finished-at="2024-03-09T10:37:30Z" duration-ms="474" status="PASS">
          <reporter-output>
          </reporter-output>
        </test-method> <!-- VerifybankManagerLoginBtnFunctionality -->
        <test-method signature="VerifyNonAccountCustomersFunctionality()[pri:8, instance:com.crm.qa.testcases.HomeDashBoardTest@3697186]" started-at="2024-03-09T10:37:30Z" name="VerifyNonAccountCustomersFunctionality" finished-at="2024-03-09T10:37:33Z" duration-ms="2993" status="PASS">
          <reporter-output>
          </reporter-output>
        </test-method> <!-- VerifyNonAccountCustomersFunctionality -->
        <test-method is-config="true" signature="tearDown()[pri:0, instance:com.crm.qa.testcases.HomeDashBoardTest@3697186]" started-at="2024-03-09T10:37:33Z" name="tearDown" finished-at="2024-03-09T10:37:34Z" duration-ms="449" status="PASS">
          <reporter-output>
          </reporter-output>
        </test-method> <!-- tearDown -->
      </class> <!-- com.crm.qa.testcases.HomeDashBoardTest -->
      <class name="com.crm.qa.testcases.BankManagerLoginFunctionalitiesTest">
        <test-method is-config="true" signature="setUp(java.lang.String)[pri:0, instance:com.crm.qa.testcases.BankManagerLoginFunctionalitiesTest@1583741e]" started-at="2024-03-09T10:37:34Z" name="setUp" finished-at="2024-03-09T10:37:37Z" duration-ms="2806" status="PASS">
          <params>
            <param index="0">
              <value>
                <![CDATA[chrome]]>
              </value>
            </param>
          </params>
          <reporter-output>
          </reporter-output>
        </test-method> <!-- setUp -->
        <test-method signature="VerifyBankManagerLoginBtnFunctionality()[pri:9, instance:com.crm.qa.testcases.BankManagerLoginFunctionalitiesTest@1583741e]" started-at="2024-03-09T10:37:37Z" name="VerifyBankManagerLoginBtnFunctionality" finished-at="2024-03-09T10:37:38Z" duration-ms="1024" status="PASS">
          <reporter-output>
          </reporter-output>
        </test-method> <!-- VerifyBankManagerLoginBtnFunctionality -->
        <test-method signature="VerifyBankManagerLogin()[pri:10, instance:com.crm.qa.testcases.BankManagerLoginFunctionalitiesTest@1583741e]" started-at="2024-03-09T10:37:38Z" name="VerifyBankManagerLogin" finished-at="2024-03-09T10:37:39Z" duration-ms="1389" status="PASS">
          <reporter-output>
          </reporter-output>
        </test-method> <!-- VerifyBankManagerLogin -->
        <test-method signature="VerifyInvalidFnameBankManagerLogin()[pri:11, instance:com.crm.qa.testcases.BankManagerLoginFunctionalitiesTest@1583741e]" started-at="2024-03-09T10:37:39Z" name="VerifyInvalidFnameBankManagerLogin" finished-at="2024-03-09T10:37:40Z" duration-ms="1030" status="FAIL">
          <exception class="java.lang.AssertionError">
            <message>
              <![CDATA[First name is containing special characters and numbers. New issue expected [Pop-up validation: Unexpected or no success message] but found [Pop-up validation: Customer added successfully]]]>
            </message>
            <full-stacktrace>
              <![CDATA[java.lang.AssertionError: First name is containing special characters and numbers. New issue expected [Pop-up validation: Unexpected or no success message] but found [Pop-up validation: Customer added successfully]
	at org.testng.Assert.fail(Assert.java:93)
	at org.testng.Assert.failNotEquals(Assert.java:512)
	at org.testng.Assert.assertEqualsImpl(Assert.java:134)
	at org.testng.Assert.assertEquals(Assert.java:115)
	at org.testng.Assert.assertEquals(Assert.java:189)
	at com.crm.qa.testcases.BankManagerLoginFunctionalitiesTest.VerifyInvalidFnameBankManagerLogin(BankManagerLoginFunctionalitiesTest.java:44)
	at java.base/jdk.internal.reflect.NativeMethodAccessorImpl.invoke0(Native Method)
	at java.base/jdk.internal.reflect.NativeMethodAccessorImpl.invoke(NativeMethodAccessorImpl.java:77)
	at java.base/jdk.internal.reflect.DelegatingMethodAccessorImpl.invoke(DelegatingMethodAccessorImpl.java:43)
	at java.base/java.lang.reflect.Method.invoke(Method.java:568)
	at org.testng.internal.MethodInvocationHelper.invokeMethod(MethodInvocationHelper.java:108)
	at org.testng.internal.Invoker.invokeMethod(Invoker.java:661)
	at org.testng.internal.Invoker.invokeTestMethod(Invoker.java:869)
	at org.testng.internal.Invoker.invokeTestMethods(Invoker.java:1193)
	at org.testng.internal.TestMethodWorker.invokeTestMethods(TestMethodWorker.java:126)
	at org.testng.internal.TestMethodWorker.run(TestMethodWorker.java:109)
	at org.testng.TestRunner.privateRun(TestRunner.java:744)
	at org.testng.TestRunner.run(TestRunner.java:602)
	at org.testng.SuiteRunner.runTest(SuiteRunner.java:380)
	at org.testng.SuiteRunner.runSequentially(SuiteRunner.java:375)
	at org.testng.SuiteRunner.privateRun(SuiteRunner.java:340)
	at org.testng.SuiteRunner.run(SuiteRunner.java:289)
	at org.testng.SuiteRunnerWorker.runSuite(SuiteRunnerWorker.java:52)
	at org.testng.SuiteRunnerWorker.run(SuiteRunnerWorker.java:86)
	at org.testng.TestNG.runSuitesSequentially(TestNG.java:1301)
	at org.testng.TestNG.runSuitesLocally(TestNG.java:1226)
	at org.testng.TestNG.runSuites(TestNG.java:1144)
	at org.testng.TestNG.run(TestNG.java:1115)
	at org.testng.remote.AbstractRemoteTestNG.run(AbstractRemoteTestNG.java:115)
	at org.testng.remote.RemoteTestNG.initAndRun(RemoteTestNG.java:251)
	at org.testng.remote.RemoteTestNG.main(RemoteTestNG.java:77)
]]>
            </full-stacktrace>
          </exception> <!-- java.lang.AssertionError -->
          <reporter-output>
          </reporter-output>
        </test-method> <!-- VerifyInvalidFnameBankManagerLogin -->
        <test-method signature="VerifyInvalidLnameBankManagerLogin()[pri:12, instance:com.crm.qa.testcases.BankManagerLoginFunctionalitiesTest@1583741e]" started-at="2024-03-09T10:37:40Z" name="VerifyInvalidLnameBankManagerLogin" finished-at="2024-03-09T10:37:41Z" duration-ms="890" status="FAIL">
          <exception class="java.lang.AssertionError">
            <message>
              <![CDATA[Last name is containing special characters and numbers. New issue expected [Pop-up validation: Unexpected or no success message] but found [Pop-up validation: Customer added successfully]]]>
            </message>
            <full-stacktrace>
              <![CDATA[java.lang.AssertionError: Last name is containing special characters and numbers. New issue expected [Pop-up validation: Unexpected or no success message] but found [Pop-up validation: Customer added successfully]
	at org.testng.Assert.fail(Assert.java:93)
	at org.testng.Assert.failNotEquals(Assert.java:512)
	at org.testng.Assert.assertEqualsImpl(Assert.java:134)
	at org.testng.Assert.assertEquals(Assert.java:115)
	at org.testng.Assert.assertEquals(Assert.java:189)
	at com.crm.qa.testcases.BankManagerLoginFunctionalitiesTest.VerifyInvalidLnameBankManagerLogin(BankManagerLoginFunctionalitiesTest.java:49)
	at java.base/jdk.internal.reflect.NativeMethodAccessorImpl.invoke0(Native Method)
	at java.base/jdk.internal.reflect.NativeMethodAccessorImpl.invoke(NativeMethodAccessorImpl.java:77)
	at java.base/jdk.internal.reflect.DelegatingMethodAccessorImpl.invoke(DelegatingMethodAccessorImpl.java:43)
	at java.base/java.lang.reflect.Method.invoke(Method.java:568)
	at org.testng.internal.MethodInvocationHelper.invokeMethod(MethodInvocationHelper.java:108)
	at org.testng.internal.Invoker.invokeMethod(Invoker.java:661)
	at org.testng.internal.Invoker.invokeTestMethod(Invoker.java:869)
	at org.testng.internal.Invoker.invokeTestMethods(Invoker.java:1193)
	at org.testng.internal.TestMethodWorker.invokeTestMethods(TestMethodWorker.java:126)
	at org.testng.internal.TestMethodWorker.run(TestMethodWorker.java:109)
	at org.testng.TestRunner.privateRun(TestRunner.java:744)
	at org.testng.TestRunner.run(TestRunner.java:602)
	at org.testng.SuiteRunner.runTest(SuiteRunner.java:380)
	at org.testng.SuiteRunner.runSequentially(SuiteRunner.java:375)
	at org.testng.SuiteRunner.privateRun(SuiteRunner.java:340)
	at org.testng.SuiteRunner.run(SuiteRunner.java:289)
	at org.testng.SuiteRunnerWorker.runSuite(SuiteRunnerWorker.java:52)
	at org.testng.SuiteRunnerWorker.run(SuiteRunnerWorker.java:86)
	at org.testng.TestNG.runSuitesSequentially(TestNG.java:1301)
	at org.testng.TestNG.runSuitesLocally(TestNG.java:1226)
	at org.testng.TestNG.runSuites(TestNG.java:1144)
	at org.testng.TestNG.run(TestNG.java:1115)
	at org.testng.remote.AbstractRemoteTestNG.run(AbstractRemoteTestNG.java:115)
	at org.testng.remote.RemoteTestNG.initAndRun(RemoteTestNG.java:251)
	at org.testng.remote.RemoteTestNG.main(RemoteTestNG.java:77)
]]>
            </full-stacktrace>
          </exception> <!-- java.lang.AssertionError -->
          <reporter-output>
          </reporter-output>
        </test-method> <!-- VerifyInvalidLnameBankManagerLogin -->
        <test-method signature="VerifyEmptyFieldBankManagerLogin()[pri:13, instance:com.crm.qa.testcases.BankManagerLoginFunctionalitiesTest@1583741e]" started-at="2024-03-09T10:37:41Z" name="VerifyEmptyFieldBankManagerLogin" finished-at="2024-03-09T10:37:43Z" duration-ms="1664" status="PASS">
          <reporter-output>
          </reporter-output>
        </test-method> <!-- VerifyEmptyFieldBankManagerLogin -->
        <test-method signature="VerifyDuplicateBankManagerLogin()[pri:14, instance:com.crm.qa.testcases.BankManagerLoginFunctionalitiesTest@1583741e]" started-at="2024-03-09T10:37:43Z" name="VerifyDuplicateBankManagerLogin" finished-at="2024-03-09T10:37:44Z" duration-ms="1157" status="PASS">
          <reporter-output>
          </reporter-output>
        </test-method> <!-- VerifyDuplicateBankManagerLogin -->
        <test-method signature="VerifyOpenAccountFunctionality()[pri:15, instance:com.crm.qa.testcases.BankManagerLoginFunctionalitiesTest@1583741e]" started-at="2024-03-09T10:37:44Z" name="VerifyOpenAccountFunctionality" finished-at="2024-03-09T10:37:45Z" duration-ms="1424" status="PASS">
          <reporter-output>
          </reporter-output>
        </test-method> <!-- VerifyOpenAccountFunctionality -->
        <test-method signature="searchCustomersFunctionalityByName()[pri:16, instance:com.crm.qa.testcases.BankManagerLoginFunctionalitiesTest@1583741e]" started-at="2024-03-09T10:37:45Z" name="searchCustomersFunctionalityByName" finished-at="2024-03-09T10:37:47Z" duration-ms="1263" status="PASS">
          <reporter-output>
          </reporter-output>
        </test-method> <!-- searchCustomersFunctionalityByName -->
        <test-method signature="searchCustomersFunctionalityByID()[pri:17, instance:com.crm.qa.testcases.BankManagerLoginFunctionalitiesTest@1583741e]" started-at="2024-03-09T10:37:47Z" name="searchCustomersFunctionalityByID" finished-at="2024-03-09T10:37:47Z" duration-ms="471" status="PASS">
          <reporter-output>
          </reporter-output>
        </test-method> <!-- searchCustomersFunctionalityByID -->
        <test-method signature="searchCustomersFunctionalityByPostCode()[pri:18, instance:com.crm.qa.testcases.BankManagerLoginFunctionalitiesTest@1583741e]" started-at="2024-03-09T10:37:47Z" name="searchCustomersFunctionalityByPostCode" finished-at="2024-03-09T10:37:47Z" duration-ms="441" status="PASS">
          <reporter-output>
          </reporter-output>
        </test-method> <!-- searchCustomersFunctionalityByPostCode -->
        <test-method signature="deleteCustomerFunctionality()[pri:19, instance:com.crm.qa.testcases.BankManagerLoginFunctionalitiesTest@1583741e]" started-at="2024-03-09T10:37:47Z" name="deleteCustomerFunctionality" finished-at="2024-03-09T10:37:49Z" duration-ms="1032" status="PASS">
          <reporter-output>
          </reporter-output>
        </test-method> <!-- deleteCustomerFunctionality -->
        <test-method is-config="true" signature="tearDown()[pri:0, instance:com.crm.qa.testcases.BankManagerLoginFunctionalitiesTest@1583741e]" started-at="2024-03-09T10:37:49Z" name="tearDown" finished-at="2024-03-09T10:37:49Z" duration-ms="272" status="PASS">
          <reporter-output>
          </reporter-output>
        </test-method> <!-- tearDown -->
      </class> <!-- com.crm.qa.testcases.BankManagerLoginFunctionalitiesTest -->
    </test> <!-- GWB-Tests -->
    <test started-at="2024-03-09T05:08:02Z" name="GWB-Tests-Firefox" finished-at="2024-03-09T05:08:59Z" duration-ms="56633">
      <class name="com.crm.qa.testcases.CustomerLoginFunctionalitiesTest">
        <test-method is-config="true" signature="setUp(java.lang.String)[pri:0, instance:com.crm.qa.testcases.CustomerLoginFunctionalitiesTest@2421cc4]" started-at="2024-03-09T10:38:40Z" name="setUp" finished-at="2024-03-09T10:38:47Z" duration-ms="7321" status="PASS">
          <params>
            <param index="0">
              <value>
                <![CDATA[firefox]]>
              </value>
            </param>
          </params>
          <reporter-output>
          </reporter-output>
        </test-method> <!-- setUp -->
        <test-method signature="VerifycustLoginBtnFunctionality()[pri:20, instance:com.crm.qa.testcases.CustomerLoginFunctionalitiesTest@2421cc4]" started-at="2024-03-09T10:38:47Z" name="VerifycustLoginBtnFunctionality" finished-at="2024-03-09T10:38:48Z" duration-ms="977" status="PASS">
          <reporter-output>
          </reporter-output>
        </test-method> <!-- VerifycustLoginBtnFunctionality -->
        <test-method signature="VerifyCustomerLogin()[pri:21, instance:com.crm.qa.testcases.CustomerLoginFunctionalitiesTest@2421cc4]" started-at="2024-03-09T10:38:48Z" name="VerifyCustomerLogin" finished-at="2024-03-09T10:38:49Z" duration-ms="1001" status="PASS">
          <reporter-output>
          </reporter-output>
        </test-method> <!-- VerifyCustomerLogin -->
        <test-method signature="depositValidAmount()[pri:23, instance:com.crm.qa.testcases.CustomerLoginFunctionalitiesTest@2421cc4]" started-at="2024-03-09T10:38:49Z" name="depositValidAmount" finished-at="2024-03-09T10:38:50Z" duration-ms="645" status="PASS">
          <reporter-output>
          </reporter-output>
        </test-method> <!-- depositValidAmount -->
        <test-method signature="depositInValidAmount()[pri:24, instance:com.crm.qa.testcases.CustomerLoginFunctionalitiesTest@2421cc4]" started-at="2024-03-09T10:38:50Z" name="depositInValidAmount" finished-at="2024-03-09T10:38:50Z" duration-ms="589" status="FAIL">
          <exception class="java.lang.AssertionError">
            <message>
              <![CDATA[No warning raised. New issue detected expected [Deposit Successful] but found [Invalid Input]]]>
            </message>
            <full-stacktrace>
              <![CDATA[java.lang.AssertionError: No warning raised. New issue detected expected [Deposit Successful] but found [Invalid Input]
	at org.testng.Assert.fail(Assert.java:93)
	at org.testng.Assert.failNotEquals(Assert.java:512)
	at org.testng.Assert.assertEqualsImpl(Assert.java:134)
	at org.testng.Assert.assertEquals(Assert.java:115)
	at org.testng.Assert.assertEquals(Assert.java:189)
	at com.crm.qa.testcases.CustomerLoginFunctionalitiesTest.depositInValidAmount(CustomerLoginFunctionalitiesTest.java:55)
	at java.base/jdk.internal.reflect.NativeMethodAccessorImpl.invoke0(Native Method)
	at java.base/jdk.internal.reflect.NativeMethodAccessorImpl.invoke(NativeMethodAccessorImpl.java:77)
	at java.base/jdk.internal.reflect.DelegatingMethodAccessorImpl.invoke(DelegatingMethodAccessorImpl.java:43)
	at java.base/java.lang.reflect.Method.invoke(Method.java:568)
	at org.testng.internal.MethodInvocationHelper.invokeMethod(MethodInvocationHelper.java:108)
	at org.testng.internal.Invoker.invokeMethod(Invoker.java:661)
	at org.testng.internal.Invoker.invokeTestMethod(Invoker.java:869)
	at org.testng.internal.Invoker.invokeTestMethods(Invoker.java:1193)
	at org.testng.internal.TestMethodWorker.invokeTestMethods(TestMethodWorker.java:126)
	at org.testng.internal.TestMethodWorker.run(TestMethodWorker.java:109)
	at org.testng.TestRunner.privateRun(TestRunner.java:744)
	at org.testng.TestRunner.run(TestRunner.java:602)
	at org.testng.SuiteRunner.runTest(SuiteRunner.java:380)
	at org.testng.SuiteRunner.runSequentially(SuiteRunner.java:375)
	at org.testng.SuiteRunner.privateRun(SuiteRunner.java:340)
	at org.testng.SuiteRunner.run(SuiteRunner.java:289)
	at org.testng.SuiteRunnerWorker.runSuite(SuiteRunnerWorker.java:52)
	at org.testng.SuiteRunnerWorker.run(SuiteRunnerWorker.java:86)
	at org.testng.TestNG.runSuitesSequentially(TestNG.java:1301)
	at org.testng.TestNG.runSuitesLocally(TestNG.java:1226)
	at org.testng.TestNG.runSuites(TestNG.java:1144)
	at org.testng.TestNG.run(TestNG.java:1115)
	at org.testng.remote.AbstractRemoteTestNG.run(AbstractRemoteTestNG.java:115)
	at org.testng.remote.RemoteTestNG.initAndRun(RemoteTestNG.java:251)
	at org.testng.remote.RemoteTestNG.main(RemoteTestNG.java:77)
]]>
            </full-stacktrace>
          </exception> <!-- java.lang.AssertionError -->
          <reporter-output>
          </reporter-output>
        </test-method> <!-- depositInValidAmount -->
        <test-method signature="depositDecimalAmount()[pri:25, instance:com.crm.qa.testcases.CustomerLoginFunctionalitiesTest@2421cc4]" started-at="2024-03-09T10:38:50Z" name="depositDecimalAmount" finished-at="2024-03-09T10:38:51Z" duration-ms="627" status="PASS">
          <reporter-output>
          </reporter-output>
        </test-method> <!-- depositDecimalAmount -->
        <test-method signature="withdrawValidAmount()[pri:26, instance:com.crm.qa.testcases.CustomerLoginFunctionalitiesTest@2421cc4]" started-at="2024-03-09T10:38:51Z" name="withdrawValidAmount" finished-at="2024-03-09T10:38:53Z" duration-ms="2210" status="PASS">
          <reporter-output>
          </reporter-output>
        </test-method> <!-- withdrawValidAmount -->
        <test-method signature="withdrawInValidAmount()[pri:27, instance:com.crm.qa.testcases.CustomerLoginFunctionalitiesTest@2421cc4]" started-at="2024-03-09T10:38:53Z" name="withdrawInValidAmount" finished-at="2024-03-09T10:38:55Z" duration-ms="2159" status="FAIL">
          <exception class="java.lang.AssertionError">
            <message>
              <![CDATA[No warning raised. New issue detected expected [Transaction successful] but found [Invalid Input]]]>
            </message>
            <full-stacktrace>
              <![CDATA[java.lang.AssertionError: No warning raised. New issue detected expected [Transaction successful] but found [Invalid Input]
	at org.testng.Assert.fail(Assert.java:93)
	at org.testng.Assert.failNotEquals(Assert.java:512)
	at org.testng.Assert.assertEqualsImpl(Assert.java:134)
	at org.testng.Assert.assertEquals(Assert.java:115)
	at org.testng.Assert.assertEquals(Assert.java:189)
	at com.crm.qa.testcases.CustomerLoginFunctionalitiesTest.withdrawInValidAmount(CustomerLoginFunctionalitiesTest.java:76)
	at java.base/jdk.internal.reflect.NativeMethodAccessorImpl.invoke0(Native Method)
	at java.base/jdk.internal.reflect.NativeMethodAccessorImpl.invoke(NativeMethodAccessorImpl.java:77)
	at java.base/jdk.internal.reflect.DelegatingMethodAccessorImpl.invoke(DelegatingMethodAccessorImpl.java:43)
	at java.base/java.lang.reflect.Method.invoke(Method.java:568)
	at org.testng.internal.MethodInvocationHelper.invokeMethod(MethodInvocationHelper.java:108)
	at org.testng.internal.Invoker.invokeMethod(Invoker.java:661)
	at org.testng.internal.Invoker.invokeTestMethod(Invoker.java:869)
	at org.testng.internal.Invoker.invokeTestMethods(Invoker.java:1193)
	at org.testng.internal.TestMethodWorker.invokeTestMethods(TestMethodWorker.java:126)
	at org.testng.internal.TestMethodWorker.run(TestMethodWorker.java:109)
	at org.testng.TestRunner.privateRun(TestRunner.java:744)
	at org.testng.TestRunner.run(TestRunner.java:602)
	at org.testng.SuiteRunner.runTest(SuiteRunner.java:380)
	at org.testng.SuiteRunner.runSequentially(SuiteRunner.java:375)
	at org.testng.SuiteRunner.privateRun(SuiteRunner.java:340)
	at org.testng.SuiteRunner.run(SuiteRunner.java:289)
	at org.testng.SuiteRunnerWorker.runSuite(SuiteRunnerWorker.java:52)
	at org.testng.SuiteRunnerWorker.run(SuiteRunnerWorker.java:86)
	at org.testng.TestNG.runSuitesSequentially(TestNG.java:1301)
	at org.testng.TestNG.runSuitesLocally(TestNG.java:1226)
	at org.testng.TestNG.runSuites(TestNG.java:1144)
	at org.testng.TestNG.run(TestNG.java:1115)
	at org.testng.remote.AbstractRemoteTestNG.run(AbstractRemoteTestNG.java:115)
	at org.testng.remote.RemoteTestNG.initAndRun(RemoteTestNG.java:251)
	at org.testng.remote.RemoteTestNG.main(RemoteTestNG.java:77)
]]>
            </full-stacktrace>
          </exception> <!-- java.lang.AssertionError -->
          <reporter-output>
          </reporter-output>
        </test-method> <!-- withdrawInValidAmount -->
        <test-method signature="withdrawDecimalAmount()[pri:28, instance:com.crm.qa.testcases.CustomerLoginFunctionalitiesTest@2421cc4]" started-at="2024-03-09T10:38:55Z" name="withdrawDecimalAmount" finished-at="2024-03-09T10:38:56Z" duration-ms="591" status="PASS">
          <reporter-output>
          </reporter-output>
        </test-method> <!-- withdrawDecimalAmount -->
        <test-method signature="withdrawInsufficientAmount()[pri:29, instance:com.crm.qa.testcases.CustomerLoginFunctionalitiesTest@2421cc4]" started-at="2024-03-09T10:38:56Z" name="withdrawInsufficientAmount" finished-at="2024-03-09T10:38:56Z" duration-ms="578" status="PASS">
          <reporter-output>
          </reporter-output>
        </test-method> <!-- withdrawInsufficientAmount -->
        <test-method signature="transactionResetFunctionalities()[pri:30, instance:com.crm.qa.testcases.CustomerLoginFunctionalitiesTest@2421cc4]" started-at="2024-03-09T10:38:56Z" name="transactionResetFunctionalities" finished-at="2024-03-09T10:38:57Z" duration-ms="880" status="FAIL">
          <exception class="java.lang.AssertionError">
            <message>
              <![CDATA[No warning raised. Major Issue detected. Balance is resetting, too. expected [Data reset successful] but found [Data reset unsuccessful]]]>
            </message>
            <full-stacktrace>
              <![CDATA[java.lang.AssertionError: No warning raised. Major Issue detected. Balance is resetting, too. expected [Data reset successful] but found [Data reset unsuccessful]
	at org.testng.Assert.fail(Assert.java:93)
	at org.testng.Assert.failNotEquals(Assert.java:512)
	at org.testng.Assert.assertEqualsImpl(Assert.java:134)
	at org.testng.Assert.assertEquals(Assert.java:115)
	at org.testng.Assert.assertEquals(Assert.java:189)
	at com.crm.qa.testcases.CustomerLoginFunctionalitiesTest.transactionResetFunctionalities(CustomerLoginFunctionalitiesTest.java:95)
	at java.base/jdk.internal.reflect.NativeMethodAccessorImpl.invoke0(Native Method)
	at java.base/jdk.internal.reflect.NativeMethodAccessorImpl.invoke(NativeMethodAccessorImpl.java:77)
	at java.base/jdk.internal.reflect.DelegatingMethodAccessorImpl.invoke(DelegatingMethodAccessorImpl.java:43)
	at java.base/java.lang.reflect.Method.invoke(Method.java:568)
	at org.testng.internal.MethodInvocationHelper.invokeMethod(MethodInvocationHelper.java:108)
	at org.testng.internal.Invoker.invokeMethod(Invoker.java:661)
	at org.testng.internal.Invoker.invokeTestMethod(Invoker.java:869)
	at org.testng.internal.Invoker.invokeTestMethods(Invoker.java:1193)
	at org.testng.internal.TestMethodWorker.invokeTestMethods(TestMethodWorker.java:126)
	at org.testng.internal.TestMethodWorker.run(TestMethodWorker.java:109)
	at org.testng.TestRunner.privateRun(TestRunner.java:744)
	at org.testng.TestRunner.run(TestRunner.java:602)
	at org.testng.SuiteRunner.runTest(SuiteRunner.java:380)
	at org.testng.SuiteRunner.runSequentially(SuiteRunner.java:375)
	at org.testng.SuiteRunner.privateRun(SuiteRunner.java:340)
	at org.testng.SuiteRunner.run(SuiteRunner.java:289)
	at org.testng.SuiteRunnerWorker.runSuite(SuiteRunnerWorker.java:52)
	at org.testng.SuiteRunnerWorker.run(SuiteRunnerWorker.java:86)
	at org.testng.TestNG.runSuitesSequentially(TestNG.java:1301)
	at org.testng.TestNG.runSuitesLocally(TestNG.java:1226)
	at org.testng.TestNG.runSuites(TestNG.java:1144)
	at org.testng.TestNG.run(TestNG.java:1115)
	at org.testng.remote.AbstractRemoteTestNG.run(AbstractRemoteTestNG.java:115)
	at org.testng.remote.RemoteTestNG.initAndRun(RemoteTestNG.java:251)
	at org.testng.remote.RemoteTestNG.main(RemoteTestNG.java:77)
]]>
            </full-stacktrace>
          </exception> <!-- java.lang.AssertionError -->
          <reporter-output>
          </reporter-output>
        </test-method> <!-- transactionResetFunctionalities -->
        <test-method signature="transactionBackFunctionalities()[pri:31, instance:com.crm.qa.testcases.CustomerLoginFunctionalitiesTest@2421cc4]" started-at="2024-03-09T10:38:57Z" name="transactionBackFunctionalities" finished-at="2024-03-09T10:38:57Z" duration-ms="80" status="PASS">
          <reporter-output>
          </reporter-output>
        </test-method> <!-- transactionBackFunctionalities -->
        <test-method signature="VerifyLogoutFunctionality()[pri:32, instance:com.crm.qa.testcases.CustomerLoginFunctionalitiesTest@2421cc4]" started-at="2024-03-09T10:38:57Z" name="VerifyLogoutFunctionality" finished-at="2024-03-09T10:38:57Z" duration-ms="116" status="PASS">
          <reporter-output>
          </reporter-output>
        </test-method> <!-- VerifyLogoutFunctionality -->
        <test-method signature="VerifyPostLogoutFunctionality()[pri:33, instance:com.crm.qa.testcases.CustomerLoginFunctionalitiesTest@2421cc4]" started-at="2024-03-09T10:38:57Z" name="VerifyPostLogoutFunctionality" finished-at="2024-03-09T10:38:58Z" duration-ms="135" status="FAIL">
          <exception class="java.lang.AssertionError">
            <message>
              <![CDATA[Customer is able to visit the session after logging out. New issue expected [Customer is not able to visit the session after logging out.] but found [Customer is able to visit the session after logging out. New issue]]]>
            </message>
            <full-stacktrace>
              <![CDATA[java.lang.AssertionError: Customer is able to visit the session after logging out. New issue expected [Customer is not able to visit the session after logging out.] but found [Customer is able to visit the session after logging out. New issue]
	at org.testng.Assert.fail(Assert.java:93)
	at org.testng.Assert.failNotEquals(Assert.java:512)
	at org.testng.Assert.assertEqualsImpl(Assert.java:134)
	at org.testng.Assert.assertEquals(Assert.java:115)
	at org.testng.Assert.assertEquals(Assert.java:189)
	at com.crm.qa.testcases.CustomerLoginFunctionalitiesTest.VerifyPostLogoutFunctionality(CustomerLoginFunctionalitiesTest.java:115)
	at java.base/jdk.internal.reflect.NativeMethodAccessorImpl.invoke0(Native Method)
	at java.base/jdk.internal.reflect.NativeMethodAccessorImpl.invoke(NativeMethodAccessorImpl.java:77)
	at java.base/jdk.internal.reflect.DelegatingMethodAccessorImpl.invoke(DelegatingMethodAccessorImpl.java:43)
	at java.base/java.lang.reflect.Method.invoke(Method.java:568)
	at org.testng.internal.MethodInvocationHelper.invokeMethod(MethodInvocationHelper.java:108)
	at org.testng.internal.Invoker.invokeMethod(Invoker.java:661)
	at org.testng.internal.Invoker.invokeTestMethod(Invoker.java:869)
	at org.testng.internal.Invoker.invokeTestMethods(Invoker.java:1193)
	at org.testng.internal.TestMethodWorker.invokeTestMethods(TestMethodWorker.java:126)
	at org.testng.internal.TestMethodWorker.run(TestMethodWorker.java:109)
	at org.testng.TestRunner.privateRun(TestRunner.java:744)
	at org.testng.TestRunner.run(TestRunner.java:602)
	at org.testng.SuiteRunner.runTest(SuiteRunner.java:380)
	at org.testng.SuiteRunner.runSequentially(SuiteRunner.java:375)
	at org.testng.SuiteRunner.privateRun(SuiteRunner.java:340)
	at org.testng.SuiteRunner.run(SuiteRunner.java:289)
	at org.testng.SuiteRunnerWorker.runSuite(SuiteRunnerWorker.java:52)
	at org.testng.SuiteRunnerWorker.run(SuiteRunnerWorker.java:86)
	at org.testng.TestNG.runSuitesSequentially(TestNG.java:1301)
	at org.testng.TestNG.runSuitesLocally(TestNG.java:1226)
	at org.testng.TestNG.runSuites(TestNG.java:1144)
	at org.testng.TestNG.run(TestNG.java:1115)
	at org.testng.remote.AbstractRemoteTestNG.run(AbstractRemoteTestNG.java:115)
	at org.testng.remote.RemoteTestNG.initAndRun(RemoteTestNG.java:251)
	at org.testng.remote.RemoteTestNG.main(RemoteTestNG.java:77)
]]>
            </full-stacktrace>
          </exception> <!-- java.lang.AssertionError -->
          <reporter-output>
          </reporter-output>
        </test-method> <!-- VerifyPostLogoutFunctionality -->
        <test-method signature="VerifyredirectToNonaccessablePageFunctionality()[pri:34, instance:com.crm.qa.testcases.CustomerLoginFunctionalitiesTest@2421cc4]" started-at="2024-03-09T10:38:58Z" name="VerifyredirectToNonaccessablePageFunctionality" finished-at="2024-03-09T10:38:58Z" duration-ms="129" status="FAIL">
          <exception class="java.lang.AssertionError">
            <message>
              <![CDATA[Customer is able to access the account after logging out. New issue expected [Customer is not access the account after logging out.] but found [Customer is able to access the account after logging out. New issue]]]>
            </message>
            <full-stacktrace>
              <![CDATA[java.lang.AssertionError: Customer is able to access the account after logging out. New issue expected [Customer is not access the account after logging out.] but found [Customer is able to access the account after logging out. New issue]
	at org.testng.Assert.fail(Assert.java:93)
	at org.testng.Assert.failNotEquals(Assert.java:512)
	at org.testng.Assert.assertEqualsImpl(Assert.java:134)
	at org.testng.Assert.assertEquals(Assert.java:115)
	at org.testng.Assert.assertEquals(Assert.java:189)
	at com.crm.qa.testcases.CustomerLoginFunctionalitiesTest.VerifyredirectToNonaccessablePageFunctionality(CustomerLoginFunctionalitiesTest.java:120)
	at java.base/jdk.internal.reflect.NativeMethodAccessorImpl.invoke0(Native Method)
	at java.base/jdk.internal.reflect.NativeMethodAccessorImpl.invoke(NativeMethodAccessorImpl.java:77)
	at java.base/jdk.internal.reflect.DelegatingMethodAccessorImpl.invoke(DelegatingMethodAccessorImpl.java:43)
	at java.base/java.lang.reflect.Method.invoke(Method.java:568)
	at org.testng.internal.MethodInvocationHelper.invokeMethod(MethodInvocationHelper.java:108)
	at org.testng.internal.Invoker.invokeMethod(Invoker.java:661)
	at org.testng.internal.Invoker.invokeTestMethod(Invoker.java:869)
	at org.testng.internal.Invoker.invokeTestMethods(Invoker.java:1193)
	at org.testng.internal.TestMethodWorker.invokeTestMethods(TestMethodWorker.java:126)
	at org.testng.internal.TestMethodWorker.run(TestMethodWorker.java:109)
	at org.testng.TestRunner.privateRun(TestRunner.java:744)
	at org.testng.TestRunner.run(TestRunner.java:602)
	at org.testng.SuiteRunner.runTest(SuiteRunner.java:380)
	at org.testng.SuiteRunner.runSequentially(SuiteRunner.java:375)
	at org.testng.SuiteRunner.privateRun(SuiteRunner.java:340)
	at org.testng.SuiteRunner.run(SuiteRunner.java:289)
	at org.testng.SuiteRunnerWorker.runSuite(SuiteRunnerWorker.java:52)
	at org.testng.SuiteRunnerWorker.run(SuiteRunnerWorker.java:86)
	at org.testng.TestNG.runSuitesSequentially(TestNG.java:1301)
	at org.testng.TestNG.runSuitesLocally(TestNG.java:1226)
	at org.testng.TestNG.runSuites(TestNG.java:1144)
	at org.testng.TestNG.run(TestNG.java:1115)
	at org.testng.remote.AbstractRemoteTestNG.run(AbstractRemoteTestNG.java:115)
	at org.testng.remote.RemoteTestNG.initAndRun(RemoteTestNG.java:251)
	at org.testng.remote.RemoteTestNG.main(RemoteTestNG.java:77)
]]>
            </full-stacktrace>
          </exception> <!-- java.lang.AssertionError -->
          <reporter-output>
          </reporter-output>
        </test-method> <!-- VerifyredirectToNonaccessablePageFunctionality -->
        <test-method is-config="true" signature="tearDown()[pri:0, instance:com.crm.qa.testcases.CustomerLoginFunctionalitiesTest@2421cc4]" started-at="2024-03-09T10:38:58Z" name="tearDown" finished-at="2024-03-09T10:38:59Z" duration-ms="1360" status="PASS">
          <reporter-output>
          </reporter-output>
        </test-method> <!-- tearDown -->
      </class> <!-- com.crm.qa.testcases.CustomerLoginFunctionalitiesTest -->
      <class name="com.crm.qa.testcases.HomeDashBoardTest">
        <test-method is-config="true" signature="setUp(java.lang.String)[pri:0, instance:com.crm.qa.testcases.HomeDashBoardTest@68702e03]" started-at="2024-03-09T10:38:02Z" name="setUp" finished-at="2024-03-09T10:38:13Z" duration-ms="10512" status="PASS">
          <params>
            <param index="0">
              <value>
                <![CDATA[firefox]]>
              </value>
            </param>
          </params>
          <reporter-output>
          </reporter-output>
        </test-method> <!-- setUp -->
        <test-method signature="VerifyTitle()[pri:1, instance:com.crm.qa.testcases.HomeDashBoardTest@68702e03]" started-at="2024-03-09T10:38:13Z" name="VerifyTitle" finished-at="2024-03-09T10:38:14Z" duration-ms="706" status="PASS">
          <reporter-output>
          </reporter-output>
        </test-method> <!-- VerifyTitle -->
        <test-method signature="VerifyHomeBtn()[pri:2, instance:com.crm.qa.testcases.HomeDashBoardTest@68702e03]" started-at="2024-03-09T10:38:14Z" name="VerifyHomeBtn" finished-at="2024-03-09T10:38:14Z" duration-ms="60" status="PASS">
          <reporter-output>
          </reporter-output>
        </test-method> <!-- VerifyHomeBtn -->
        <test-method signature="VerifycustLoginBtn()[pri:3, instance:com.crm.qa.testcases.HomeDashBoardTest@68702e03]" started-at="2024-03-09T10:38:14Z" name="VerifycustLoginBtn" finished-at="2024-03-09T10:38:14Z" duration-ms="63" status="PASS">
          <reporter-output>
          </reporter-output>
        </test-method> <!-- VerifycustLoginBtn -->
        <test-method signature="VerifybankManagerLoginBtn()[pri:4, instance:com.crm.qa.testcases.HomeDashBoardTest@68702e03]" started-at="2024-03-09T10:38:14Z" name="VerifybankManagerLoginBtn" finished-at="2024-03-09T10:38:14Z" duration-ms="54" status="PASS">
          <reporter-output>
          </reporter-output>
        </test-method> <!-- VerifybankManagerLoginBtn -->
        <test-method signature="VerifyHomeBtnFunctionality()[pri:5, instance:com.crm.qa.testcases.HomeDashBoardTest@68702e03]" started-at="2024-03-09T10:38:14Z" name="VerifyHomeBtnFunctionality" finished-at="2024-03-09T10:38:14Z" duration-ms="399" status="PASS">
          <reporter-output>
          </reporter-output>
        </test-method> <!-- VerifyHomeBtnFunctionality -->
        <test-method signature="VerifycustLoginBtnFunctionality()[pri:6, instance:com.crm.qa.testcases.HomeDashBoardTest@68702e03]" started-at="2024-03-09T10:38:14Z" name="VerifycustLoginBtnFunctionality" finished-at="2024-03-09T10:38:15Z" duration-ms="397" status="PASS">
          <reporter-output>
          </reporter-output>
        </test-method> <!-- VerifycustLoginBtnFunctionality -->
        <test-method signature="VerifybankManagerLoginBtnFunctionality()[pri:7, instance:com.crm.qa.testcases.HomeDashBoardTest@68702e03]" started-at="2024-03-09T10:38:15Z" name="VerifybankManagerLoginBtnFunctionality" finished-at="2024-03-09T10:38:15Z" duration-ms="377" status="PASS">
          <reporter-output>
          </reporter-output>
        </test-method> <!-- VerifybankManagerLoginBtnFunctionality -->
        <test-method signature="VerifyNonAccountCustomersFunctionality()[pri:8, instance:com.crm.qa.testcases.HomeDashBoardTest@68702e03]" started-at="2024-03-09T10:38:15Z" name="VerifyNonAccountCustomersFunctionality" finished-at="2024-03-09T10:38:18Z" duration-ms="2823" status="PASS">
          <reporter-output>
          </reporter-output>
        </test-method> <!-- VerifyNonAccountCustomersFunctionality -->
        <test-method is-config="true" signature="tearDown()[pri:0, instance:com.crm.qa.testcases.HomeDashBoardTest@68702e03]" started-at="2024-03-09T10:38:18Z" name="tearDown" finished-at="2024-03-09T10:38:19Z" duration-ms="1326" status="PASS">
          <reporter-output>
          </reporter-output>
        </test-method> <!-- tearDown -->
      </class> <!-- com.crm.qa.testcases.HomeDashBoardTest -->
      <class name="com.crm.qa.testcases.BankManagerLoginFunctionalitiesTest">
        <test-method is-config="true" signature="setUp(java.lang.String)[pri:0, instance:com.crm.qa.testcases.BankManagerLoginFunctionalitiesTest@7a220c9a]" started-at="2024-03-09T10:38:19Z" name="setUp" finished-at="2024-03-09T10:38:27Z" duration-ms="7582" status="PASS">
          <params>
            <param index="0">
              <value>
                <![CDATA[firefox]]>
              </value>
            </param>
          </params>
          <reporter-output>
          </reporter-output>
        </test-method> <!-- setUp -->
        <test-method signature="VerifyBankManagerLoginBtnFunctionality()[pri:9, instance:com.crm.qa.testcases.BankManagerLoginFunctionalitiesTest@7a220c9a]" started-at="2024-03-09T10:38:27Z" name="VerifyBankManagerLoginBtnFunctionality" finished-at="2024-03-09T10:38:28Z" duration-ms="1007" status="PASS">
          <reporter-output>
          </reporter-output>
        </test-method> <!-- VerifyBankManagerLoginBtnFunctionality -->
        <test-method signature="VerifyBankManagerLogin()[pri:10, instance:com.crm.qa.testcases.BankManagerLoginFunctionalitiesTest@7a220c9a]" started-at="2024-03-09T10:38:28Z" name="VerifyBankManagerLogin" finished-at="2024-03-09T10:38:29Z" duration-ms="805" status="PASS">
          <reporter-output>
          </reporter-output>
        </test-method> <!-- VerifyBankManagerLogin -->
        <test-method signature="VerifyInvalidFnameBankManagerLogin()[pri:11, instance:com.crm.qa.testcases.BankManagerLoginFunctionalitiesTest@7a220c9a]" started-at="2024-03-09T10:38:29Z" name="VerifyInvalidFnameBankManagerLogin" finished-at="2024-03-09T10:38:29Z" duration-ms="537" status="FAIL">
          <exception class="java.lang.AssertionError">
            <message>
              <![CDATA[First name is containing special characters and numbers. New issue expected [Pop-up validation: Unexpected or no success message] but found [Pop-up validation: Customer added successfully]]]>
            </message>
            <full-stacktrace>
              <![CDATA[java.lang.AssertionError: First name is containing special characters and numbers. New issue expected [Pop-up validation: Unexpected or no success message] but found [Pop-up validation: Customer added successfully]
	at org.testng.Assert.fail(Assert.java:93)
	at org.testng.Assert.failNotEquals(Assert.java:512)
	at org.testng.Assert.assertEqualsImpl(Assert.java:134)
	at org.testng.Assert.assertEquals(Assert.java:115)
	at org.testng.Assert.assertEquals(Assert.java:189)
	at com.crm.qa.testcases.BankManagerLoginFunctionalitiesTest.VerifyInvalidFnameBankManagerLogin(BankManagerLoginFunctionalitiesTest.java:44)
	at java.base/jdk.internal.reflect.NativeMethodAccessorImpl.invoke0(Native Method)
	at java.base/jdk.internal.reflect.NativeMethodAccessorImpl.invoke(NativeMethodAccessorImpl.java:77)
	at java.base/jdk.internal.reflect.DelegatingMethodAccessorImpl.invoke(DelegatingMethodAccessorImpl.java:43)
	at java.base/java.lang.reflect.Method.invoke(Method.java:568)
	at org.testng.internal.MethodInvocationHelper.invokeMethod(MethodInvocationHelper.java:108)
	at org.testng.internal.Invoker.invokeMethod(Invoker.java:661)
	at org.testng.internal.Invoker.invokeTestMethod(Invoker.java:869)
	at org.testng.internal.Invoker.invokeTestMethods(Invoker.java:1193)
	at org.testng.internal.TestMethodWorker.invokeTestMethods(TestMethodWorker.java:126)
	at org.testng.internal.TestMethodWorker.run(TestMethodWorker.java:109)
	at org.testng.TestRunner.privateRun(TestRunner.java:744)
	at org.testng.TestRunner.run(TestRunner.java:602)
	at org.testng.SuiteRunner.runTest(SuiteRunner.java:380)
	at org.testng.SuiteRunner.runSequentially(SuiteRunner.java:375)
	at org.testng.SuiteRunner.privateRun(SuiteRunner.java:340)
	at org.testng.SuiteRunner.run(SuiteRunner.java:289)
	at org.testng.SuiteRunnerWorker.runSuite(SuiteRunnerWorker.java:52)
	at org.testng.SuiteRunnerWorker.run(SuiteRunnerWorker.java:86)
	at org.testng.TestNG.runSuitesSequentially(TestNG.java:1301)
	at org.testng.TestNG.runSuitesLocally(TestNG.java:1226)
	at org.testng.TestNG.runSuites(TestNG.java:1144)
	at org.testng.TestNG.run(TestNG.java:1115)
	at org.testng.remote.AbstractRemoteTestNG.run(AbstractRemoteTestNG.java:115)
	at org.testng.remote.RemoteTestNG.initAndRun(RemoteTestNG.java:251)
	at org.testng.remote.RemoteTestNG.main(RemoteTestNG.java:77)
]]>
            </full-stacktrace>
          </exception> <!-- java.lang.AssertionError -->
          <reporter-output>
          </reporter-output>
        </test-method> <!-- VerifyInvalidFnameBankManagerLogin -->
        <test-method signature="VerifyInvalidLnameBankManagerLogin()[pri:12, instance:com.crm.qa.testcases.BankManagerLoginFunctionalitiesTest@7a220c9a]" started-at="2024-03-09T10:38:29Z" name="VerifyInvalidLnameBankManagerLogin" finished-at="2024-03-09T10:38:30Z" duration-ms="513" status="FAIL">
          <exception class="java.lang.AssertionError">
            <message>
              <![CDATA[Last name is containing special characters and numbers. New issue expected [Pop-up validation: Unexpected or no success message] but found [Pop-up validation: Customer added successfully]]]>
            </message>
            <full-stacktrace>
              <![CDATA[java.lang.AssertionError: Last name is containing special characters and numbers. New issue expected [Pop-up validation: Unexpected or no success message] but found [Pop-up validation: Customer added successfully]
	at org.testng.Assert.fail(Assert.java:93)
	at org.testng.Assert.failNotEquals(Assert.java:512)
	at org.testng.Assert.assertEqualsImpl(Assert.java:134)
	at org.testng.Assert.assertEquals(Assert.java:115)
	at org.testng.Assert.assertEquals(Assert.java:189)
	at com.crm.qa.testcases.BankManagerLoginFunctionalitiesTest.VerifyInvalidLnameBankManagerLogin(BankManagerLoginFunctionalitiesTest.java:49)
	at java.base/jdk.internal.reflect.NativeMethodAccessorImpl.invoke0(Native Method)
	at java.base/jdk.internal.reflect.NativeMethodAccessorImpl.invoke(NativeMethodAccessorImpl.java:77)
	at java.base/jdk.internal.reflect.DelegatingMethodAccessorImpl.invoke(DelegatingMethodAccessorImpl.java:43)
	at java.base/java.lang.reflect.Method.invoke(Method.java:568)
	at org.testng.internal.MethodInvocationHelper.invokeMethod(MethodInvocationHelper.java:108)
	at org.testng.internal.Invoker.invokeMethod(Invoker.java:661)
	at org.testng.internal.Invoker.invokeTestMethod(Invoker.java:869)
	at org.testng.internal.Invoker.invokeTestMethods(Invoker.java:1193)
	at org.testng.internal.TestMethodWorker.invokeTestMethods(TestMethodWorker.java:126)
	at org.testng.internal.TestMethodWorker.run(TestMethodWorker.java:109)
	at org.testng.TestRunner.privateRun(TestRunner.java:744)
	at org.testng.TestRunner.run(TestRunner.java:602)
	at org.testng.SuiteRunner.runTest(SuiteRunner.java:380)
	at org.testng.SuiteRunner.runSequentially(SuiteRunner.java:375)
	at org.testng.SuiteRunner.privateRun(SuiteRunner.java:340)
	at org.testng.SuiteRunner.run(SuiteRunner.java:289)
	at org.testng.SuiteRunnerWorker.runSuite(SuiteRunnerWorker.java:52)
	at org.testng.SuiteRunnerWorker.run(SuiteRunnerWorker.java:86)
	at org.testng.TestNG.runSuitesSequentially(TestNG.java:1301)
	at org.testng.TestNG.runSuitesLocally(TestNG.java:1226)
	at org.testng.TestNG.runSuites(TestNG.java:1144)
	at org.testng.TestNG.run(TestNG.java:1115)
	at org.testng.remote.AbstractRemoteTestNG.run(AbstractRemoteTestNG.java:115)
	at org.testng.remote.RemoteTestNG.initAndRun(RemoteTestNG.java:251)
	at org.testng.remote.RemoteTestNG.main(RemoteTestNG.java:77)
]]>
            </full-stacktrace>
          </exception> <!-- java.lang.AssertionError -->
          <reporter-output>
          </reporter-output>
        </test-method> <!-- VerifyInvalidLnameBankManagerLogin -->
        <test-method signature="VerifyEmptyFieldBankManagerLogin()[pri:13, instance:com.crm.qa.testcases.BankManagerLoginFunctionalitiesTest@7a220c9a]" started-at="2024-03-09T10:38:30Z" name="VerifyEmptyFieldBankManagerLogin" finished-at="2024-03-09T10:38:32Z" duration-ms="2172" status="PASS">
          <reporter-output>
          </reporter-output>
        </test-method> <!-- VerifyEmptyFieldBankManagerLogin -->
        <test-method signature="VerifyDuplicateBankManagerLogin()[pri:14, instance:com.crm.qa.testcases.BankManagerLoginFunctionalitiesTest@7a220c9a]" started-at="2024-03-09T10:38:32Z" name="VerifyDuplicateBankManagerLogin" finished-at="2024-03-09T10:38:34Z" duration-ms="2341" status="PASS">
          <reporter-output>
          </reporter-output>
        </test-method> <!-- VerifyDuplicateBankManagerLogin -->
        <test-method signature="VerifyOpenAccountFunctionality()[pri:15, instance:com.crm.qa.testcases.BankManagerLoginFunctionalitiesTest@7a220c9a]" started-at="2024-03-09T10:38:34Z" name="VerifyOpenAccountFunctionality" finished-at="2024-03-09T10:38:36Z" duration-ms="1831" status="PASS">
          <reporter-output>
          </reporter-output>
        </test-method> <!-- VerifyOpenAccountFunctionality -->
        <test-method signature="searchCustomersFunctionalityByName()[pri:16, instance:com.crm.qa.testcases.BankManagerLoginFunctionalitiesTest@7a220c9a]" started-at="2024-03-09T10:38:36Z" name="searchCustomersFunctionalityByName" finished-at="2024-03-09T10:38:37Z" duration-ms="529" status="PASS">
          <reporter-output>
          </reporter-output>
        </test-method> <!-- searchCustomersFunctionalityByName -->
        <test-method signature="searchCustomersFunctionalityByID()[pri:17, instance:com.crm.qa.testcases.BankManagerLoginFunctionalitiesTest@7a220c9a]" started-at="2024-03-09T10:38:37Z" name="searchCustomersFunctionalityByID" finished-at="2024-03-09T10:38:37Z" duration-ms="421" status="PASS">
          <reporter-output>
          </reporter-output>
        </test-method> <!-- searchCustomersFunctionalityByID -->
        <test-method signature="searchCustomersFunctionalityByPostCode()[pri:18, instance:com.crm.qa.testcases.BankManagerLoginFunctionalitiesTest@7a220c9a]" started-at="2024-03-09T10:38:37Z" name="searchCustomersFunctionalityByPostCode" finished-at="2024-03-09T10:38:37Z" duration-ms="398" status="PASS">
          <reporter-output>
          </reporter-output>
        </test-method> <!-- searchCustomersFunctionalityByPostCode -->
        <test-method signature="deleteCustomerFunctionality()[pri:19, instance:com.crm.qa.testcases.BankManagerLoginFunctionalitiesTest@7a220c9a]" started-at="2024-03-09T10:38:37Z" name="deleteCustomerFunctionality" finished-at="2024-03-09T10:38:38Z" duration-ms="1033" status="PASS">
          <reporter-output>
          </reporter-output>
        </test-method> <!-- deleteCustomerFunctionality -->
        <test-method is-config="true" signature="tearDown()[pri:0, instance:com.crm.qa.testcases.BankManagerLoginFunctionalitiesTest@7a220c9a]" started-at="2024-03-09T10:38:38Z" name="tearDown" finished-at="2024-03-09T10:38:40Z" duration-ms="1300" status="PASS">
          <reporter-output>
          </reporter-output>
        </test-method> <!-- tearDown -->
      </class> <!-- com.crm.qa.testcases.BankManagerLoginFunctionalitiesTest -->
    </test> <!-- GWB-Tests-Firefox -->
  </suite> <!-- Gringotts Wizarding Bank -->
</testng-results>
