<?xml version="1.0" encoding="UTF-8"?>
<testng-results ignored="0" total="99" passed="78" failed="21" skipped="0">
  <reporter-output>
  </reporter-output>
  <suite started-at="2024-03-12T18:57:04Z" name="Gringotts Wizarding Bank" finished-at="2024-03-12T19:00:48Z" duration-ms="223210">
    <groups>
    </groups>
    <test started-at="2024-03-12T18:57:04Z" name="GWB-Tests-Chrome" finished-at="2024-03-12T18:58:13Z" duration-ms="68631">
      <class name="com.crm.qa.testcases.CustomerLoginFunctionalitiesTest">
        <test-method is-config="true" signature="setUp(java.lang.String)[pri:0, instance:com.crm.qa.testcases.CustomerLoginFunctionalitiesTest@5b367418]" started-at="2024-03-13T00:27:42Z" name="setUp" finished-at="2024-03-13T00:27:47Z" duration-ms="5906" status="PASS">
          <params>
            <param index="0">
              <value>
                <![CDATA[chrome]]>
              </value>
            </param>
          </params>
          <reporter-output>
          </reporter-output>
        </test-method> <!-- setUp -->
        <test-method signature="VerifycustLoginBtnFunctionality()[pri:20, instance:com.crm.qa.testcases.CustomerLoginFunctionalitiesTest@5b367418]" started-at="2024-03-13T00:27:47Z" name="VerifycustLoginBtnFunctionality" finished-at="2024-03-13T00:27:53Z" duration-ms="5795" status="PASS">
          <reporter-output>
          </reporter-output>
        </test-method> <!-- VerifycustLoginBtnFunctionality -->
        <test-method signature="VerifyCustomerLogin()[pri:21, instance:com.crm.qa.testcases.CustomerLoginFunctionalitiesTest@5b367418]" started-at="2024-03-13T00:27:53Z" name="VerifyCustomerLogin" finished-at="2024-03-13T00:27:56Z" duration-ms="2542" status="PASS">
          <reporter-output>
          </reporter-output>
        </test-method> <!-- VerifyCustomerLogin -->
        <test-method signature="depositValidAmount()[pri:23, instance:com.crm.qa.testcases.CustomerLoginFunctionalitiesTest@5b367418]" started-at="2024-03-13T00:27:56Z" name="depositValidAmount" finished-at="2024-03-13T00:27:59Z" duration-ms="3055" status="PASS">
          <reporter-output>
          </reporter-output>
        </test-method> <!-- depositValidAmount -->
        <test-method signature="depositInValidAmount()[pri:24, instance:com.crm.qa.testcases.CustomerLoginFunctionalitiesTest@5b367418]" started-at="2024-03-13T00:27:59Z" name="depositInValidAmount" finished-at="2024-03-13T00:28:00Z" duration-ms="861" status="FAIL">
          <exception class="java.lang.AssertionError">
            <message>
              <![CDATA[No warning raised. New issue detected expected [Deposit Successful] but found [Invalid Input]]]>
            </message>
            <full-stacktrace>
              <![CDATA[java.lang.AssertionError: No warning raised. New issue detected expected [Deposit Successful] but found [Invalid Input]
	at org.testng.Assert.fail(Assert.java:93)
	at org.testng.Assert.failNotEquals(Assert.java:512)
	at org.testng.Assert.assertEqualsImpl(Assert.java:134)
	at org.testng.Assert.assertEquals(Assert.java:115)
	at org.testng.Assert.assertEquals(Assert.java:189)
	at com.crm.qa.testcases.CustomerLoginFunctionalitiesTest.depositInValidAmount(CustomerLoginFunctionalitiesTest.java:55)
	at java.base/jdk.internal.reflect.NativeMethodAccessorImpl.invoke0(Native Method)
	at java.base/jdk.internal.reflect.NativeMethodAccessorImpl.invoke(NativeMethodAccessorImpl.java:77)
	at java.base/jdk.internal.reflect.DelegatingMethodAccessorImpl.invoke(DelegatingMethodAccessorImpl.java:43)
	at java.base/java.lang.reflect.Method.invoke(Method.java:568)
	at org.testng.internal.MethodInvocationHelper.invokeMethod(MethodInvocationHelper.java:108)
	at org.testng.internal.Invoker.invokeMethod(Invoker.java:661)
	at org.testng.internal.Invoker.invokeTestMethod(Invoker.java:869)
	at org.testng.internal.Invoker.invokeTestMethods(Invoker.java:1193)
	at org.testng.internal.TestMethodWorker.invokeTestMethods(TestMethodWorker.java:126)
	at org.testng.internal.TestMethodWorker.run(TestMethodWorker.java:109)
	at org.testng.TestRunner.privateRun(TestRunner.java:744)
	at org.testng.TestRunner.run(TestRunner.java:602)
	at org.testng.SuiteRunner.runTest(SuiteRunner.java:380)
	at org.testng.SuiteRunner.runSequentially(SuiteRunner.java:375)
	at org.testng.SuiteRunner.privateRun(SuiteRunner.java:340)
	at org.testng.SuiteRunner.run(SuiteRunner.java:289)
	at org.testng.SuiteRunnerWorker.runSuite(SuiteRunnerWorker.java:52)
	at org.testng.SuiteRunnerWorker.run(SuiteRunnerWorker.java:86)
	at org.testng.TestNG.runSuitesSequentially(TestNG.java:1301)
	at org.testng.TestNG.runSuitesLocally(TestNG.java:1226)
	at org.testng.TestNG.runSuites(TestNG.java:1144)
	at org.testng.TestNG.run(TestNG.java:1115)
	at org.testng.remote.AbstractRemoteTestNG.run(AbstractRemoteTestNG.java:115)
	at org.testng.remote.RemoteTestNG.initAndRun(RemoteTestNG.java:251)
	at org.testng.remote.RemoteTestNG.main(RemoteTestNG.java:77)
]]>
            </full-stacktrace>
          </exception> <!-- java.lang.AssertionError -->
          <reporter-output>
          </reporter-output>
        </test-method> <!-- depositInValidAmount -->
        <test-method signature="depositDecimalAmount()[pri:25, instance:com.crm.qa.testcases.CustomerLoginFunctionalitiesTest@5b367418]" started-at="2024-03-13T00:28:00Z" name="depositDecimalAmount" finished-at="2024-03-13T00:28:00Z" duration-ms="704" status="PASS">
          <reporter-output>
          </reporter-output>
        </test-method> <!-- depositDecimalAmount -->
        <test-method signature="withdrawValidAmount()[pri:26, instance:com.crm.qa.testcases.CustomerLoginFunctionalitiesTest@5b367418]" started-at="2024-03-13T00:28:00Z" name="withdrawValidAmount" finished-at="2024-03-13T00:28:05Z" duration-ms="4585" status="PASS">
          <reporter-output>
          </reporter-output>
        </test-method> <!-- withdrawValidAmount -->
        <test-method signature="withdrawInValidAmount()[pri:27, instance:com.crm.qa.testcases.CustomerLoginFunctionalitiesTest@5b367418]" started-at="2024-03-13T00:28:05Z" name="withdrawInValidAmount" finished-at="2024-03-13T00:28:07Z" duration-ms="1639" status="FAIL">
          <exception class="java.lang.AssertionError">
            <message>
              <![CDATA[No warning raised. New issue detected expected [Transaction successful] but found [Invalid Input]]]>
            </message>
            <full-stacktrace>
              <![CDATA[java.lang.AssertionError: No warning raised. New issue detected expected [Transaction successful] but found [Invalid Input]
	at org.testng.Assert.fail(Assert.java:93)
	at org.testng.Assert.failNotEquals(Assert.java:512)
	at org.testng.Assert.assertEqualsImpl(Assert.java:134)
	at org.testng.Assert.assertEquals(Assert.java:115)
	at org.testng.Assert.assertEquals(Assert.java:189)
	at com.crm.qa.testcases.CustomerLoginFunctionalitiesTest.withdrawInValidAmount(CustomerLoginFunctionalitiesTest.java:76)
	at java.base/jdk.internal.reflect.NativeMethodAccessorImpl.invoke0(Native Method)
	at java.base/jdk.internal.reflect.NativeMethodAccessorImpl.invoke(NativeMethodAccessorImpl.java:77)
	at java.base/jdk.internal.reflect.DelegatingMethodAccessorImpl.invoke(DelegatingMethodAccessorImpl.java:43)
	at java.base/java.lang.reflect.Method.invoke(Method.java:568)
	at org.testng.internal.MethodInvocationHelper.invokeMethod(MethodInvocationHelper.java:108)
	at org.testng.internal.Invoker.invokeMethod(Invoker.java:661)
	at org.testng.internal.Invoker.invokeTestMethod(Invoker.java:869)
	at org.testng.internal.Invoker.invokeTestMethods(Invoker.java:1193)
	at org.testng.internal.TestMethodWorker.invokeTestMethods(TestMethodWorker.java:126)
	at org.testng.internal.TestMethodWorker.run(TestMethodWorker.java:109)
	at org.testng.TestRunner.privateRun(TestRunner.java:744)
	at org.testng.TestRunner.run(TestRunner.java:602)
	at org.testng.SuiteRunner.runTest(SuiteRunner.java:380)
	at org.testng.SuiteRunner.runSequentially(SuiteRunner.java:375)
	at org.testng.SuiteRunner.privateRun(SuiteRunner.java:340)
	at org.testng.SuiteRunner.run(SuiteRunner.java:289)
	at org.testng.SuiteRunnerWorker.runSuite(SuiteRunnerWorker.java:52)
	at org.testng.SuiteRunnerWorker.run(SuiteRunnerWorker.java:86)
	at org.testng.TestNG.runSuitesSequentially(TestNG.java:1301)
	at org.testng.TestNG.runSuitesLocally(TestNG.java:1226)
	at org.testng.TestNG.runSuites(TestNG.java:1144)
	at org.testng.TestNG.run(TestNG.java:1115)
	at org.testng.remote.AbstractRemoteTestNG.run(AbstractRemoteTestNG.java:115)
	at org.testng.remote.RemoteTestNG.initAndRun(RemoteTestNG.java:251)
	at org.testng.remote.RemoteTestNG.main(RemoteTestNG.java:77)
]]>
            </full-stacktrace>
          </exception> <!-- java.lang.AssertionError -->
          <reporter-output>
          </reporter-output>
        </test-method> <!-- withdrawInValidAmount -->
        <test-method signature="withdrawDecimalAmount()[pri:28, instance:com.crm.qa.testcases.CustomerLoginFunctionalitiesTest@5b367418]" started-at="2024-03-13T00:28:07Z" name="withdrawDecimalAmount" finished-at="2024-03-13T00:28:07Z" duration-ms="796" status="PASS">
          <reporter-output>
          </reporter-output>
        </test-method> <!-- withdrawDecimalAmount -->
        <test-method signature="withdrawInsufficientAmount()[pri:29, instance:com.crm.qa.testcases.CustomerLoginFunctionalitiesTest@5b367418]" started-at="2024-03-13T00:28:07Z" name="withdrawInsufficientAmount" finished-at="2024-03-13T00:28:08Z" duration-ms="738" status="PASS">
          <reporter-output>
          </reporter-output>
        </test-method> <!-- withdrawInsufficientAmount -->
        <test-method signature="transactionResetFunctionalities()[pri:30, instance:com.crm.qa.testcases.CustomerLoginFunctionalitiesTest@5b367418]" started-at="2024-03-13T00:28:08Z" name="transactionResetFunctionalities" finished-at="2024-03-13T00:28:11Z" duration-ms="2475" status="FAIL">
          <exception class="java.lang.AssertionError">
            <message>
              <![CDATA[No warning raised. Major Issue detected. Balance is resetting, too. expected [Data reset successful] but found [Data reset unsuccessful]]]>
            </message>
            <full-stacktrace>
              <![CDATA[java.lang.AssertionError: No warning raised. Major Issue detected. Balance is resetting, too. expected [Data reset successful] but found [Data reset unsuccessful]
	at org.testng.Assert.fail(Assert.java:93)
	at org.testng.Assert.failNotEquals(Assert.java:512)
	at org.testng.Assert.assertEqualsImpl(Assert.java:134)
	at org.testng.Assert.assertEquals(Assert.java:115)
	at org.testng.Assert.assertEquals(Assert.java:189)
	at com.crm.qa.testcases.CustomerLoginFunctionalitiesTest.transactionResetFunctionalities(CustomerLoginFunctionalitiesTest.java:95)
	at java.base/jdk.internal.reflect.NativeMethodAccessorImpl.invoke0(Native Method)
	at java.base/jdk.internal.reflect.NativeMethodAccessorImpl.invoke(NativeMethodAccessorImpl.java:77)
	at java.base/jdk.internal.reflect.DelegatingMethodAccessorImpl.invoke(DelegatingMethodAccessorImpl.java:43)
	at java.base/java.lang.reflect.Method.invoke(Method.java:568)
	at org.testng.internal.MethodInvocationHelper.invokeMethod(MethodInvocationHelper.java:108)
	at org.testng.internal.Invoker.invokeMethod(Invoker.java:661)
	at org.testng.internal.Invoker.invokeTestMethod(Invoker.java:869)
	at org.testng.internal.Invoker.invokeTestMethods(Invoker.java:1193)
	at org.testng.internal.TestMethodWorker.invokeTestMethods(TestMethodWorker.java:126)
	at org.testng.internal.TestMethodWorker.run(TestMethodWorker.java:109)
	at org.testng.TestRunner.privateRun(TestRunner.java:744)
	at org.testng.TestRunner.run(TestRunner.java:602)
	at org.testng.SuiteRunner.runTest(SuiteRunner.java:380)
	at org.testng.SuiteRunner.runSequentially(SuiteRunner.java:375)
	at org.testng.SuiteRunner.privateRun(SuiteRunner.java:340)
	at org.testng.SuiteRunner.run(SuiteRunner.java:289)
	at org.testng.SuiteRunnerWorker.runSuite(SuiteRunnerWorker.java:52)
	at org.testng.SuiteRunnerWorker.run(SuiteRunnerWorker.java:86)
	at org.testng.TestNG.runSuitesSequentially(TestNG.java:1301)
	at org.testng.TestNG.runSuitesLocally(TestNG.java:1226)
	at org.testng.TestNG.runSuites(TestNG.java:1144)
	at org.testng.TestNG.run(TestNG.java:1115)
	at org.testng.remote.AbstractRemoteTestNG.run(AbstractRemoteTestNG.java:115)
	at org.testng.remote.RemoteTestNG.initAndRun(RemoteTestNG.java:251)
	at org.testng.remote.RemoteTestNG.main(RemoteTestNG.java:77)
]]>
            </full-stacktrace>
          </exception> <!-- java.lang.AssertionError -->
          <reporter-output>
          </reporter-output>
        </test-method> <!-- transactionResetFunctionalities -->
        <test-method signature="transactionBackFunctionalities()[pri:31, instance:com.crm.qa.testcases.CustomerLoginFunctionalitiesTest@5b367418]" started-at="2024-03-13T00:28:11Z" name="transactionBackFunctionalities" finished-at="2024-03-13T00:28:11Z" duration-ms="336" status="PASS">
          <reporter-output>
          </reporter-output>
        </test-method> <!-- transactionBackFunctionalities -->
        <test-method signature="VerifyLogoutFunctionality()[pri:32, instance:com.crm.qa.testcases.CustomerLoginFunctionalitiesTest@5b367418]" started-at="2024-03-13T00:28:11Z" name="VerifyLogoutFunctionality" finished-at="2024-03-13T00:28:11Z" duration-ms="404" status="PASS">
          <reporter-output>
          </reporter-output>
        </test-method> <!-- VerifyLogoutFunctionality -->
        <test-method signature="VerifyPostLogoutFunctionality()[pri:33, instance:com.crm.qa.testcases.CustomerLoginFunctionalitiesTest@5b367418]" started-at="2024-03-13T00:28:11Z" name="VerifyPostLogoutFunctionality" finished-at="2024-03-13T00:28:12Z" duration-ms="380" status="FAIL">
          <exception class="java.lang.AssertionError">
            <message>
              <![CDATA[Customer is able to visit the session after logging out. New issue expected [Customer is not able to visit the session after logging out.] but found [Customer is able to visit the session after logging out. New issue]]]>
            </message>
            <full-stacktrace>
              <![CDATA[java.lang.AssertionError: Customer is able to visit the session after logging out. New issue expected [Customer is not able to visit the session after logging out.] but found [Customer is able to visit the session after logging out. New issue]
	at org.testng.Assert.fail(Assert.java:93)
	at org.testng.Assert.failNotEquals(Assert.java:512)
	at org.testng.Assert.assertEqualsImpl(Assert.java:134)
	at org.testng.Assert.assertEquals(Assert.java:115)
	at org.testng.Assert.assertEquals(Assert.java:189)
	at com.crm.qa.testcases.CustomerLoginFunctionalitiesTest.VerifyPostLogoutFunctionality(CustomerLoginFunctionalitiesTest.java:115)
	at java.base/jdk.internal.reflect.NativeMethodAccessorImpl.invoke0(Native Method)
	at java.base/jdk.internal.reflect.NativeMethodAccessorImpl.invoke(NativeMethodAccessorImpl.java:77)
	at java.base/jdk.internal.reflect.DelegatingMethodAccessorImpl.invoke(DelegatingMethodAccessorImpl.java:43)
	at java.base/java.lang.reflect.Method.invoke(Method.java:568)
	at org.testng.internal.MethodInvocationHelper.invokeMethod(MethodInvocationHelper.java:108)
	at org.testng.internal.Invoker.invokeMethod(Invoker.java:661)
	at org.testng.internal.Invoker.invokeTestMethod(Invoker.java:869)
	at org.testng.internal.Invoker.invokeTestMethods(Invoker.java:1193)
	at org.testng.internal.TestMethodWorker.invokeTestMethods(TestMethodWorker.java:126)
	at org.testng.internal.TestMethodWorker.run(TestMethodWorker.java:109)
	at org.testng.TestRunner.privateRun(TestRunner.java:744)
	at org.testng.TestRunner.run(TestRunner.java:602)
	at org.testng.SuiteRunner.runTest(SuiteRunner.java:380)
	at org.testng.SuiteRunner.runSequentially(SuiteRunner.java:375)
	at org.testng.SuiteRunner.privateRun(SuiteRunner.java:340)
	at org.testng.SuiteRunner.run(SuiteRunner.java:289)
	at org.testng.SuiteRunnerWorker.runSuite(SuiteRunnerWorker.java:52)
	at org.testng.SuiteRunnerWorker.run(SuiteRunnerWorker.java:86)
	at org.testng.TestNG.runSuitesSequentially(TestNG.java:1301)
	at org.testng.TestNG.runSuitesLocally(TestNG.java:1226)
	at org.testng.TestNG.runSuites(TestNG.java:1144)
	at org.testng.TestNG.run(TestNG.java:1115)
	at org.testng.remote.AbstractRemoteTestNG.run(AbstractRemoteTestNG.java:115)
	at org.testng.remote.RemoteTestNG.initAndRun(RemoteTestNG.java:251)
	at org.testng.remote.RemoteTestNG.main(RemoteTestNG.java:77)
]]>
            </full-stacktrace>
          </exception> <!-- java.lang.AssertionError -->
          <reporter-output>
          </reporter-output>
        </test-method> <!-- VerifyPostLogoutFunctionality -->
        <test-method signature="VerifyredirectToNonaccessablePageFunctionality()[pri:34, instance:com.crm.qa.testcases.CustomerLoginFunctionalitiesTest@5b367418]" started-at="2024-03-13T00:28:12Z" name="VerifyredirectToNonaccessablePageFunctionality" finished-at="2024-03-13T00:28:12Z" duration-ms="349" status="FAIL">
          <exception class="java.lang.AssertionError">
            <message>
              <![CDATA[Customer is able to access the account after logging out. New issue expected [Customer is not access the account after logging out.] but found [Customer is able to access the account after logging out. New issue]]]>
            </message>
            <full-stacktrace>
              <![CDATA[java.lang.AssertionError: Customer is able to access the account after logging out. New issue expected [Customer is not access the account after logging out.] but found [Customer is able to access the account after logging out. New issue]
	at org.testng.Assert.fail(Assert.java:93)
	at org.testng.Assert.failNotEquals(Assert.java:512)
	at org.testng.Assert.assertEqualsImpl(Assert.java:134)
	at org.testng.Assert.assertEquals(Assert.java:115)
	at org.testng.Assert.assertEquals(Assert.java:189)
	at com.crm.qa.testcases.CustomerLoginFunctionalitiesTest.VerifyredirectToNonaccessablePageFunctionality(CustomerLoginFunctionalitiesTest.java:120)
	at java.base/jdk.internal.reflect.NativeMethodAccessorImpl.invoke0(Native Method)
	at java.base/jdk.internal.reflect.NativeMethodAccessorImpl.invoke(NativeMethodAccessorImpl.java:77)
	at java.base/jdk.internal.reflect.DelegatingMethodAccessorImpl.invoke(DelegatingMethodAccessorImpl.java:43)
	at java.base/java.lang.reflect.Method.invoke(Method.java:568)
	at org.testng.internal.MethodInvocationHelper.invokeMethod(MethodInvocationHelper.java:108)
	at org.testng.internal.Invoker.invokeMethod(Invoker.java:661)
	at org.testng.internal.Invoker.invokeTestMethod(Invoker.java:869)
	at org.testng.internal.Invoker.invokeTestMethods(Invoker.java:1193)
	at org.testng.internal.TestMethodWorker.invokeTestMethods(TestMethodWorker.java:126)
	at org.testng.internal.TestMethodWorker.run(TestMethodWorker.java:109)
	at org.testng.TestRunner.privateRun(TestRunner.java:744)
	at org.testng.TestRunner.run(TestRunner.java:602)
	at org.testng.SuiteRunner.runTest(SuiteRunner.java:380)
	at org.testng.SuiteRunner.runSequentially(SuiteRunner.java:375)
	at org.testng.SuiteRunner.privateRun(SuiteRunner.java:340)
	at org.testng.SuiteRunner.run(SuiteRunner.java:289)
	at org.testng.SuiteRunnerWorker.runSuite(SuiteRunnerWorker.java:52)
	at org.testng.SuiteRunnerWorker.run(SuiteRunnerWorker.java:86)
	at org.testng.TestNG.runSuitesSequentially(TestNG.java:1301)
	at org.testng.TestNG.runSuitesLocally(TestNG.java:1226)
	at org.testng.TestNG.runSuites(TestNG.java:1144)
	at org.testng.TestNG.run(TestNG.java:1115)
	at org.testng.remote.AbstractRemoteTestNG.run(AbstractRemoteTestNG.java:115)
	at org.testng.remote.RemoteTestNG.initAndRun(RemoteTestNG.java:251)
	at org.testng.remote.RemoteTestNG.main(RemoteTestNG.java:77)
]]>
            </full-stacktrace>
          </exception> <!-- java.lang.AssertionError -->
          <reporter-output>
          </reporter-output>
        </test-method> <!-- VerifyredirectToNonaccessablePageFunctionality -->
        <test-method is-config="true" signature="tearDown()[pri:0, instance:com.crm.qa.testcases.CustomerLoginFunctionalitiesTest@5b367418]" started-at="2024-03-13T00:28:12Z" name="tearDown" finished-at="2024-03-13T00:28:13Z" duration-ms="768" status="PASS">
          <reporter-output>
          </reporter-output>
        </test-method> <!-- tearDown -->
      </class> <!-- com.crm.qa.testcases.CustomerLoginFunctionalitiesTest -->
      <class name="com.crm.qa.testcases.HomeDashBoardTest">
        <test-method is-config="true" signature="setUp(java.lang.String)[pri:0, instance:com.crm.qa.testcases.HomeDashBoardTest@3697186]" started-at="2024-03-13T00:27:04Z" name="setUp" finished-at="2024-03-13T00:27:12Z" duration-ms="7242" status="PASS">
          <params>
            <param index="0">
              <value>
                <![CDATA[chrome]]>
              </value>
            </param>
          </params>
          <reporter-output>
          </reporter-output>
        </test-method> <!-- setUp -->
        <test-method signature="VerifyTitle()[pri:1, instance:com.crm.qa.testcases.HomeDashBoardTest@3697186]" started-at="2024-03-13T00:27:12Z" name="VerifyTitle" finished-at="2024-03-13T00:27:13Z" duration-ms="1454" status="PASS">
          <reporter-output>
          </reporter-output>
        </test-method> <!-- VerifyTitle -->
        <test-method signature="VerifyHomeBtn()[pri:2, instance:com.crm.qa.testcases.HomeDashBoardTest@3697186]" started-at="2024-03-13T00:27:13Z" name="VerifyHomeBtn" finished-at="2024-03-13T00:27:13Z" duration-ms="142" status="PASS">
          <reporter-output>
          </reporter-output>
        </test-method> <!-- VerifyHomeBtn -->
        <test-method signature="VerifycustLoginBtn()[pri:3, instance:com.crm.qa.testcases.HomeDashBoardTest@3697186]" started-at="2024-03-13T00:27:13Z" name="VerifycustLoginBtn" finished-at="2024-03-13T00:27:13Z" duration-ms="93" status="PASS">
          <reporter-output>
          </reporter-output>
        </test-method> <!-- VerifycustLoginBtn -->
        <test-method signature="VerifybankManagerLoginBtn()[pri:4, instance:com.crm.qa.testcases.HomeDashBoardTest@3697186]" started-at="2024-03-13T00:27:13Z" name="VerifybankManagerLoginBtn" finished-at="2024-03-13T00:27:13Z" duration-ms="67" status="PASS">
          <reporter-output>
          </reporter-output>
        </test-method> <!-- VerifybankManagerLoginBtn -->
        <test-method signature="VerifyHomeBtnFunctionality()[pri:5, instance:com.crm.qa.testcases.HomeDashBoardTest@3697186]" started-at="2024-03-13T00:27:13Z" name="VerifyHomeBtnFunctionality" finished-at="2024-03-13T00:27:14Z" duration-ms="422" status="PASS">
          <reporter-output>
          </reporter-output>
        </test-method> <!-- VerifyHomeBtnFunctionality -->
        <test-method signature="VerifycustLoginBtnFunctionality()[pri:6, instance:com.crm.qa.testcases.HomeDashBoardTest@3697186]" started-at="2024-03-13T00:27:14Z" name="VerifycustLoginBtnFunctionality" finished-at="2024-03-13T00:27:14Z" duration-ms="618" status="PASS">
          <reporter-output>
          </reporter-output>
        </test-method> <!-- VerifycustLoginBtnFunctionality -->
        <test-method signature="VerifybankManagerLoginBtnFunctionality()[pri:7, instance:com.crm.qa.testcases.HomeDashBoardTest@3697186]" started-at="2024-03-13T00:27:14Z" name="VerifybankManagerLoginBtnFunctionality" finished-at="2024-03-13T00:27:15Z" duration-ms="1012" status="PASS">
          <reporter-output>
          </reporter-output>
        </test-method> <!-- VerifybankManagerLoginBtnFunctionality -->
        <test-method signature="VerifyNonAccountCustomersFunctionality()[pri:8, instance:com.crm.qa.testcases.HomeDashBoardTest@3697186]" started-at="2024-03-13T00:27:15Z" name="VerifyNonAccountCustomersFunctionality" finished-at="2024-03-13T00:27:20Z" duration-ms="4429" status="PASS">
          <reporter-output>
          </reporter-output>
        </test-method> <!-- VerifyNonAccountCustomersFunctionality -->
        <test-method is-config="true" signature="tearDown()[pri:0, instance:com.crm.qa.testcases.HomeDashBoardTest@3697186]" started-at="2024-03-13T00:27:20Z" name="tearDown" finished-at="2024-03-13T00:27:20Z" duration-ms="462" status="PASS">
          <reporter-output>
          </reporter-output>
        </test-method> <!-- tearDown -->
      </class> <!-- com.crm.qa.testcases.HomeDashBoardTest -->
      <class name="com.crm.qa.testcases.BankManagerLoginFunctionalitiesTest">
        <test-method is-config="true" signature="setUp(java.lang.String)[pri:0, instance:com.crm.qa.testcases.BankManagerLoginFunctionalitiesTest@1583741e]" started-at="2024-03-13T00:27:20Z" name="setUp" finished-at="2024-03-13T00:27:24Z" duration-ms="3475" status="PASS">
          <params>
            <param index="0">
              <value>
                <![CDATA[chrome]]>
              </value>
            </param>
          </params>
          <reporter-output>
          </reporter-output>
        </test-method> <!-- setUp -->
        <test-method signature="VerifyBankManagerLoginBtnFunctionality()[pri:9, instance:com.crm.qa.testcases.BankManagerLoginFunctionalitiesTest@1583741e]" started-at="2024-03-13T00:27:24Z" name="VerifyBankManagerLoginBtnFunctionality" finished-at="2024-03-13T00:27:25Z" duration-ms="1353" status="PASS">
          <reporter-output>
          </reporter-output>
        </test-method> <!-- VerifyBankManagerLoginBtnFunctionality -->
        <test-method signature="VerifyBankManagerLogin()[pri:10, instance:com.crm.qa.testcases.BankManagerLoginFunctionalitiesTest@1583741e]" started-at="2024-03-13T00:27:25Z" name="VerifyBankManagerLogin" finished-at="2024-03-13T00:27:27Z" duration-ms="1495" status="PASS">
          <reporter-output>
          </reporter-output>
        </test-method> <!-- VerifyBankManagerLogin -->
        <test-method signature="VerifyInvalidFnameBankManagerLogin()[pri:11, instance:com.crm.qa.testcases.BankManagerLoginFunctionalitiesTest@1583741e]" started-at="2024-03-13T00:27:27Z" name="VerifyInvalidFnameBankManagerLogin" finished-at="2024-03-13T00:27:28Z" duration-ms="1091" status="FAIL">
          <exception class="java.lang.AssertionError">
            <message>
              <![CDATA[First name is containing special characters and numbers. New issue expected [Pop-up validation: Unexpected or no success message] but found [Pop-up validation: Customer added successfully]]]>
            </message>
            <full-stacktrace>
              <![CDATA[java.lang.AssertionError: First name is containing special characters and numbers. New issue expected [Pop-up validation: Unexpected or no success message] but found [Pop-up validation: Customer added successfully]
	at org.testng.Assert.fail(Assert.java:93)
	at org.testng.Assert.failNotEquals(Assert.java:512)
	at org.testng.Assert.assertEqualsImpl(Assert.java:134)
	at org.testng.Assert.assertEquals(Assert.java:115)
	at org.testng.Assert.assertEquals(Assert.java:189)
	at com.crm.qa.testcases.BankManagerLoginFunctionalitiesTest.VerifyInvalidFnameBankManagerLogin(BankManagerLoginFunctionalitiesTest.java:44)
	at java.base/jdk.internal.reflect.NativeMethodAccessorImpl.invoke0(Native Method)
	at java.base/jdk.internal.reflect.NativeMethodAccessorImpl.invoke(NativeMethodAccessorImpl.java:77)
	at java.base/jdk.internal.reflect.DelegatingMethodAccessorImpl.invoke(DelegatingMethodAccessorImpl.java:43)
	at java.base/java.lang.reflect.Method.invoke(Method.java:568)
	at org.testng.internal.MethodInvocationHelper.invokeMethod(MethodInvocationHelper.java:108)
	at org.testng.internal.Invoker.invokeMethod(Invoker.java:661)
	at org.testng.internal.Invoker.invokeTestMethod(Invoker.java:869)
	at org.testng.internal.Invoker.invokeTestMethods(Invoker.java:1193)
	at org.testng.internal.TestMethodWorker.invokeTestMethods(TestMethodWorker.java:126)
	at org.testng.internal.TestMethodWorker.run(TestMethodWorker.java:109)
	at org.testng.TestRunner.privateRun(TestRunner.java:744)
	at org.testng.TestRunner.run(TestRunner.java:602)
	at org.testng.SuiteRunner.runTest(SuiteRunner.java:380)
	at org.testng.SuiteRunner.runSequentially(SuiteRunner.java:375)
	at org.testng.SuiteRunner.privateRun(SuiteRunner.java:340)
	at org.testng.SuiteRunner.run(SuiteRunner.java:289)
	at org.testng.SuiteRunnerWorker.runSuite(SuiteRunnerWorker.java:52)
	at org.testng.SuiteRunnerWorker.run(SuiteRunnerWorker.java:86)
	at org.testng.TestNG.runSuitesSequentially(TestNG.java:1301)
	at org.testng.TestNG.runSuitesLocally(TestNG.java:1226)
	at org.testng.TestNG.runSuites(TestNG.java:1144)
	at org.testng.TestNG.run(TestNG.java:1115)
	at org.testng.remote.AbstractRemoteTestNG.run(AbstractRemoteTestNG.java:115)
	at org.testng.remote.RemoteTestNG.initAndRun(RemoteTestNG.java:251)
	at org.testng.remote.RemoteTestNG.main(RemoteTestNG.java:77)
]]>
            </full-stacktrace>
          </exception> <!-- java.lang.AssertionError -->
          <reporter-output>
          </reporter-output>
        </test-method> <!-- VerifyInvalidFnameBankManagerLogin -->
        <test-method signature="VerifyInvalidLnameBankManagerLogin()[pri:12, instance:com.crm.qa.testcases.BankManagerLoginFunctionalitiesTest@1583741e]" started-at="2024-03-13T00:27:28Z" name="VerifyInvalidLnameBankManagerLogin" finished-at="2024-03-13T00:27:29Z" duration-ms="1008" status="FAIL">
          <exception class="java.lang.AssertionError">
            <message>
              <![CDATA[Last name is containing special characters and numbers. New issue expected [Pop-up validation: Unexpected or no success message] but found [Pop-up validation: Customer added successfully]]]>
            </message>
            <full-stacktrace>
              <![CDATA[java.lang.AssertionError: Last name is containing special characters and numbers. New issue expected [Pop-up validation: Unexpected or no success message] but found [Pop-up validation: Customer added successfully]
	at org.testng.Assert.fail(Assert.java:93)
	at org.testng.Assert.failNotEquals(Assert.java:512)
	at org.testng.Assert.assertEqualsImpl(Assert.java:134)
	at org.testng.Assert.assertEquals(Assert.java:115)
	at org.testng.Assert.assertEquals(Assert.java:189)
	at com.crm.qa.testcases.BankManagerLoginFunctionalitiesTest.VerifyInvalidLnameBankManagerLogin(BankManagerLoginFunctionalitiesTest.java:49)
	at java.base/jdk.internal.reflect.NativeMethodAccessorImpl.invoke0(Native Method)
	at java.base/jdk.internal.reflect.NativeMethodAccessorImpl.invoke(NativeMethodAccessorImpl.java:77)
	at java.base/jdk.internal.reflect.DelegatingMethodAccessorImpl.invoke(DelegatingMethodAccessorImpl.java:43)
	at java.base/java.lang.reflect.Method.invoke(Method.java:568)
	at org.testng.internal.MethodInvocationHelper.invokeMethod(MethodInvocationHelper.java:108)
	at org.testng.internal.Invoker.invokeMethod(Invoker.java:661)
	at org.testng.internal.Invoker.invokeTestMethod(Invoker.java:869)
	at org.testng.internal.Invoker.invokeTestMethods(Invoker.java:1193)
	at org.testng.internal.TestMethodWorker.invokeTestMethods(TestMethodWorker.java:126)
	at org.testng.internal.TestMethodWorker.run(TestMethodWorker.java:109)
	at org.testng.TestRunner.privateRun(TestRunner.java:744)
	at org.testng.TestRunner.run(TestRunner.java:602)
	at org.testng.SuiteRunner.runTest(SuiteRunner.java:380)
	at org.testng.SuiteRunner.runSequentially(SuiteRunner.java:375)
	at org.testng.SuiteRunner.privateRun(SuiteRunner.java:340)
	at org.testng.SuiteRunner.run(SuiteRunner.java:289)
	at org.testng.SuiteRunnerWorker.runSuite(SuiteRunnerWorker.java:52)
	at org.testng.SuiteRunnerWorker.run(SuiteRunnerWorker.java:86)
	at org.testng.TestNG.runSuitesSequentially(TestNG.java:1301)
	at org.testng.TestNG.runSuitesLocally(TestNG.java:1226)
	at org.testng.TestNG.runSuites(TestNG.java:1144)
	at org.testng.TestNG.run(TestNG.java:1115)
	at org.testng.remote.AbstractRemoteTestNG.run(AbstractRemoteTestNG.java:115)
	at org.testng.remote.RemoteTestNG.initAndRun(RemoteTestNG.java:251)
	at org.testng.remote.RemoteTestNG.main(RemoteTestNG.java:77)
]]>
            </full-stacktrace>
          </exception> <!-- java.lang.AssertionError -->
          <reporter-output>
          </reporter-output>
        </test-method> <!-- VerifyInvalidLnameBankManagerLogin -->
        <test-method signature="VerifyEmptyFieldBankManagerLogin()[pri:13, instance:com.crm.qa.testcases.BankManagerLoginFunctionalitiesTest@1583741e]" started-at="2024-03-13T00:27:29Z" name="VerifyEmptyFieldBankManagerLogin" finished-at="2024-03-13T00:27:31Z" duration-ms="2286" status="PASS">
          <reporter-output>
          </reporter-output>
        </test-method> <!-- VerifyEmptyFieldBankManagerLogin -->
        <test-method signature="VerifyDuplicateBankManagerLogin()[pri:14, instance:com.crm.qa.testcases.BankManagerLoginFunctionalitiesTest@1583741e]" started-at="2024-03-13T00:27:31Z" name="VerifyDuplicateBankManagerLogin" finished-at="2024-03-13T00:27:34Z" duration-ms="2482" status="PASS">
          <reporter-output>
          </reporter-output>
        </test-method> <!-- VerifyDuplicateBankManagerLogin -->
        <test-method signature="VerifyOpenAccountFunctionality()[pri:15, instance:com.crm.qa.testcases.BankManagerLoginFunctionalitiesTest@1583741e]" started-at="2024-03-13T00:27:34Z" name="VerifyOpenAccountFunctionality" finished-at="2024-03-13T00:27:36Z" duration-ms="2671" status="PASS">
          <reporter-output>
          </reporter-output>
        </test-method> <!-- VerifyOpenAccountFunctionality -->
        <test-method signature="searchCustomersFunctionalityByName()[pri:16, instance:com.crm.qa.testcases.BankManagerLoginFunctionalitiesTest@1583741e]" started-at="2024-03-13T00:27:36Z" name="searchCustomersFunctionalityByName" finished-at="2024-03-13T00:27:38Z" duration-ms="2248" status="PASS">
          <reporter-output>
          </reporter-output>
        </test-method> <!-- searchCustomersFunctionalityByName -->
        <test-method signature="searchCustomersFunctionalityByID()[pri:17, instance:com.crm.qa.testcases.BankManagerLoginFunctionalitiesTest@1583741e]" started-at="2024-03-13T00:27:38Z" name="searchCustomersFunctionalityByID" finished-at="2024-03-13T00:27:39Z" duration-ms="692" status="PASS">
          <reporter-output>
          </reporter-output>
        </test-method> <!-- searchCustomersFunctionalityByID -->
        <test-method signature="searchCustomersFunctionalityByPostCode()[pri:18, instance:com.crm.qa.testcases.BankManagerLoginFunctionalitiesTest@1583741e]" started-at="2024-03-13T00:27:39Z" name="searchCustomersFunctionalityByPostCode" finished-at="2024-03-13T00:27:40Z" duration-ms="511" status="PASS">
          <reporter-output>
          </reporter-output>
        </test-method> <!-- searchCustomersFunctionalityByPostCode -->
        <test-method signature="deleteCustomerFunctionality()[pri:19, instance:com.crm.qa.testcases.BankManagerLoginFunctionalitiesTest@1583741e]" started-at="2024-03-13T00:27:40Z" name="deleteCustomerFunctionality" finished-at="2024-03-13T00:27:41Z" duration-ms="1233" status="PASS">
          <reporter-output>
          </reporter-output>
        </test-method> <!-- deleteCustomerFunctionality -->
        <test-method is-config="true" signature="tearDown()[pri:0, instance:com.crm.qa.testcases.BankManagerLoginFunctionalitiesTest@1583741e]" started-at="2024-03-13T00:27:41Z" name="tearDown" finished-at="2024-03-13T00:27:42Z" duration-ms="657" status="PASS">
          <reporter-output>
          </reporter-output>
        </test-method> <!-- tearDown -->
      </class> <!-- com.crm.qa.testcases.BankManagerLoginFunctionalitiesTest -->
    </test> <!-- GWB-Tests-Chrome -->
    <test started-at="2024-03-12T18:58:13Z" name="GWB-Tests-Firefox" finished-at="2024-03-12T18:59:33Z" duration-ms="80182">
      <class name="com.crm.qa.testcases.CustomerLoginFunctionalitiesTest">
        <test-method is-config="true" signature="setUp(java.lang.String)[pri:0, instance:com.crm.qa.testcases.CustomerLoginFunctionalitiesTest@2421cc4]" started-at="2024-03-13T00:29:05Z" name="setUp" finished-at="2024-03-13T00:29:14Z" duration-ms="9308" status="PASS">
          <params>
            <param index="0">
              <value>
                <![CDATA[firefox]]>
              </value>
            </param>
          </params>
          <reporter-output>
          </reporter-output>
        </test-method> <!-- setUp -->
        <test-method signature="VerifycustLoginBtnFunctionality()[pri:20, instance:com.crm.qa.testcases.CustomerLoginFunctionalitiesTest@2421cc4]" started-at="2024-03-13T00:29:14Z" name="VerifycustLoginBtnFunctionality" finished-at="2024-03-13T00:29:16Z" duration-ms="1946" status="PASS">
          <reporter-output>
          </reporter-output>
        </test-method> <!-- VerifycustLoginBtnFunctionality -->
        <test-method signature="VerifyCustomerLogin()[pri:21, instance:com.crm.qa.testcases.CustomerLoginFunctionalitiesTest@2421cc4]" started-at="2024-03-13T00:29:16Z" name="VerifyCustomerLogin" finished-at="2024-03-13T00:29:17Z" duration-ms="1224" status="PASS">
          <reporter-output>
          </reporter-output>
        </test-method> <!-- VerifyCustomerLogin -->
        <test-method signature="depositValidAmount()[pri:23, instance:com.crm.qa.testcases.CustomerLoginFunctionalitiesTest@2421cc4]" started-at="2024-03-13T00:29:17Z" name="depositValidAmount" finished-at="2024-03-13T00:29:18Z" duration-ms="995" status="PASS">
          <reporter-output>
          </reporter-output>
        </test-method> <!-- depositValidAmount -->
        <test-method signature="depositInValidAmount()[pri:24, instance:com.crm.qa.testcases.CustomerLoginFunctionalitiesTest@2421cc4]" started-at="2024-03-13T00:29:18Z" name="depositInValidAmount" finished-at="2024-03-13T00:29:19Z" duration-ms="631" status="FAIL">
          <exception class="java.lang.AssertionError">
            <message>
              <![CDATA[No warning raised. New issue detected expected [Deposit Successful] but found [Invalid Input]]]>
            </message>
            <full-stacktrace>
              <![CDATA[java.lang.AssertionError: No warning raised. New issue detected expected [Deposit Successful] but found [Invalid Input]
	at org.testng.Assert.fail(Assert.java:93)
	at org.testng.Assert.failNotEquals(Assert.java:512)
	at org.testng.Assert.assertEqualsImpl(Assert.java:134)
	at org.testng.Assert.assertEquals(Assert.java:115)
	at org.testng.Assert.assertEquals(Assert.java:189)
	at com.crm.qa.testcases.CustomerLoginFunctionalitiesTest.depositInValidAmount(CustomerLoginFunctionalitiesTest.java:55)
	at java.base/jdk.internal.reflect.NativeMethodAccessorImpl.invoke0(Native Method)
	at java.base/jdk.internal.reflect.NativeMethodAccessorImpl.invoke(NativeMethodAccessorImpl.java:77)
	at java.base/jdk.internal.reflect.DelegatingMethodAccessorImpl.invoke(DelegatingMethodAccessorImpl.java:43)
	at java.base/java.lang.reflect.Method.invoke(Method.java:568)
	at org.testng.internal.MethodInvocationHelper.invokeMethod(MethodInvocationHelper.java:108)
	at org.testng.internal.Invoker.invokeMethod(Invoker.java:661)
	at org.testng.internal.Invoker.invokeTestMethod(Invoker.java:869)
	at org.testng.internal.Invoker.invokeTestMethods(Invoker.java:1193)
	at org.testng.internal.TestMethodWorker.invokeTestMethods(TestMethodWorker.java:126)
	at org.testng.internal.TestMethodWorker.run(TestMethodWorker.java:109)
	at org.testng.TestRunner.privateRun(TestRunner.java:744)
	at org.testng.TestRunner.run(TestRunner.java:602)
	at org.testng.SuiteRunner.runTest(SuiteRunner.java:380)
	at org.testng.SuiteRunner.runSequentially(SuiteRunner.java:375)
	at org.testng.SuiteRunner.privateRun(SuiteRunner.java:340)
	at org.testng.SuiteRunner.run(SuiteRunner.java:289)
	at org.testng.SuiteRunnerWorker.runSuite(SuiteRunnerWorker.java:52)
	at org.testng.SuiteRunnerWorker.run(SuiteRunnerWorker.java:86)
	at org.testng.TestNG.runSuitesSequentially(TestNG.java:1301)
	at org.testng.TestNG.runSuitesLocally(TestNG.java:1226)
	at org.testng.TestNG.runSuites(TestNG.java:1144)
	at org.testng.TestNG.run(TestNG.java:1115)
	at org.testng.remote.AbstractRemoteTestNG.run(AbstractRemoteTestNG.java:115)
	at org.testng.remote.RemoteTestNG.initAndRun(RemoteTestNG.java:251)
	at org.testng.remote.RemoteTestNG.main(RemoteTestNG.java:77)
]]>
            </full-stacktrace>
          </exception> <!-- java.lang.AssertionError -->
          <reporter-output>
          </reporter-output>
        </test-method> <!-- depositInValidAmount -->
        <test-method signature="depositDecimalAmount()[pri:25, instance:com.crm.qa.testcases.CustomerLoginFunctionalitiesTest@2421cc4]" started-at="2024-03-13T00:29:19Z" name="depositDecimalAmount" finished-at="2024-03-13T00:29:20Z" duration-ms="636" status="PASS">
          <reporter-output>
          </reporter-output>
        </test-method> <!-- depositDecimalAmount -->
        <test-method signature="withdrawValidAmount()[pri:26, instance:com.crm.qa.testcases.CustomerLoginFunctionalitiesTest@2421cc4]" started-at="2024-03-13T00:29:20Z" name="withdrawValidAmount" finished-at="2024-03-13T00:29:23Z" duration-ms="3864" status="PASS">
          <reporter-output>
          </reporter-output>
        </test-method> <!-- withdrawValidAmount -->
        <test-method signature="withdrawInValidAmount()[pri:27, instance:com.crm.qa.testcases.CustomerLoginFunctionalitiesTest@2421cc4]" started-at="2024-03-13T00:29:23Z" name="withdrawInValidAmount" finished-at="2024-03-13T00:29:29Z" duration-ms="5089" status="FAIL">
          <exception class="java.lang.AssertionError">
            <message>
              <![CDATA[No warning raised. New issue detected expected [Transaction successful] but found [Invalid Input]]]>
            </message>
            <full-stacktrace>
              <![CDATA[java.lang.AssertionError: No warning raised. New issue detected expected [Transaction successful] but found [Invalid Input]
	at org.testng.Assert.fail(Assert.java:93)
	at org.testng.Assert.failNotEquals(Assert.java:512)
	at org.testng.Assert.assertEqualsImpl(Assert.java:134)
	at org.testng.Assert.assertEquals(Assert.java:115)
	at org.testng.Assert.assertEquals(Assert.java:189)
	at com.crm.qa.testcases.CustomerLoginFunctionalitiesTest.withdrawInValidAmount(CustomerLoginFunctionalitiesTest.java:76)
	at java.base/jdk.internal.reflect.NativeMethodAccessorImpl.invoke0(Native Method)
	at java.base/jdk.internal.reflect.NativeMethodAccessorImpl.invoke(NativeMethodAccessorImpl.java:77)
	at java.base/jdk.internal.reflect.DelegatingMethodAccessorImpl.invoke(DelegatingMethodAccessorImpl.java:43)
	at java.base/java.lang.reflect.Method.invoke(Method.java:568)
	at org.testng.internal.MethodInvocationHelper.invokeMethod(MethodInvocationHelper.java:108)
	at org.testng.internal.Invoker.invokeMethod(Invoker.java:661)
	at org.testng.internal.Invoker.invokeTestMethod(Invoker.java:869)
	at org.testng.internal.Invoker.invokeTestMethods(Invoker.java:1193)
	at org.testng.internal.TestMethodWorker.invokeTestMethods(TestMethodWorker.java:126)
	at org.testng.internal.TestMethodWorker.run(TestMethodWorker.java:109)
	at org.testng.TestRunner.privateRun(TestRunner.java:744)
	at org.testng.TestRunner.run(TestRunner.java:602)
	at org.testng.SuiteRunner.runTest(SuiteRunner.java:380)
	at org.testng.SuiteRunner.runSequentially(SuiteRunner.java:375)
	at org.testng.SuiteRunner.privateRun(SuiteRunner.java:340)
	at org.testng.SuiteRunner.run(SuiteRunner.java:289)
	at org.testng.SuiteRunnerWorker.runSuite(SuiteRunnerWorker.java:52)
	at org.testng.SuiteRunnerWorker.run(SuiteRunnerWorker.java:86)
	at org.testng.TestNG.runSuitesSequentially(TestNG.java:1301)
	at org.testng.TestNG.runSuitesLocally(TestNG.java:1226)
	at org.testng.TestNG.runSuites(TestNG.java:1144)
	at org.testng.TestNG.run(TestNG.java:1115)
	at org.testng.remote.AbstractRemoteTestNG.run(AbstractRemoteTestNG.java:115)
	at org.testng.remote.RemoteTestNG.initAndRun(RemoteTestNG.java:251)
	at org.testng.remote.RemoteTestNG.main(RemoteTestNG.java:77)
]]>
            </full-stacktrace>
          </exception> <!-- java.lang.AssertionError -->
          <reporter-output>
          </reporter-output>
        </test-method> <!-- withdrawInValidAmount -->
        <test-method signature="withdrawDecimalAmount()[pri:28, instance:com.crm.qa.testcases.CustomerLoginFunctionalitiesTest@2421cc4]" started-at="2024-03-13T00:29:29Z" name="withdrawDecimalAmount" finished-at="2024-03-13T00:29:29Z" duration-ms="684" status="PASS">
          <reporter-output>
          </reporter-output>
        </test-method> <!-- withdrawDecimalAmount -->
        <test-method signature="withdrawInsufficientAmount()[pri:29, instance:com.crm.qa.testcases.CustomerLoginFunctionalitiesTest@2421cc4]" started-at="2024-03-13T00:29:29Z" name="withdrawInsufficientAmount" finished-at="2024-03-13T00:29:30Z" duration-ms="723" status="PASS">
          <reporter-output>
          </reporter-output>
        </test-method> <!-- withdrawInsufficientAmount -->
        <test-method signature="transactionResetFunctionalities()[pri:30, instance:com.crm.qa.testcases.CustomerLoginFunctionalitiesTest@2421cc4]" started-at="2024-03-13T00:29:30Z" name="transactionResetFunctionalities" finished-at="2024-03-13T00:29:32Z" duration-ms="1595" status="FAIL">
          <exception class="java.lang.AssertionError">
            <message>
              <![CDATA[No warning raised. Major Issue detected. Balance is resetting, too. expected [Data reset successful] but found [Data reset unsuccessful]]]>
            </message>
            <full-stacktrace>
              <![CDATA[java.lang.AssertionError: No warning raised. Major Issue detected. Balance is resetting, too. expected [Data reset successful] but found [Data reset unsuccessful]
	at org.testng.Assert.fail(Assert.java:93)
	at org.testng.Assert.failNotEquals(Assert.java:512)
	at org.testng.Assert.assertEqualsImpl(Assert.java:134)
	at org.testng.Assert.assertEquals(Assert.java:115)
	at org.testng.Assert.assertEquals(Assert.java:189)
	at com.crm.qa.testcases.CustomerLoginFunctionalitiesTest.transactionResetFunctionalities(CustomerLoginFunctionalitiesTest.java:95)
	at java.base/jdk.internal.reflect.NativeMethodAccessorImpl.invoke0(Native Method)
	at java.base/jdk.internal.reflect.NativeMethodAccessorImpl.invoke(NativeMethodAccessorImpl.java:77)
	at java.base/jdk.internal.reflect.DelegatingMethodAccessorImpl.invoke(DelegatingMethodAccessorImpl.java:43)
	at java.base/java.lang.reflect.Method.invoke(Method.java:568)
	at org.testng.internal.MethodInvocationHelper.invokeMethod(MethodInvocationHelper.java:108)
	at org.testng.internal.Invoker.invokeMethod(Invoker.java:661)
	at org.testng.internal.Invoker.invokeTestMethod(Invoker.java:869)
	at org.testng.internal.Invoker.invokeTestMethods(Invoker.java:1193)
	at org.testng.internal.TestMethodWorker.invokeTestMethods(TestMethodWorker.java:126)
	at org.testng.internal.TestMethodWorker.run(TestMethodWorker.java:109)
	at org.testng.TestRunner.privateRun(TestRunner.java:744)
	at org.testng.TestRunner.run(TestRunner.java:602)
	at org.testng.SuiteRunner.runTest(SuiteRunner.java:380)
	at org.testng.SuiteRunner.runSequentially(SuiteRunner.java:375)
	at org.testng.SuiteRunner.privateRun(SuiteRunner.java:340)
	at org.testng.SuiteRunner.run(SuiteRunner.java:289)
	at org.testng.SuiteRunnerWorker.runSuite(SuiteRunnerWorker.java:52)
	at org.testng.SuiteRunnerWorker.run(SuiteRunnerWorker.java:86)
	at org.testng.TestNG.runSuitesSequentially(TestNG.java:1301)
	at org.testng.TestNG.runSuitesLocally(TestNG.java:1226)
	at org.testng.TestNG.runSuites(TestNG.java:1144)
	at org.testng.TestNG.run(TestNG.java:1115)
	at org.testng.remote.AbstractRemoteTestNG.run(AbstractRemoteTestNG.java:115)
	at org.testng.remote.RemoteTestNG.initAndRun(RemoteTestNG.java:251)
	at org.testng.remote.RemoteTestNG.main(RemoteTestNG.java:77)
]]>
            </full-stacktrace>
          </exception> <!-- java.lang.AssertionError -->
          <reporter-output>
          </reporter-output>
        </test-method> <!-- transactionResetFunctionalities -->
        <test-method signature="transactionBackFunctionalities()[pri:31, instance:com.crm.qa.testcases.CustomerLoginFunctionalitiesTest@2421cc4]" started-at="2024-03-13T00:29:32Z" name="transactionBackFunctionalities" finished-at="2024-03-13T00:29:32Z" duration-ms="129" status="PASS">
          <reporter-output>
          </reporter-output>
        </test-method> <!-- transactionBackFunctionalities -->
        <test-method signature="VerifyLogoutFunctionality()[pri:32, instance:com.crm.qa.testcases.CustomerLoginFunctionalitiesTest@2421cc4]" started-at="2024-03-13T00:29:32Z" name="VerifyLogoutFunctionality" finished-at="2024-03-13T00:29:32Z" duration-ms="159" status="PASS">
          <reporter-output>
          </reporter-output>
        </test-method> <!-- VerifyLogoutFunctionality -->
        <test-method signature="VerifyPostLogoutFunctionality()[pri:33, instance:com.crm.qa.testcases.CustomerLoginFunctionalitiesTest@2421cc4]" started-at="2024-03-13T00:29:32Z" name="VerifyPostLogoutFunctionality" finished-at="2024-03-13T00:29:32Z" duration-ms="176" status="FAIL">
          <exception class="java.lang.AssertionError">
            <message>
              <![CDATA[Customer is able to visit the session after logging out. New issue expected [Customer is not able to visit the session after logging out.] but found [Customer is able to visit the session after logging out. New issue]]]>
            </message>
            <full-stacktrace>
              <![CDATA[java.lang.AssertionError: Customer is able to visit the session after logging out. New issue expected [Customer is not able to visit the session after logging out.] but found [Customer is able to visit the session after logging out. New issue]
	at org.testng.Assert.fail(Assert.java:93)
	at org.testng.Assert.failNotEquals(Assert.java:512)
	at org.testng.Assert.assertEqualsImpl(Assert.java:134)
	at org.testng.Assert.assertEquals(Assert.java:115)
	at org.testng.Assert.assertEquals(Assert.java:189)
	at com.crm.qa.testcases.CustomerLoginFunctionalitiesTest.VerifyPostLogoutFunctionality(CustomerLoginFunctionalitiesTest.java:115)
	at java.base/jdk.internal.reflect.NativeMethodAccessorImpl.invoke0(Native Method)
	at java.base/jdk.internal.reflect.NativeMethodAccessorImpl.invoke(NativeMethodAccessorImpl.java:77)
	at java.base/jdk.internal.reflect.DelegatingMethodAccessorImpl.invoke(DelegatingMethodAccessorImpl.java:43)
	at java.base/java.lang.reflect.Method.invoke(Method.java:568)
	at org.testng.internal.MethodInvocationHelper.invokeMethod(MethodInvocationHelper.java:108)
	at org.testng.internal.Invoker.invokeMethod(Invoker.java:661)
	at org.testng.internal.Invoker.invokeTestMethod(Invoker.java:869)
	at org.testng.internal.Invoker.invokeTestMethods(Invoker.java:1193)
	at org.testng.internal.TestMethodWorker.invokeTestMethods(TestMethodWorker.java:126)
	at org.testng.internal.TestMethodWorker.run(TestMethodWorker.java:109)
	at org.testng.TestRunner.privateRun(TestRunner.java:744)
	at org.testng.TestRunner.run(TestRunner.java:602)
	at org.testng.SuiteRunner.runTest(SuiteRunner.java:380)
	at org.testng.SuiteRunner.runSequentially(SuiteRunner.java:375)
	at org.testng.SuiteRunner.privateRun(SuiteRunner.java:340)
	at org.testng.SuiteRunner.run(SuiteRunner.java:289)
	at org.testng.SuiteRunnerWorker.runSuite(SuiteRunnerWorker.java:52)
	at org.testng.SuiteRunnerWorker.run(SuiteRunnerWorker.java:86)
	at org.testng.TestNG.runSuitesSequentially(TestNG.java:1301)
	at org.testng.TestNG.runSuitesLocally(TestNG.java:1226)
	at org.testng.TestNG.runSuites(TestNG.java:1144)
	at org.testng.TestNG.run(TestNG.java:1115)
	at org.testng.remote.AbstractRemoteTestNG.run(AbstractRemoteTestNG.java:115)
	at org.testng.remote.RemoteTestNG.initAndRun(RemoteTestNG.java:251)
	at org.testng.remote.RemoteTestNG.main(RemoteTestNG.java:77)
]]>
            </full-stacktrace>
          </exception> <!-- java.lang.AssertionError -->
          <reporter-output>
          </reporter-output>
        </test-method> <!-- VerifyPostLogoutFunctionality -->
        <test-method signature="VerifyredirectToNonaccessablePageFunctionality()[pri:34, instance:com.crm.qa.testcases.CustomerLoginFunctionalitiesTest@2421cc4]" started-at="2024-03-13T00:29:32Z" name="VerifyredirectToNonaccessablePageFunctionality" finished-at="2024-03-13T00:29:32Z" duration-ms="145" status="FAIL">
          <exception class="java.lang.AssertionError">
            <message>
              <![CDATA[Customer is able to access the account after logging out. New issue expected [Customer is not access the account after logging out.] but found [Customer is able to access the account after logging out. New issue]]]>
            </message>
            <full-stacktrace>
              <![CDATA[java.lang.AssertionError: Customer is able to access the account after logging out. New issue expected [Customer is not access the account after logging out.] but found [Customer is able to access the account after logging out. New issue]
	at org.testng.Assert.fail(Assert.java:93)
	at org.testng.Assert.failNotEquals(Assert.java:512)
	at org.testng.Assert.assertEqualsImpl(Assert.java:134)
	at org.testng.Assert.assertEquals(Assert.java:115)
	at org.testng.Assert.assertEquals(Assert.java:189)
	at com.crm.qa.testcases.CustomerLoginFunctionalitiesTest.VerifyredirectToNonaccessablePageFunctionality(CustomerLoginFunctionalitiesTest.java:120)
	at java.base/jdk.internal.reflect.NativeMethodAccessorImpl.invoke0(Native Method)
	at java.base/jdk.internal.reflect.NativeMethodAccessorImpl.invoke(NativeMethodAccessorImpl.java:77)
	at java.base/jdk.internal.reflect.DelegatingMethodAccessorImpl.invoke(DelegatingMethodAccessorImpl.java:43)
	at java.base/java.lang.reflect.Method.invoke(Method.java:568)
	at org.testng.internal.MethodInvocationHelper.invokeMethod(MethodInvocationHelper.java:108)
	at org.testng.internal.Invoker.invokeMethod(Invoker.java:661)
	at org.testng.internal.Invoker.invokeTestMethod(Invoker.java:869)
	at org.testng.internal.Invoker.invokeTestMethods(Invoker.java:1193)
	at org.testng.internal.TestMethodWorker.invokeTestMethods(TestMethodWorker.java:126)
	at org.testng.internal.TestMethodWorker.run(TestMethodWorker.java:109)
	at org.testng.TestRunner.privateRun(TestRunner.java:744)
	at org.testng.TestRunner.run(TestRunner.java:602)
	at org.testng.SuiteRunner.runTest(SuiteRunner.java:380)
	at org.testng.SuiteRunner.runSequentially(SuiteRunner.java:375)
	at org.testng.SuiteRunner.privateRun(SuiteRunner.java:340)
	at org.testng.SuiteRunner.run(SuiteRunner.java:289)
	at org.testng.SuiteRunnerWorker.runSuite(SuiteRunnerWorker.java:52)
	at org.testng.SuiteRunnerWorker.run(SuiteRunnerWorker.java:86)
	at org.testng.TestNG.runSuitesSequentially(TestNG.java:1301)
	at org.testng.TestNG.runSuitesLocally(TestNG.java:1226)
	at org.testng.TestNG.runSuites(TestNG.java:1144)
	at org.testng.TestNG.run(TestNG.java:1115)
	at org.testng.remote.AbstractRemoteTestNG.run(AbstractRemoteTestNG.java:115)
	at org.testng.remote.RemoteTestNG.initAndRun(RemoteTestNG.java:251)
	at org.testng.remote.RemoteTestNG.main(RemoteTestNG.java:77)
]]>
            </full-stacktrace>
          </exception> <!-- java.lang.AssertionError -->
          <reporter-output>
          </reporter-output>
        </test-method> <!-- VerifyredirectToNonaccessablePageFunctionality -->
        <test-method is-config="true" signature="tearDown()[pri:0, instance:com.crm.qa.testcases.CustomerLoginFunctionalitiesTest@2421cc4]" started-at="2024-03-13T00:29:32Z" name="tearDown" finished-at="2024-03-13T00:29:33Z" duration-ms="1097" status="PASS">
          <reporter-output>
          </reporter-output>
        </test-method> <!-- tearDown -->
      </class> <!-- com.crm.qa.testcases.CustomerLoginFunctionalitiesTest -->
      <class name="com.crm.qa.testcases.HomeDashBoardTest">
        <test-method is-config="true" signature="setUp(java.lang.String)[pri:0, instance:com.crm.qa.testcases.HomeDashBoardTest@68702e03]" started-at="2024-03-13T00:28:13Z" name="setUp" finished-at="2024-03-13T00:28:24Z" duration-ms="11110" status="PASS">
          <params>
            <param index="0">
              <value>
                <![CDATA[firefox]]>
              </value>
            </param>
          </params>
          <reporter-output>
          </reporter-output>
        </test-method> <!-- setUp -->
        <test-method signature="VerifyTitle()[pri:1, instance:com.crm.qa.testcases.HomeDashBoardTest@68702e03]" started-at="2024-03-13T00:28:24Z" name="VerifyTitle" finished-at="2024-03-13T00:28:26Z" duration-ms="1813" status="PASS">
          <reporter-output>
          </reporter-output>
        </test-method> <!-- VerifyTitle -->
        <test-method signature="VerifyHomeBtn()[pri:2, instance:com.crm.qa.testcases.HomeDashBoardTest@68702e03]" started-at="2024-03-13T00:28:26Z" name="VerifyHomeBtn" finished-at="2024-03-13T00:28:26Z" duration-ms="52" status="PASS">
          <reporter-output>
          </reporter-output>
        </test-method> <!-- VerifyHomeBtn -->
        <test-method signature="VerifycustLoginBtn()[pri:3, instance:com.crm.qa.testcases.HomeDashBoardTest@68702e03]" started-at="2024-03-13T00:28:26Z" name="VerifycustLoginBtn" finished-at="2024-03-13T00:28:26Z" duration-ms="54" status="PASS">
          <reporter-output>
          </reporter-output>
        </test-method> <!-- VerifycustLoginBtn -->
        <test-method signature="VerifybankManagerLoginBtn()[pri:4, instance:com.crm.qa.testcases.HomeDashBoardTest@68702e03]" started-at="2024-03-13T00:28:26Z" name="VerifybankManagerLoginBtn" finished-at="2024-03-13T00:28:26Z" duration-ms="47" status="PASS">
          <reporter-output>
          </reporter-output>
        </test-method> <!-- VerifybankManagerLoginBtn -->
        <test-method signature="VerifyHomeBtnFunctionality()[pri:5, instance:com.crm.qa.testcases.HomeDashBoardTest@68702e03]" started-at="2024-03-13T00:28:26Z" name="VerifyHomeBtnFunctionality" finished-at="2024-03-13T00:28:27Z" duration-ms="364" status="PASS">
          <reporter-output>
          </reporter-output>
        </test-method> <!-- VerifyHomeBtnFunctionality -->
        <test-method signature="VerifycustLoginBtnFunctionality()[pri:6, instance:com.crm.qa.testcases.HomeDashBoardTest@68702e03]" started-at="2024-03-13T00:28:27Z" name="VerifycustLoginBtnFunctionality" finished-at="2024-03-13T00:28:27Z" duration-ms="633" status="PASS">
          <reporter-output>
          </reporter-output>
        </test-method> <!-- VerifycustLoginBtnFunctionality -->
        <test-method signature="VerifybankManagerLoginBtnFunctionality()[pri:7, instance:com.crm.qa.testcases.HomeDashBoardTest@68702e03]" started-at="2024-03-13T00:28:27Z" name="VerifybankManagerLoginBtnFunctionality" finished-at="2024-03-13T00:28:28Z" duration-ms="1043" status="PASS">
          <reporter-output>
          </reporter-output>
        </test-method> <!-- VerifybankManagerLoginBtnFunctionality -->
        <test-method signature="VerifyNonAccountCustomersFunctionality()[pri:8, instance:com.crm.qa.testcases.HomeDashBoardTest@68702e03]" started-at="2024-03-13T00:28:28Z" name="VerifyNonAccountCustomersFunctionality" finished-at="2024-03-13T00:28:33Z" duration-ms="4586" status="PASS">
          <reporter-output>
          </reporter-output>
        </test-method> <!-- VerifyNonAccountCustomersFunctionality -->
        <test-method is-config="true" signature="tearDown()[pri:0, instance:com.crm.qa.testcases.HomeDashBoardTest@68702e03]" started-at="2024-03-13T00:28:33Z" name="tearDown" finished-at="2024-03-13T00:28:34Z" duration-ms="1313" status="PASS">
          <reporter-output>
          </reporter-output>
        </test-method> <!-- tearDown -->
      </class> <!-- com.crm.qa.testcases.HomeDashBoardTest -->
      <class name="com.crm.qa.testcases.BankManagerLoginFunctionalitiesTest">
        <test-method is-config="true" signature="setUp(java.lang.String)[pri:0, instance:com.crm.qa.testcases.BankManagerLoginFunctionalitiesTest@7a220c9a]" started-at="2024-03-13T00:28:34Z" name="setUp" finished-at="2024-03-13T00:28:43Z" duration-ms="9107" status="PASS">
          <params>
            <param index="0">
              <value>
                <![CDATA[firefox]]>
              </value>
            </param>
          </params>
          <reporter-output>
          </reporter-output>
        </test-method> <!-- setUp -->
        <test-method signature="VerifyBankManagerLoginBtnFunctionality()[pri:9, instance:com.crm.qa.testcases.BankManagerLoginFunctionalitiesTest@7a220c9a]" started-at="2024-03-13T00:28:43Z" name="VerifyBankManagerLoginBtnFunctionality" finished-at="2024-03-13T00:28:46Z" duration-ms="3057" status="PASS">
          <reporter-output>
          </reporter-output>
        </test-method> <!-- VerifyBankManagerLoginBtnFunctionality -->
        <test-method signature="VerifyBankManagerLogin()[pri:10, instance:com.crm.qa.testcases.BankManagerLoginFunctionalitiesTest@7a220c9a]" started-at="2024-03-13T00:28:46Z" name="VerifyBankManagerLogin" finished-at="2024-03-13T00:28:48Z" duration-ms="1226" status="PASS">
          <reporter-output>
          </reporter-output>
        </test-method> <!-- VerifyBankManagerLogin -->
        <test-method signature="VerifyInvalidFnameBankManagerLogin()[pri:11, instance:com.crm.qa.testcases.BankManagerLoginFunctionalitiesTest@7a220c9a]" started-at="2024-03-13T00:28:48Z" name="VerifyInvalidFnameBankManagerLogin" finished-at="2024-03-13T00:28:48Z" duration-ms="646" status="FAIL">
          <exception class="java.lang.AssertionError">
            <message>
              <![CDATA[First name is containing special characters and numbers. New issue expected [Pop-up validation: Unexpected or no success message] but found [Pop-up validation: Customer added successfully]]]>
            </message>
            <full-stacktrace>
              <![CDATA[java.lang.AssertionError: First name is containing special characters and numbers. New issue expected [Pop-up validation: Unexpected or no success message] but found [Pop-up validation: Customer added successfully]
	at org.testng.Assert.fail(Assert.java:93)
	at org.testng.Assert.failNotEquals(Assert.java:512)
	at org.testng.Assert.assertEqualsImpl(Assert.java:134)
	at org.testng.Assert.assertEquals(Assert.java:115)
	at org.testng.Assert.assertEquals(Assert.java:189)
	at com.crm.qa.testcases.BankManagerLoginFunctionalitiesTest.VerifyInvalidFnameBankManagerLogin(BankManagerLoginFunctionalitiesTest.java:44)
	at java.base/jdk.internal.reflect.NativeMethodAccessorImpl.invoke0(Native Method)
	at java.base/jdk.internal.reflect.NativeMethodAccessorImpl.invoke(NativeMethodAccessorImpl.java:77)
	at java.base/jdk.internal.reflect.DelegatingMethodAccessorImpl.invoke(DelegatingMethodAccessorImpl.java:43)
	at java.base/java.lang.reflect.Method.invoke(Method.java:568)
	at org.testng.internal.MethodInvocationHelper.invokeMethod(MethodInvocationHelper.java:108)
	at org.testng.internal.Invoker.invokeMethod(Invoker.java:661)
	at org.testng.internal.Invoker.invokeTestMethod(Invoker.java:869)
	at org.testng.internal.Invoker.invokeTestMethods(Invoker.java:1193)
	at org.testng.internal.TestMethodWorker.invokeTestMethods(TestMethodWorker.java:126)
	at org.testng.internal.TestMethodWorker.run(TestMethodWorker.java:109)
	at org.testng.TestRunner.privateRun(TestRunner.java:744)
	at org.testng.TestRunner.run(TestRunner.java:602)
	at org.testng.SuiteRunner.runTest(SuiteRunner.java:380)
	at org.testng.SuiteRunner.runSequentially(SuiteRunner.java:375)
	at org.testng.SuiteRunner.privateRun(SuiteRunner.java:340)
	at org.testng.SuiteRunner.run(SuiteRunner.java:289)
	at org.testng.SuiteRunnerWorker.runSuite(SuiteRunnerWorker.java:52)
	at org.testng.SuiteRunnerWorker.run(SuiteRunnerWorker.java:86)
	at org.testng.TestNG.runSuitesSequentially(TestNG.java:1301)
	at org.testng.TestNG.runSuitesLocally(TestNG.java:1226)
	at org.testng.TestNG.runSuites(TestNG.java:1144)
	at org.testng.TestNG.run(TestNG.java:1115)
	at org.testng.remote.AbstractRemoteTestNG.run(AbstractRemoteTestNG.java:115)
	at org.testng.remote.RemoteTestNG.initAndRun(RemoteTestNG.java:251)
	at org.testng.remote.RemoteTestNG.main(RemoteTestNG.java:77)
]]>
            </full-stacktrace>
          </exception> <!-- java.lang.AssertionError -->
          <reporter-output>
          </reporter-output>
        </test-method> <!-- VerifyInvalidFnameBankManagerLogin -->
        <test-method signature="VerifyInvalidLnameBankManagerLogin()[pri:12, instance:com.crm.qa.testcases.BankManagerLoginFunctionalitiesTest@7a220c9a]" started-at="2024-03-13T00:28:48Z" name="VerifyInvalidLnameBankManagerLogin" finished-at="2024-03-13T00:28:49Z" duration-ms="648" status="FAIL">
          <exception class="java.lang.AssertionError">
            <message>
              <![CDATA[Last name is containing special characters and numbers. New issue expected [Pop-up validation: Unexpected or no success message] but found [Pop-up validation: Customer added successfully]]]>
            </message>
            <full-stacktrace>
              <![CDATA[java.lang.AssertionError: Last name is containing special characters and numbers. New issue expected [Pop-up validation: Unexpected or no success message] but found [Pop-up validation: Customer added successfully]
	at org.testng.Assert.fail(Assert.java:93)
	at org.testng.Assert.failNotEquals(Assert.java:512)
	at org.testng.Assert.assertEqualsImpl(Assert.java:134)
	at org.testng.Assert.assertEquals(Assert.java:115)
	at org.testng.Assert.assertEquals(Assert.java:189)
	at com.crm.qa.testcases.BankManagerLoginFunctionalitiesTest.VerifyInvalidLnameBankManagerLogin(BankManagerLoginFunctionalitiesTest.java:49)
	at java.base/jdk.internal.reflect.NativeMethodAccessorImpl.invoke0(Native Method)
	at java.base/jdk.internal.reflect.NativeMethodAccessorImpl.invoke(NativeMethodAccessorImpl.java:77)
	at java.base/jdk.internal.reflect.DelegatingMethodAccessorImpl.invoke(DelegatingMethodAccessorImpl.java:43)
	at java.base/java.lang.reflect.Method.invoke(Method.java:568)
	at org.testng.internal.MethodInvocationHelper.invokeMethod(MethodInvocationHelper.java:108)
	at org.testng.internal.Invoker.invokeMethod(Invoker.java:661)
	at org.testng.internal.Invoker.invokeTestMethod(Invoker.java:869)
	at org.testng.internal.Invoker.invokeTestMethods(Invoker.java:1193)
	at org.testng.internal.TestMethodWorker.invokeTestMethods(TestMethodWorker.java:126)
	at org.testng.internal.TestMethodWorker.run(TestMethodWorker.java:109)
	at org.testng.TestRunner.privateRun(TestRunner.java:744)
	at org.testng.TestRunner.run(TestRunner.java:602)
	at org.testng.SuiteRunner.runTest(SuiteRunner.java:380)
	at org.testng.SuiteRunner.runSequentially(SuiteRunner.java:375)
	at org.testng.SuiteRunner.privateRun(SuiteRunner.java:340)
	at org.testng.SuiteRunner.run(SuiteRunner.java:289)
	at org.testng.SuiteRunnerWorker.runSuite(SuiteRunnerWorker.java:52)
	at org.testng.SuiteRunnerWorker.run(SuiteRunnerWorker.java:86)
	at org.testng.TestNG.runSuitesSequentially(TestNG.java:1301)
	at org.testng.TestNG.runSuitesLocally(TestNG.java:1226)
	at org.testng.TestNG.runSuites(TestNG.java:1144)
	at org.testng.TestNG.run(TestNG.java:1115)
	at org.testng.remote.AbstractRemoteTestNG.run(AbstractRemoteTestNG.java:115)
	at org.testng.remote.RemoteTestNG.initAndRun(RemoteTestNG.java:251)
	at org.testng.remote.RemoteTestNG.main(RemoteTestNG.java:77)
]]>
            </full-stacktrace>
          </exception> <!-- java.lang.AssertionError -->
          <reporter-output>
          </reporter-output>
        </test-method> <!-- VerifyInvalidLnameBankManagerLogin -->
        <test-method signature="VerifyEmptyFieldBankManagerLogin()[pri:13, instance:com.crm.qa.testcases.BankManagerLoginFunctionalitiesTest@7a220c9a]" started-at="2024-03-13T00:28:49Z" name="VerifyEmptyFieldBankManagerLogin" finished-at="2024-03-13T00:28:52Z" duration-ms="2873" status="PASS">
          <reporter-output>
          </reporter-output>
        </test-method> <!-- VerifyEmptyFieldBankManagerLogin -->
        <test-method signature="VerifyDuplicateBankManagerLogin()[pri:14, instance:com.crm.qa.testcases.BankManagerLoginFunctionalitiesTest@7a220c9a]" started-at="2024-03-13T00:28:52Z" name="VerifyDuplicateBankManagerLogin" finished-at="2024-03-13T00:28:56Z" duration-ms="4510" status="PASS">
          <reporter-output>
          </reporter-output>
        </test-method> <!-- VerifyDuplicateBankManagerLogin -->
        <test-method signature="VerifyOpenAccountFunctionality()[pri:15, instance:com.crm.qa.testcases.BankManagerLoginFunctionalitiesTest@7a220c9a]" started-at="2024-03-13T00:28:56Z" name="VerifyOpenAccountFunctionality" finished-at="2024-03-13T00:28:59Z" duration-ms="3183" status="PASS">
          <reporter-output>
          </reporter-output>
        </test-method> <!-- VerifyOpenAccountFunctionality -->
        <test-method signature="searchCustomersFunctionalityByName()[pri:16, instance:com.crm.qa.testcases.BankManagerLoginFunctionalitiesTest@7a220c9a]" started-at="2024-03-13T00:28:59Z" name="searchCustomersFunctionalityByName" finished-at="2024-03-13T00:29:02Z" duration-ms="2182" status="PASS">
          <reporter-output>
          </reporter-output>
        </test-method> <!-- searchCustomersFunctionalityByName -->
        <test-method signature="searchCustomersFunctionalityByID()[pri:17, instance:com.crm.qa.testcases.BankManagerLoginFunctionalitiesTest@7a220c9a]" started-at="2024-03-13T00:29:02Z" name="searchCustomersFunctionalityByID" finished-at="2024-03-13T00:29:02Z" duration-ms="477" status="PASS">
          <reporter-output>
          </reporter-output>
        </test-method> <!-- searchCustomersFunctionalityByID -->
        <test-method signature="searchCustomersFunctionalityByPostCode()[pri:18, instance:com.crm.qa.testcases.BankManagerLoginFunctionalitiesTest@7a220c9a]" started-at="2024-03-13T00:29:02Z" name="searchCustomersFunctionalityByPostCode" finished-at="2024-03-13T00:29:02Z" duration-ms="402" status="PASS">
          <reporter-output>
          </reporter-output>
        </test-method> <!-- searchCustomersFunctionalityByPostCode -->
        <test-method signature="deleteCustomerFunctionality()[pri:19, instance:com.crm.qa.testcases.BankManagerLoginFunctionalitiesTest@7a220c9a]" started-at="2024-03-13T00:29:02Z" name="deleteCustomerFunctionality" finished-at="2024-03-13T00:29:04Z" duration-ms="1181" status="PASS">
          <reporter-output>
          </reporter-output>
        </test-method> <!-- deleteCustomerFunctionality -->
        <test-method is-config="true" signature="tearDown()[pri:0, instance:com.crm.qa.testcases.BankManagerLoginFunctionalitiesTest@7a220c9a]" started-at="2024-03-13T00:29:04Z" name="tearDown" finished-at="2024-03-13T00:29:05Z" duration-ms="1209" status="PASS">
          <reporter-output>
          </reporter-output>
        </test-method> <!-- tearDown -->
      </class> <!-- com.crm.qa.testcases.BankManagerLoginFunctionalitiesTest -->
    </test> <!-- GWB-Tests-Firefox -->
    <test started-at="2024-03-12T18:59:33Z" name="GWB-Tests-Edge" finished-at="2024-03-12T19:00:48Z" duration-ms="74210">
      <class name="com.crm.qa.testcases.CustomerLoginFunctionalitiesTest">
        <test-method is-config="true" signature="setUp(java.lang.String)[pri:0, instance:com.crm.qa.testcases.CustomerLoginFunctionalitiesTest@b4711e2]" started-at="2024-03-13T00:30:20Z" name="setUp" finished-at="2024-03-13T00:30:25Z" duration-ms="5317" status="PASS">
          <params>
            <param index="0">
              <value>
                <![CDATA[edge]]>
              </value>
            </param>
          </params>
          <reporter-output>
          </reporter-output>
        </test-method> <!-- setUp -->
        <test-method signature="VerifycustLoginBtnFunctionality()[pri:20, instance:com.crm.qa.testcases.CustomerLoginFunctionalitiesTest@b4711e2]" started-at="2024-03-13T00:30:25Z" name="VerifycustLoginBtnFunctionality" finished-at="2024-03-13T00:30:29Z" duration-ms="4184" status="PASS">
          <reporter-output>
          </reporter-output>
        </test-method> <!-- VerifycustLoginBtnFunctionality -->
        <test-method signature="VerifyCustomerLogin()[pri:21, instance:com.crm.qa.testcases.CustomerLoginFunctionalitiesTest@b4711e2]" started-at="2024-03-13T00:30:29Z" name="VerifyCustomerLogin" finished-at="2024-03-13T00:30:31Z" duration-ms="2041" status="PASS">
          <reporter-output>
          </reporter-output>
        </test-method> <!-- VerifyCustomerLogin -->
        <test-method signature="depositValidAmount()[pri:23, instance:com.crm.qa.testcases.CustomerLoginFunctionalitiesTest@b4711e2]" started-at="2024-03-13T00:30:31Z" name="depositValidAmount" finished-at="2024-03-13T00:30:35Z" duration-ms="3335" status="PASS">
          <reporter-output>
          </reporter-output>
        </test-method> <!-- depositValidAmount -->
        <test-method signature="depositInValidAmount()[pri:24, instance:com.crm.qa.testcases.CustomerLoginFunctionalitiesTest@b4711e2]" started-at="2024-03-13T00:30:35Z" name="depositInValidAmount" finished-at="2024-03-13T00:30:35Z" duration-ms="684" status="FAIL">
          <exception class="java.lang.AssertionError">
            <message>
              <![CDATA[No warning raised. New issue detected expected [Deposit Successful] but found [Invalid Input]]]>
            </message>
            <full-stacktrace>
              <![CDATA[java.lang.AssertionError: No warning raised. New issue detected expected [Deposit Successful] but found [Invalid Input]
	at org.testng.Assert.fail(Assert.java:93)
	at org.testng.Assert.failNotEquals(Assert.java:512)
	at org.testng.Assert.assertEqualsImpl(Assert.java:134)
	at org.testng.Assert.assertEquals(Assert.java:115)
	at org.testng.Assert.assertEquals(Assert.java:189)
	at com.crm.qa.testcases.CustomerLoginFunctionalitiesTest.depositInValidAmount(CustomerLoginFunctionalitiesTest.java:55)
	at java.base/jdk.internal.reflect.NativeMethodAccessorImpl.invoke0(Native Method)
	at java.base/jdk.internal.reflect.NativeMethodAccessorImpl.invoke(NativeMethodAccessorImpl.java:77)
	at java.base/jdk.internal.reflect.DelegatingMethodAccessorImpl.invoke(DelegatingMethodAccessorImpl.java:43)
	at java.base/java.lang.reflect.Method.invoke(Method.java:568)
	at org.testng.internal.MethodInvocationHelper.invokeMethod(MethodInvocationHelper.java:108)
	at org.testng.internal.Invoker.invokeMethod(Invoker.java:661)
	at org.testng.internal.Invoker.invokeTestMethod(Invoker.java:869)
	at org.testng.internal.Invoker.invokeTestMethods(Invoker.java:1193)
	at org.testng.internal.TestMethodWorker.invokeTestMethods(TestMethodWorker.java:126)
	at org.testng.internal.TestMethodWorker.run(TestMethodWorker.java:109)
	at org.testng.TestRunner.privateRun(TestRunner.java:744)
	at org.testng.TestRunner.run(TestRunner.java:602)
	at org.testng.SuiteRunner.runTest(SuiteRunner.java:380)
	at org.testng.SuiteRunner.runSequentially(SuiteRunner.java:375)
	at org.testng.SuiteRunner.privateRun(SuiteRunner.java:340)
	at org.testng.SuiteRunner.run(SuiteRunner.java:289)
	at org.testng.SuiteRunnerWorker.runSuite(SuiteRunnerWorker.java:52)
	at org.testng.SuiteRunnerWorker.run(SuiteRunnerWorker.java:86)
	at org.testng.TestNG.runSuitesSequentially(TestNG.java:1301)
	at org.testng.TestNG.runSuitesLocally(TestNG.java:1226)
	at org.testng.TestNG.runSuites(TestNG.java:1144)
	at org.testng.TestNG.run(TestNG.java:1115)
	at org.testng.remote.AbstractRemoteTestNG.run(AbstractRemoteTestNG.java:115)
	at org.testng.remote.RemoteTestNG.initAndRun(RemoteTestNG.java:251)
	at org.testng.remote.RemoteTestNG.main(RemoteTestNG.java:77)
]]>
            </full-stacktrace>
          </exception> <!-- java.lang.AssertionError -->
          <reporter-output>
          </reporter-output>
        </test-method> <!-- depositInValidAmount -->
        <test-method signature="depositDecimalAmount()[pri:25, instance:com.crm.qa.testcases.CustomerLoginFunctionalitiesTest@b4711e2]" started-at="2024-03-13T00:30:35Z" name="depositDecimalAmount" finished-at="2024-03-13T00:30:36Z" duration-ms="691" status="PASS">
          <reporter-output>
          </reporter-output>
        </test-method> <!-- depositDecimalAmount -->
        <test-method signature="withdrawValidAmount()[pri:26, instance:com.crm.qa.testcases.CustomerLoginFunctionalitiesTest@b4711e2]" started-at="2024-03-13T00:30:36Z" name="withdrawValidAmount" finished-at="2024-03-13T00:30:40Z" duration-ms="3702" status="PASS">
          <reporter-output>
          </reporter-output>
        </test-method> <!-- withdrawValidAmount -->
        <test-method signature="withdrawInValidAmount()[pri:27, instance:com.crm.qa.testcases.CustomerLoginFunctionalitiesTest@b4711e2]" started-at="2024-03-13T00:30:40Z" name="withdrawInValidAmount" finished-at="2024-03-13T00:30:41Z" duration-ms="1634" status="FAIL">
          <exception class="java.lang.AssertionError">
            <message>
              <![CDATA[No warning raised. New issue detected expected [Transaction successful] but found [Invalid Input]]]>
            </message>
            <full-stacktrace>
              <![CDATA[java.lang.AssertionError: No warning raised. New issue detected expected [Transaction successful] but found [Invalid Input]
	at org.testng.Assert.fail(Assert.java:93)
	at org.testng.Assert.failNotEquals(Assert.java:512)
	at org.testng.Assert.assertEqualsImpl(Assert.java:134)
	at org.testng.Assert.assertEquals(Assert.java:115)
	at org.testng.Assert.assertEquals(Assert.java:189)
	at com.crm.qa.testcases.CustomerLoginFunctionalitiesTest.withdrawInValidAmount(CustomerLoginFunctionalitiesTest.java:76)
	at java.base/jdk.internal.reflect.NativeMethodAccessorImpl.invoke0(Native Method)
	at java.base/jdk.internal.reflect.NativeMethodAccessorImpl.invoke(NativeMethodAccessorImpl.java:77)
	at java.base/jdk.internal.reflect.DelegatingMethodAccessorImpl.invoke(DelegatingMethodAccessorImpl.java:43)
	at java.base/java.lang.reflect.Method.invoke(Method.java:568)
	at org.testng.internal.MethodInvocationHelper.invokeMethod(MethodInvocationHelper.java:108)
	at org.testng.internal.Invoker.invokeMethod(Invoker.java:661)
	at org.testng.internal.Invoker.invokeTestMethod(Invoker.java:869)
	at org.testng.internal.Invoker.invokeTestMethods(Invoker.java:1193)
	at org.testng.internal.TestMethodWorker.invokeTestMethods(TestMethodWorker.java:126)
	at org.testng.internal.TestMethodWorker.run(TestMethodWorker.java:109)
	at org.testng.TestRunner.privateRun(TestRunner.java:744)
	at org.testng.TestRunner.run(TestRunner.java:602)
	at org.testng.SuiteRunner.runTest(SuiteRunner.java:380)
	at org.testng.SuiteRunner.runSequentially(SuiteRunner.java:375)
	at org.testng.SuiteRunner.privateRun(SuiteRunner.java:340)
	at org.testng.SuiteRunner.run(SuiteRunner.java:289)
	at org.testng.SuiteRunnerWorker.runSuite(SuiteRunnerWorker.java:52)
	at org.testng.SuiteRunnerWorker.run(SuiteRunnerWorker.java:86)
	at org.testng.TestNG.runSuitesSequentially(TestNG.java:1301)
	at org.testng.TestNG.runSuitesLocally(TestNG.java:1226)
	at org.testng.TestNG.runSuites(TestNG.java:1144)
	at org.testng.TestNG.run(TestNG.java:1115)
	at org.testng.remote.AbstractRemoteTestNG.run(AbstractRemoteTestNG.java:115)
	at org.testng.remote.RemoteTestNG.initAndRun(RemoteTestNG.java:251)
	at org.testng.remote.RemoteTestNG.main(RemoteTestNG.java:77)
]]>
            </full-stacktrace>
          </exception> <!-- java.lang.AssertionError -->
          <reporter-output>
          </reporter-output>
        </test-method> <!-- withdrawInValidAmount -->
        <test-method signature="withdrawDecimalAmount()[pri:28, instance:com.crm.qa.testcases.CustomerLoginFunctionalitiesTest@b4711e2]" started-at="2024-03-13T00:30:41Z" name="withdrawDecimalAmount" finished-at="2024-03-13T00:30:42Z" duration-ms="781" status="PASS">
          <reporter-output>
          </reporter-output>
        </test-method> <!-- withdrawDecimalAmount -->
        <test-method signature="withdrawInsufficientAmount()[pri:29, instance:com.crm.qa.testcases.CustomerLoginFunctionalitiesTest@b4711e2]" started-at="2024-03-13T00:30:42Z" name="withdrawInsufficientAmount" finished-at="2024-03-13T00:30:43Z" duration-ms="754" status="PASS">
          <reporter-output>
          </reporter-output>
        </test-method> <!-- withdrawInsufficientAmount -->
        <test-method signature="transactionResetFunctionalities()[pri:30, instance:com.crm.qa.testcases.CustomerLoginFunctionalitiesTest@b4711e2]" started-at="2024-03-13T00:30:43Z" name="transactionResetFunctionalities" finished-at="2024-03-13T00:30:46Z" duration-ms="2680" status="FAIL">
          <exception class="java.lang.AssertionError">
            <message>
              <![CDATA[No warning raised. Major Issue detected. Balance is resetting, too. expected [Data reset successful] but found [Data reset unsuccessful]]]>
            </message>
            <full-stacktrace>
              <![CDATA[java.lang.AssertionError: No warning raised. Major Issue detected. Balance is resetting, too. expected [Data reset successful] but found [Data reset unsuccessful]
	at org.testng.Assert.fail(Assert.java:93)
	at org.testng.Assert.failNotEquals(Assert.java:512)
	at org.testng.Assert.assertEqualsImpl(Assert.java:134)
	at org.testng.Assert.assertEquals(Assert.java:115)
	at org.testng.Assert.assertEquals(Assert.java:189)
	at com.crm.qa.testcases.CustomerLoginFunctionalitiesTest.transactionResetFunctionalities(CustomerLoginFunctionalitiesTest.java:95)
	at java.base/jdk.internal.reflect.NativeMethodAccessorImpl.invoke0(Native Method)
	at java.base/jdk.internal.reflect.NativeMethodAccessorImpl.invoke(NativeMethodAccessorImpl.java:77)
	at java.base/jdk.internal.reflect.DelegatingMethodAccessorImpl.invoke(DelegatingMethodAccessorImpl.java:43)
	at java.base/java.lang.reflect.Method.invoke(Method.java:568)
	at org.testng.internal.MethodInvocationHelper.invokeMethod(MethodInvocationHelper.java:108)
	at org.testng.internal.Invoker.invokeMethod(Invoker.java:661)
	at org.testng.internal.Invoker.invokeTestMethod(Invoker.java:869)
	at org.testng.internal.Invoker.invokeTestMethods(Invoker.java:1193)
	at org.testng.internal.TestMethodWorker.invokeTestMethods(TestMethodWorker.java:126)
	at org.testng.internal.TestMethodWorker.run(TestMethodWorker.java:109)
	at org.testng.TestRunner.privateRun(TestRunner.java:744)
	at org.testng.TestRunner.run(TestRunner.java:602)
	at org.testng.SuiteRunner.runTest(SuiteRunner.java:380)
	at org.testng.SuiteRunner.runSequentially(SuiteRunner.java:375)
	at org.testng.SuiteRunner.privateRun(SuiteRunner.java:340)
	at org.testng.SuiteRunner.run(SuiteRunner.java:289)
	at org.testng.SuiteRunnerWorker.runSuite(SuiteRunnerWorker.java:52)
	at org.testng.SuiteRunnerWorker.run(SuiteRunnerWorker.java:86)
	at org.testng.TestNG.runSuitesSequentially(TestNG.java:1301)
	at org.testng.TestNG.runSuitesLocally(TestNG.java:1226)
	at org.testng.TestNG.runSuites(TestNG.java:1144)
	at org.testng.TestNG.run(TestNG.java:1115)
	at org.testng.remote.AbstractRemoteTestNG.run(AbstractRemoteTestNG.java:115)
	at org.testng.remote.RemoteTestNG.initAndRun(RemoteTestNG.java:251)
	at org.testng.remote.RemoteTestNG.main(RemoteTestNG.java:77)
]]>
            </full-stacktrace>
          </exception> <!-- java.lang.AssertionError -->
          <reporter-output>
          </reporter-output>
        </test-method> <!-- transactionResetFunctionalities -->
        <test-method signature="transactionBackFunctionalities()[pri:31, instance:com.crm.qa.testcases.CustomerLoginFunctionalitiesTest@b4711e2]" started-at="2024-03-13T00:30:46Z" name="transactionBackFunctionalities" finished-at="2024-03-13T00:30:46Z" duration-ms="274" status="PASS">
          <reporter-output>
          </reporter-output>
        </test-method> <!-- transactionBackFunctionalities -->
        <test-method signature="VerifyLogoutFunctionality()[pri:32, instance:com.crm.qa.testcases.CustomerLoginFunctionalitiesTest@b4711e2]" started-at="2024-03-13T00:30:46Z" name="VerifyLogoutFunctionality" finished-at="2024-03-13T00:30:46Z" duration-ms="386" status="PASS">
          <reporter-output>
          </reporter-output>
        </test-method> <!-- VerifyLogoutFunctionality -->
        <test-method signature="VerifyPostLogoutFunctionality()[pri:33, instance:com.crm.qa.testcases.CustomerLoginFunctionalitiesTest@b4711e2]" started-at="2024-03-13T00:30:46Z" name="VerifyPostLogoutFunctionality" finished-at="2024-03-13T00:30:47Z" duration-ms="412" status="FAIL">
          <exception class="java.lang.AssertionError">
            <message>
              <![CDATA[Customer is able to visit the session after logging out. New issue expected [Customer is not able to visit the session after logging out.] but found [Customer is able to visit the session after logging out. New issue]]]>
            </message>
            <full-stacktrace>
              <![CDATA[java.lang.AssertionError: Customer is able to visit the session after logging out. New issue expected [Customer is not able to visit the session after logging out.] but found [Customer is able to visit the session after logging out. New issue]
	at org.testng.Assert.fail(Assert.java:93)
	at org.testng.Assert.failNotEquals(Assert.java:512)
	at org.testng.Assert.assertEqualsImpl(Assert.java:134)
	at org.testng.Assert.assertEquals(Assert.java:115)
	at org.testng.Assert.assertEquals(Assert.java:189)
	at com.crm.qa.testcases.CustomerLoginFunctionalitiesTest.VerifyPostLogoutFunctionality(CustomerLoginFunctionalitiesTest.java:115)
	at java.base/jdk.internal.reflect.NativeMethodAccessorImpl.invoke0(Native Method)
	at java.base/jdk.internal.reflect.NativeMethodAccessorImpl.invoke(NativeMethodAccessorImpl.java:77)
	at java.base/jdk.internal.reflect.DelegatingMethodAccessorImpl.invoke(DelegatingMethodAccessorImpl.java:43)
	at java.base/java.lang.reflect.Method.invoke(Method.java:568)
	at org.testng.internal.MethodInvocationHelper.invokeMethod(MethodInvocationHelper.java:108)
	at org.testng.internal.Invoker.invokeMethod(Invoker.java:661)
	at org.testng.internal.Invoker.invokeTestMethod(Invoker.java:869)
	at org.testng.internal.Invoker.invokeTestMethods(Invoker.java:1193)
	at org.testng.internal.TestMethodWorker.invokeTestMethods(TestMethodWorker.java:126)
	at org.testng.internal.TestMethodWorker.run(TestMethodWorker.java:109)
	at org.testng.TestRunner.privateRun(TestRunner.java:744)
	at org.testng.TestRunner.run(TestRunner.java:602)
	at org.testng.SuiteRunner.runTest(SuiteRunner.java:380)
	at org.testng.SuiteRunner.runSequentially(SuiteRunner.java:375)
	at org.testng.SuiteRunner.privateRun(SuiteRunner.java:340)
	at org.testng.SuiteRunner.run(SuiteRunner.java:289)
	at org.testng.SuiteRunnerWorker.runSuite(SuiteRunnerWorker.java:52)
	at org.testng.SuiteRunnerWorker.run(SuiteRunnerWorker.java:86)
	at org.testng.TestNG.runSuitesSequentially(TestNG.java:1301)
	at org.testng.TestNG.runSuitesLocally(TestNG.java:1226)
	at org.testng.TestNG.runSuites(TestNG.java:1144)
	at org.testng.TestNG.run(TestNG.java:1115)
	at org.testng.remote.AbstractRemoteTestNG.run(AbstractRemoteTestNG.java:115)
	at org.testng.remote.RemoteTestNG.initAndRun(RemoteTestNG.java:251)
	at org.testng.remote.RemoteTestNG.main(RemoteTestNG.java:77)
]]>
            </full-stacktrace>
          </exception> <!-- java.lang.AssertionError -->
          <reporter-output>
          </reporter-output>
        </test-method> <!-- VerifyPostLogoutFunctionality -->
        <test-method signature="VerifyredirectToNonaccessablePageFunctionality()[pri:34, instance:com.crm.qa.testcases.CustomerLoginFunctionalitiesTest@b4711e2]" started-at="2024-03-13T00:30:47Z" name="VerifyredirectToNonaccessablePageFunctionality" finished-at="2024-03-13T00:30:47Z" duration-ms="302" status="FAIL">
          <exception class="java.lang.AssertionError">
            <message>
              <![CDATA[Customer is able to access the account after logging out. New issue expected [Customer is not access the account after logging out.] but found [Customer is able to access the account after logging out. New issue]]]>
            </message>
            <full-stacktrace>
              <![CDATA[java.lang.AssertionError: Customer is able to access the account after logging out. New issue expected [Customer is not access the account after logging out.] but found [Customer is able to access the account after logging out. New issue]
	at org.testng.Assert.fail(Assert.java:93)
	at org.testng.Assert.failNotEquals(Assert.java:512)
	at org.testng.Assert.assertEqualsImpl(Assert.java:134)
	at org.testng.Assert.assertEquals(Assert.java:115)
	at org.testng.Assert.assertEquals(Assert.java:189)
	at com.crm.qa.testcases.CustomerLoginFunctionalitiesTest.VerifyredirectToNonaccessablePageFunctionality(CustomerLoginFunctionalitiesTest.java:120)
	at java.base/jdk.internal.reflect.NativeMethodAccessorImpl.invoke0(Native Method)
	at java.base/jdk.internal.reflect.NativeMethodAccessorImpl.invoke(NativeMethodAccessorImpl.java:77)
	at java.base/jdk.internal.reflect.DelegatingMethodAccessorImpl.invoke(DelegatingMethodAccessorImpl.java:43)
	at java.base/java.lang.reflect.Method.invoke(Method.java:568)
	at org.testng.internal.MethodInvocationHelper.invokeMethod(MethodInvocationHelper.java:108)
	at org.testng.internal.Invoker.invokeMethod(Invoker.java:661)
	at org.testng.internal.Invoker.invokeTestMethod(Invoker.java:869)
	at org.testng.internal.Invoker.invokeTestMethods(Invoker.java:1193)
	at org.testng.internal.TestMethodWorker.invokeTestMethods(TestMethodWorker.java:126)
	at org.testng.internal.TestMethodWorker.run(TestMethodWorker.java:109)
	at org.testng.TestRunner.privateRun(TestRunner.java:744)
	at org.testng.TestRunner.run(TestRunner.java:602)
	at org.testng.SuiteRunner.runTest(SuiteRunner.java:380)
	at org.testng.SuiteRunner.runSequentially(SuiteRunner.java:375)
	at org.testng.SuiteRunner.privateRun(SuiteRunner.java:340)
	at org.testng.SuiteRunner.run(SuiteRunner.java:289)
	at org.testng.SuiteRunnerWorker.runSuite(SuiteRunnerWorker.java:52)
	at org.testng.SuiteRunnerWorker.run(SuiteRunnerWorker.java:86)
	at org.testng.TestNG.runSuitesSequentially(TestNG.java:1301)
	at org.testng.TestNG.runSuitesLocally(TestNG.java:1226)
	at org.testng.TestNG.runSuites(TestNG.java:1144)
	at org.testng.TestNG.run(TestNG.java:1115)
	at org.testng.remote.AbstractRemoteTestNG.run(AbstractRemoteTestNG.java:115)
	at org.testng.remote.RemoteTestNG.initAndRun(RemoteTestNG.java:251)
	at org.testng.remote.RemoteTestNG.main(RemoteTestNG.java:77)
]]>
            </full-stacktrace>
          </exception> <!-- java.lang.AssertionError -->
          <reporter-output>
          </reporter-output>
        </test-method> <!-- VerifyredirectToNonaccessablePageFunctionality -->
        <test-method is-config="true" signature="tearDown()[pri:0, instance:com.crm.qa.testcases.CustomerLoginFunctionalitiesTest@b4711e2]" started-at="2024-03-13T00:30:47Z" name="tearDown" finished-at="2024-03-13T00:30:48Z" duration-ms="481" status="PASS">
          <reporter-output>
          </reporter-output>
        </test-method> <!-- tearDown -->
      </class> <!-- com.crm.qa.testcases.CustomerLoginFunctionalitiesTest -->
      <class name="com.crm.qa.testcases.HomeDashBoardTest">
        <test-method is-config="true" signature="setUp(java.lang.String)[pri:0, instance:com.crm.qa.testcases.HomeDashBoardTest@56673b2c]" started-at="2024-03-13T00:29:33Z" name="setUp" finished-at="2024-03-13T00:29:47Z" duration-ms="13969" status="PASS">
          <params>
            <param index="0">
              <value>
                <![CDATA[edge]]>
              </value>
            </param>
          </params>
          <reporter-output>
          </reporter-output>
        </test-method> <!-- setUp -->
        <test-method signature="VerifyTitle()[pri:1, instance:com.crm.qa.testcases.HomeDashBoardTest@56673b2c]" started-at="2024-03-13T00:29:47Z" name="VerifyTitle" finished-at="2024-03-13T00:29:48Z" duration-ms="660" status="PASS">
          <reporter-output>
          </reporter-output>
        </test-method> <!-- VerifyTitle -->
        <test-method signature="VerifyHomeBtn()[pri:2, instance:com.crm.qa.testcases.HomeDashBoardTest@56673b2c]" started-at="2024-03-13T00:29:48Z" name="VerifyHomeBtn" finished-at="2024-03-13T00:29:48Z" duration-ms="78" status="PASS">
          <reporter-output>
          </reporter-output>
        </test-method> <!-- VerifyHomeBtn -->
        <test-method signature="VerifycustLoginBtn()[pri:3, instance:com.crm.qa.testcases.HomeDashBoardTest@56673b2c]" started-at="2024-03-13T00:29:48Z" name="VerifycustLoginBtn" finished-at="2024-03-13T00:29:48Z" duration-ms="65" status="PASS">
          <reporter-output>
          </reporter-output>
        </test-method> <!-- VerifycustLoginBtn -->
        <test-method signature="VerifybankManagerLoginBtn()[pri:4, instance:com.crm.qa.testcases.HomeDashBoardTest@56673b2c]" started-at="2024-03-13T00:29:48Z" name="VerifybankManagerLoginBtn" finished-at="2024-03-13T00:29:48Z" duration-ms="79" status="PASS">
          <reporter-output>
          </reporter-output>
        </test-method> <!-- VerifybankManagerLoginBtn -->
        <test-method signature="VerifyHomeBtnFunctionality()[pri:5, instance:com.crm.qa.testcases.HomeDashBoardTest@56673b2c]" started-at="2024-03-13T00:29:48Z" name="VerifyHomeBtnFunctionality" finished-at="2024-03-13T00:29:48Z" duration-ms="332" status="PASS">
          <reporter-output>
          </reporter-output>
        </test-method> <!-- VerifyHomeBtnFunctionality -->
        <test-method signature="VerifycustLoginBtnFunctionality()[pri:6, instance:com.crm.qa.testcases.HomeDashBoardTest@56673b2c]" started-at="2024-03-13T00:29:48Z" name="VerifycustLoginBtnFunctionality" finished-at="2024-03-13T00:29:49Z" duration-ms="526" status="PASS">
          <reporter-output>
          </reporter-output>
        </test-method> <!-- VerifycustLoginBtnFunctionality -->
        <test-method signature="VerifybankManagerLoginBtnFunctionality()[pri:7, instance:com.crm.qa.testcases.HomeDashBoardTest@56673b2c]" started-at="2024-03-13T00:29:49Z" name="VerifybankManagerLoginBtnFunctionality" finished-at="2024-03-13T00:29:50Z" duration-ms="566" status="PASS">
          <reporter-output>
          </reporter-output>
        </test-method> <!-- VerifybankManagerLoginBtnFunctionality -->
        <test-method signature="VerifyNonAccountCustomersFunctionality()[pri:8, instance:com.crm.qa.testcases.HomeDashBoardTest@56673b2c]" started-at="2024-03-13T00:29:50Z" name="VerifyNonAccountCustomersFunctionality" finished-at="2024-03-13T00:29:53Z" duration-ms="3442" status="PASS">
          <reporter-output>
          </reporter-output>
        </test-method> <!-- VerifyNonAccountCustomersFunctionality -->
        <test-method is-config="true" signature="tearDown()[pri:0, instance:com.crm.qa.testcases.HomeDashBoardTest@56673b2c]" started-at="2024-03-13T00:29:53Z" name="tearDown" finished-at="2024-03-13T00:29:53Z" duration-ms="440" status="PASS">
          <reporter-output>
          </reporter-output>
        </test-method> <!-- tearDown -->
      </class> <!-- com.crm.qa.testcases.HomeDashBoardTest -->
      <class name="com.crm.qa.testcases.BankManagerLoginFunctionalitiesTest">
        <test-method is-config="true" signature="setUp(java.lang.String)[pri:0, instance:com.crm.qa.testcases.BankManagerLoginFunctionalitiesTest@2796aeae]" started-at="2024-03-13T00:29:53Z" name="setUp" finished-at="2024-03-13T00:29:57Z" duration-ms="3531" status="PASS">
          <params>
            <param index="0">
              <value>
                <![CDATA[edge]]>
              </value>
            </param>
          </params>
          <reporter-output>
          </reporter-output>
        </test-method> <!-- setUp -->
        <test-method signature="VerifyBankManagerLoginBtnFunctionality()[pri:9, instance:com.crm.qa.testcases.BankManagerLoginFunctionalitiesTest@2796aeae]" started-at="2024-03-13T00:29:57Z" name="VerifyBankManagerLoginBtnFunctionality" finished-at="2024-03-13T00:29:59Z" duration-ms="1733" status="PASS">
          <reporter-output>
          </reporter-output>
        </test-method> <!-- VerifyBankManagerLoginBtnFunctionality -->
        <test-method signature="VerifyBankManagerLogin()[pri:10, instance:com.crm.qa.testcases.BankManagerLoginFunctionalitiesTest@2796aeae]" started-at="2024-03-13T00:29:59Z" name="VerifyBankManagerLogin" finished-at="2024-03-13T00:30:00Z" duration-ms="1644" status="PASS">
          <reporter-output>
          </reporter-output>
        </test-method> <!-- VerifyBankManagerLogin -->
        <test-method signature="VerifyInvalidFnameBankManagerLogin()[pri:11, instance:com.crm.qa.testcases.BankManagerLoginFunctionalitiesTest@2796aeae]" started-at="2024-03-13T00:30:00Z" name="VerifyInvalidFnameBankManagerLogin" finished-at="2024-03-13T00:30:02Z" duration-ms="1550" status="FAIL">
          <exception class="java.lang.AssertionError">
            <message>
              <![CDATA[First name is containing special characters and numbers. New issue expected [Pop-up validation: Unexpected or no success message] but found [Pop-up validation: Customer added successfully]]]>
            </message>
            <full-stacktrace>
              <![CDATA[java.lang.AssertionError: First name is containing special characters and numbers. New issue expected [Pop-up validation: Unexpected or no success message] but found [Pop-up validation: Customer added successfully]
	at org.testng.Assert.fail(Assert.java:93)
	at org.testng.Assert.failNotEquals(Assert.java:512)
	at org.testng.Assert.assertEqualsImpl(Assert.java:134)
	at org.testng.Assert.assertEquals(Assert.java:115)
	at org.testng.Assert.assertEquals(Assert.java:189)
	at com.crm.qa.testcases.BankManagerLoginFunctionalitiesTest.VerifyInvalidFnameBankManagerLogin(BankManagerLoginFunctionalitiesTest.java:44)
	at java.base/jdk.internal.reflect.NativeMethodAccessorImpl.invoke0(Native Method)
	at java.base/jdk.internal.reflect.NativeMethodAccessorImpl.invoke(NativeMethodAccessorImpl.java:77)
	at java.base/jdk.internal.reflect.DelegatingMethodAccessorImpl.invoke(DelegatingMethodAccessorImpl.java:43)
	at java.base/java.lang.reflect.Method.invoke(Method.java:568)
	at org.testng.internal.MethodInvocationHelper.invokeMethod(MethodInvocationHelper.java:108)
	at org.testng.internal.Invoker.invokeMethod(Invoker.java:661)
	at org.testng.internal.Invoker.invokeTestMethod(Invoker.java:869)
	at org.testng.internal.Invoker.invokeTestMethods(Invoker.java:1193)
	at org.testng.internal.TestMethodWorker.invokeTestMethods(TestMethodWorker.java:126)
	at org.testng.internal.TestMethodWorker.run(TestMethodWorker.java:109)
	at org.testng.TestRunner.privateRun(TestRunner.java:744)
	at org.testng.TestRunner.run(TestRunner.java:602)
	at org.testng.SuiteRunner.runTest(SuiteRunner.java:380)
	at org.testng.SuiteRunner.runSequentially(SuiteRunner.java:375)
	at org.testng.SuiteRunner.privateRun(SuiteRunner.java:340)
	at org.testng.SuiteRunner.run(SuiteRunner.java:289)
	at org.testng.SuiteRunnerWorker.runSuite(SuiteRunnerWorker.java:52)
	at org.testng.SuiteRunnerWorker.run(SuiteRunnerWorker.java:86)
	at org.testng.TestNG.runSuitesSequentially(TestNG.java:1301)
	at org.testng.TestNG.runSuitesLocally(TestNG.java:1226)
	at org.testng.TestNG.runSuites(TestNG.java:1144)
	at org.testng.TestNG.run(TestNG.java:1115)
	at org.testng.remote.AbstractRemoteTestNG.run(AbstractRemoteTestNG.java:115)
	at org.testng.remote.RemoteTestNG.initAndRun(RemoteTestNG.java:251)
	at org.testng.remote.RemoteTestNG.main(RemoteTestNG.java:77)
]]>
            </full-stacktrace>
          </exception> <!-- java.lang.AssertionError -->
          <reporter-output>
          </reporter-output>
        </test-method> <!-- VerifyInvalidFnameBankManagerLogin -->
        <test-method signature="VerifyInvalidLnameBankManagerLogin()[pri:12, instance:com.crm.qa.testcases.BankManagerLoginFunctionalitiesTest@2796aeae]" started-at="2024-03-13T00:30:02Z" name="VerifyInvalidLnameBankManagerLogin" finished-at="2024-03-13T00:30:03Z" duration-ms="1068" status="FAIL">
          <exception class="java.lang.AssertionError">
            <message>
              <![CDATA[Last name is containing special characters and numbers. New issue expected [Pop-up validation: Unexpected or no success message] but found [Pop-up validation: Customer added successfully]]]>
            </message>
            <full-stacktrace>
              <![CDATA[java.lang.AssertionError: Last name is containing special characters and numbers. New issue expected [Pop-up validation: Unexpected or no success message] but found [Pop-up validation: Customer added successfully]
	at org.testng.Assert.fail(Assert.java:93)
	at org.testng.Assert.failNotEquals(Assert.java:512)
	at org.testng.Assert.assertEqualsImpl(Assert.java:134)
	at org.testng.Assert.assertEquals(Assert.java:115)
	at org.testng.Assert.assertEquals(Assert.java:189)
	at com.crm.qa.testcases.BankManagerLoginFunctionalitiesTest.VerifyInvalidLnameBankManagerLogin(BankManagerLoginFunctionalitiesTest.java:49)
	at java.base/jdk.internal.reflect.NativeMethodAccessorImpl.invoke0(Native Method)
	at java.base/jdk.internal.reflect.NativeMethodAccessorImpl.invoke(NativeMethodAccessorImpl.java:77)
	at java.base/jdk.internal.reflect.DelegatingMethodAccessorImpl.invoke(DelegatingMethodAccessorImpl.java:43)
	at java.base/java.lang.reflect.Method.invoke(Method.java:568)
	at org.testng.internal.MethodInvocationHelper.invokeMethod(MethodInvocationHelper.java:108)
	at org.testng.internal.Invoker.invokeMethod(Invoker.java:661)
	at org.testng.internal.Invoker.invokeTestMethod(Invoker.java:869)
	at org.testng.internal.Invoker.invokeTestMethods(Invoker.java:1193)
	at org.testng.internal.TestMethodWorker.invokeTestMethods(TestMethodWorker.java:126)
	at org.testng.internal.TestMethodWorker.run(TestMethodWorker.java:109)
	at org.testng.TestRunner.privateRun(TestRunner.java:744)
	at org.testng.TestRunner.run(TestRunner.java:602)
	at org.testng.SuiteRunner.runTest(SuiteRunner.java:380)
	at org.testng.SuiteRunner.runSequentially(SuiteRunner.java:375)
	at org.testng.SuiteRunner.privateRun(SuiteRunner.java:340)
	at org.testng.SuiteRunner.run(SuiteRunner.java:289)
	at org.testng.SuiteRunnerWorker.runSuite(SuiteRunnerWorker.java:52)
	at org.testng.SuiteRunnerWorker.run(SuiteRunnerWorker.java:86)
	at org.testng.TestNG.runSuitesSequentially(TestNG.java:1301)
	at org.testng.TestNG.runSuitesLocally(TestNG.java:1226)
	at org.testng.TestNG.runSuites(TestNG.java:1144)
	at org.testng.TestNG.run(TestNG.java:1115)
	at org.testng.remote.AbstractRemoteTestNG.run(AbstractRemoteTestNG.java:115)
	at org.testng.remote.RemoteTestNG.initAndRun(RemoteTestNG.java:251)
	at org.testng.remote.RemoteTestNG.main(RemoteTestNG.java:77)
]]>
            </full-stacktrace>
          </exception> <!-- java.lang.AssertionError -->
          <reporter-output>
          </reporter-output>
        </test-method> <!-- VerifyInvalidLnameBankManagerLogin -->
        <test-method signature="VerifyEmptyFieldBankManagerLogin()[pri:13, instance:com.crm.qa.testcases.BankManagerLoginFunctionalitiesTest@2796aeae]" started-at="2024-03-13T00:30:03Z" name="VerifyEmptyFieldBankManagerLogin" finished-at="2024-03-13T00:30:07Z" duration-ms="3997" status="PASS">
          <reporter-output>
          </reporter-output>
        </test-method> <!-- VerifyEmptyFieldBankManagerLogin -->
        <test-method signature="VerifyDuplicateBankManagerLogin()[pri:14, instance:com.crm.qa.testcases.BankManagerLoginFunctionalitiesTest@2796aeae]" started-at="2024-03-13T00:30:07Z" name="VerifyDuplicateBankManagerLogin" finished-at="2024-03-13T00:30:11Z" duration-ms="3958" status="PASS">
          <reporter-output>
          </reporter-output>
        </test-method> <!-- VerifyDuplicateBankManagerLogin -->
        <test-method signature="VerifyOpenAccountFunctionality()[pri:15, instance:com.crm.qa.testcases.BankManagerLoginFunctionalitiesTest@2796aeae]" started-at="2024-03-13T00:30:11Z" name="VerifyOpenAccountFunctionality" finished-at="2024-03-13T00:30:15Z" duration-ms="4275" status="PASS">
          <reporter-output>
          </reporter-output>
        </test-method> <!-- VerifyOpenAccountFunctionality -->
        <test-method signature="searchCustomersFunctionalityByName()[pri:16, instance:com.crm.qa.testcases.BankManagerLoginFunctionalitiesTest@2796aeae]" started-at="2024-03-13T00:30:15Z" name="searchCustomersFunctionalityByName" finished-at="2024-03-13T00:30:17Z" duration-ms="1701" status="PASS">
          <reporter-output>
          </reporter-output>
        </test-method> <!-- searchCustomersFunctionalityByName -->
        <test-method signature="searchCustomersFunctionalityByID()[pri:17, instance:com.crm.qa.testcases.BankManagerLoginFunctionalitiesTest@2796aeae]" started-at="2024-03-13T00:30:17Z" name="searchCustomersFunctionalityByID" finished-at="2024-03-13T00:30:18Z" duration-ms="549" status="PASS">
          <reporter-output>
          </reporter-output>
        </test-method> <!-- searchCustomersFunctionalityByID -->
        <test-method signature="searchCustomersFunctionalityByPostCode()[pri:18, instance:com.crm.qa.testcases.BankManagerLoginFunctionalitiesTest@2796aeae]" started-at="2024-03-13T00:30:18Z" name="searchCustomersFunctionalityByPostCode" finished-at="2024-03-13T00:30:18Z" duration-ms="543" status="PASS">
          <reporter-output>
          </reporter-output>
        </test-method> <!-- searchCustomersFunctionalityByPostCode -->
        <test-method signature="deleteCustomerFunctionality()[pri:19, instance:com.crm.qa.testcases.BankManagerLoginFunctionalitiesTest@2796aeae]" started-at="2024-03-13T00:30:18Z" name="deleteCustomerFunctionality" finished-at="2024-03-13T00:30:19Z" duration-ms="1305" status="PASS">
          <reporter-output>
          </reporter-output>
        </test-method> <!-- deleteCustomerFunctionality -->
        <test-method is-config="true" signature="tearDown()[pri:0, instance:com.crm.qa.testcases.BankManagerLoginFunctionalitiesTest@2796aeae]" started-at="2024-03-13T00:30:19Z" name="tearDown" finished-at="2024-03-13T00:30:20Z" duration-ms="470" status="PASS">
          <reporter-output>
          </reporter-output>
        </test-method> <!-- tearDown -->
      </class> <!-- com.crm.qa.testcases.BankManagerLoginFunctionalitiesTest -->
    </test> <!-- GWB-Tests-Edge -->
  </suite> <!-- Gringotts Wizarding Bank -->
</testng-results>
