<?xml version="1.0" encoding="UTF-8"?>
<testng-results ignored="0" total="32" passed="24" failed="8" skipped="0">
  <reporter-output>
  </reporter-output>
  <suite started-at="2024-03-07T12:15:42Z" name="Gringotts Wizarding Bank" finished-at="2024-03-07T12:16:22Z" duration-ms="39538">
    <groups>
    </groups>
    <test started-at="2024-03-07T12:15:42Z" name="GWB-Tests" finished-at="2024-03-07T12:16:22Z" duration-ms="39538">
      <class name="com.crm.qa.testcases.CustomerLoginFunctionalitiesTest">
        <test-method is-config="true" signature="setUp()[pri:0, instance:com.crm.qa.testcases.CustomerLoginFunctionalitiesTest@d771cc9]" started-at="2024-03-07T17:46:07Z" name="setUp" finished-at="2024-03-07T17:46:10Z" duration-ms="3087" status="PASS">
          <reporter-output>
          </reporter-output>
        </test-method> <!-- setUp -->
        <test-method signature="VerifycustLoginBtnFunctionality()[pri:19, instance:com.crm.qa.testcases.CustomerLoginFunctionalitiesTest@d771cc9]" started-at="2024-03-07T17:46:10Z" name="VerifycustLoginBtnFunctionality" finished-at="2024-03-07T17:46:12Z" duration-ms="1206" status="PASS">
          <reporter-output>
          </reporter-output>
        </test-method> <!-- VerifycustLoginBtnFunctionality -->
        <test-method signature="VerifyCustomerLogin()[pri:20, instance:com.crm.qa.testcases.CustomerLoginFunctionalitiesTest@d771cc9]" started-at="2024-03-07T17:46:12Z" name="VerifyCustomerLogin" finished-at="2024-03-07T17:46:13Z" duration-ms="990" status="PASS">
          <reporter-output>
          </reporter-output>
        </test-method> <!-- VerifyCustomerLogin -->
        <test-method signature="depositValidAmount()[pri:22, instance:com.crm.qa.testcases.CustomerLoginFunctionalitiesTest@d771cc9]" started-at="2024-03-07T17:46:13Z" name="depositValidAmount" finished-at="2024-03-07T17:46:14Z" duration-ms="1662" status="PASS">
          <reporter-output>
          </reporter-output>
        </test-method> <!-- depositValidAmount -->
        <test-method signature="depositInValidAmount()[pri:23, instance:com.crm.qa.testcases.CustomerLoginFunctionalitiesTest@d771cc9]" started-at="2024-03-07T17:46:14Z" name="depositInValidAmount" finished-at="2024-03-07T17:46:15Z" duration-ms="702" status="FAIL">
          <exception class="java.lang.AssertionError">
            <message>
              <![CDATA[No warning raised. New issue detected expected [Deposit Successful] but found [Invalid Input]]]>
            </message>
            <full-stacktrace>
              <![CDATA[java.lang.AssertionError: No warning raised. New issue detected expected [Deposit Successful] but found [Invalid Input]
	at org.testng.Assert.fail(Assert.java:93)
	at org.testng.Assert.failNotEquals(Assert.java:512)
	at org.testng.Assert.assertEqualsImpl(Assert.java:134)
	at org.testng.Assert.assertEquals(Assert.java:115)
	at org.testng.Assert.assertEquals(Assert.java:189)
	at com.crm.qa.testcases.CustomerLoginFunctionalitiesTest.depositInValidAmount(CustomerLoginFunctionalitiesTest.java:52)
	at java.base/jdk.internal.reflect.NativeMethodAccessorImpl.invoke0(Native Method)
	at java.base/jdk.internal.reflect.NativeMethodAccessorImpl.invoke(NativeMethodAccessorImpl.java:77)
	at java.base/jdk.internal.reflect.DelegatingMethodAccessorImpl.invoke(DelegatingMethodAccessorImpl.java:43)
	at java.base/java.lang.reflect.Method.invoke(Method.java:568)
	at org.testng.internal.MethodInvocationHelper.invokeMethod(MethodInvocationHelper.java:108)
	at org.testng.internal.Invoker.invokeMethod(Invoker.java:661)
	at org.testng.internal.Invoker.invokeTestMethod(Invoker.java:869)
	at org.testng.internal.Invoker.invokeTestMethods(Invoker.java:1193)
	at org.testng.internal.TestMethodWorker.invokeTestMethods(TestMethodWorker.java:126)
	at org.testng.internal.TestMethodWorker.run(TestMethodWorker.java:109)
	at org.testng.TestRunner.privateRun(TestRunner.java:744)
	at org.testng.TestRunner.run(TestRunner.java:602)
	at org.testng.SuiteRunner.runTest(SuiteRunner.java:380)
	at org.testng.SuiteRunner.runSequentially(SuiteRunner.java:375)
	at org.testng.SuiteRunner.privateRun(SuiteRunner.java:340)
	at org.testng.SuiteRunner.run(SuiteRunner.java:289)
	at org.testng.SuiteRunnerWorker.runSuite(SuiteRunnerWorker.java:52)
	at org.testng.SuiteRunnerWorker.run(SuiteRunnerWorker.java:86)
	at org.testng.TestNG.runSuitesSequentially(TestNG.java:1301)
	at org.testng.TestNG.runSuitesLocally(TestNG.java:1226)
	at org.testng.TestNG.runSuites(TestNG.java:1144)
	at org.testng.TestNG.run(TestNG.java:1115)
	at org.testng.remote.AbstractRemoteTestNG.run(AbstractRemoteTestNG.java:115)
	at org.testng.remote.RemoteTestNG.initAndRun(RemoteTestNG.java:251)
	at org.testng.remote.RemoteTestNG.main(RemoteTestNG.java:77)
]]>
            </full-stacktrace>
          </exception> <!-- java.lang.AssertionError -->
          <reporter-output>
          </reporter-output>
        </test-method> <!-- depositInValidAmount -->
        <test-method signature="depositDecimalAmount()[pri:24, instance:com.crm.qa.testcases.CustomerLoginFunctionalitiesTest@d771cc9]" started-at="2024-03-07T17:46:15Z" name="depositDecimalAmount" finished-at="2024-03-07T17:46:16Z" duration-ms="685" status="PASS">
          <reporter-output>
          </reporter-output>
        </test-method> <!-- depositDecimalAmount -->
        <test-method signature="withdrawValidAmount()[pri:25, instance:com.crm.qa.testcases.CustomerLoginFunctionalitiesTest@d771cc9]" started-at="2024-03-07T17:46:16Z" name="withdrawValidAmount" finished-at="2024-03-07T17:46:17Z" duration-ms="1472" status="PASS">
          <reporter-output>
          </reporter-output>
        </test-method> <!-- withdrawValidAmount -->
        <test-method signature="withdrawInValidAmount()[pri:26, instance:com.crm.qa.testcases.CustomerLoginFunctionalitiesTest@d771cc9]" started-at="2024-03-07T17:46:17Z" name="withdrawInValidAmount" finished-at="2024-03-07T17:46:18Z" duration-ms="1092" status="FAIL">
          <exception class="java.lang.AssertionError">
            <message>
              <![CDATA[No warning raised. New issue detected expected [Transaction successful] but found [Invalid Input]]]>
            </message>
            <full-stacktrace>
              <![CDATA[java.lang.AssertionError: No warning raised. New issue detected expected [Transaction successful] but found [Invalid Input]
	at org.testng.Assert.fail(Assert.java:93)
	at org.testng.Assert.failNotEquals(Assert.java:512)
	at org.testng.Assert.assertEqualsImpl(Assert.java:134)
	at org.testng.Assert.assertEquals(Assert.java:115)
	at org.testng.Assert.assertEquals(Assert.java:189)
	at com.crm.qa.testcases.CustomerLoginFunctionalitiesTest.withdrawInValidAmount(CustomerLoginFunctionalitiesTest.java:73)
	at java.base/jdk.internal.reflect.NativeMethodAccessorImpl.invoke0(Native Method)
	at java.base/jdk.internal.reflect.NativeMethodAccessorImpl.invoke(NativeMethodAccessorImpl.java:77)
	at java.base/jdk.internal.reflect.DelegatingMethodAccessorImpl.invoke(DelegatingMethodAccessorImpl.java:43)
	at java.base/java.lang.reflect.Method.invoke(Method.java:568)
	at org.testng.internal.MethodInvocationHelper.invokeMethod(MethodInvocationHelper.java:108)
	at org.testng.internal.Invoker.invokeMethod(Invoker.java:661)
	at org.testng.internal.Invoker.invokeTestMethod(Invoker.java:869)
	at org.testng.internal.Invoker.invokeTestMethods(Invoker.java:1193)
	at org.testng.internal.TestMethodWorker.invokeTestMethods(TestMethodWorker.java:126)
	at org.testng.internal.TestMethodWorker.run(TestMethodWorker.java:109)
	at org.testng.TestRunner.privateRun(TestRunner.java:744)
	at org.testng.TestRunner.run(TestRunner.java:602)
	at org.testng.SuiteRunner.runTest(SuiteRunner.java:380)
	at org.testng.SuiteRunner.runSequentially(SuiteRunner.java:375)
	at org.testng.SuiteRunner.privateRun(SuiteRunner.java:340)
	at org.testng.SuiteRunner.run(SuiteRunner.java:289)
	at org.testng.SuiteRunnerWorker.runSuite(SuiteRunnerWorker.java:52)
	at org.testng.SuiteRunnerWorker.run(SuiteRunnerWorker.java:86)
	at org.testng.TestNG.runSuitesSequentially(TestNG.java:1301)
	at org.testng.TestNG.runSuitesLocally(TestNG.java:1226)
	at org.testng.TestNG.runSuites(TestNG.java:1144)
	at org.testng.TestNG.run(TestNG.java:1115)
	at org.testng.remote.AbstractRemoteTestNG.run(AbstractRemoteTestNG.java:115)
	at org.testng.remote.RemoteTestNG.initAndRun(RemoteTestNG.java:251)
	at org.testng.remote.RemoteTestNG.main(RemoteTestNG.java:77)
]]>
            </full-stacktrace>
          </exception> <!-- java.lang.AssertionError -->
          <reporter-output>
          </reporter-output>
        </test-method> <!-- withdrawInValidAmount -->
        <test-method signature="withdrawDecimalAmount()[pri:27, instance:com.crm.qa.testcases.CustomerLoginFunctionalitiesTest@d771cc9]" started-at="2024-03-07T17:46:18Z" name="withdrawDecimalAmount" finished-at="2024-03-07T17:46:19Z" duration-ms="668" status="PASS">
          <reporter-output>
          </reporter-output>
        </test-method> <!-- withdrawDecimalAmount -->
        <test-method signature="withdrawInsufficientAmount()[pri:28, instance:com.crm.qa.testcases.CustomerLoginFunctionalitiesTest@d771cc9]" started-at="2024-03-07T17:46:19Z" name="withdrawInsufficientAmount" finished-at="2024-03-07T17:46:20Z" duration-ms="687" status="PASS">
          <reporter-output>
          </reporter-output>
        </test-method> <!-- withdrawInsufficientAmount -->
        <test-method signature="transactionResetFunctionalities()[pri:29, instance:com.crm.qa.testcases.CustomerLoginFunctionalitiesTest@d771cc9]" started-at="2024-03-07T17:46:20Z" name="transactionResetFunctionalities" finished-at="2024-03-07T17:46:20Z" duration-ms="791" status="FAIL">
          <exception class="java.lang.AssertionError">
            <message>
              <![CDATA[No warning raised. Major Issue detected. Balance is resetting, too. expected [Data reset successful] but found [Data reset unsuccessful]]]>
            </message>
            <full-stacktrace>
              <![CDATA[java.lang.AssertionError: No warning raised. Major Issue detected. Balance is resetting, too. expected [Data reset successful] but found [Data reset unsuccessful]
	at org.testng.Assert.fail(Assert.java:93)
	at org.testng.Assert.failNotEquals(Assert.java:512)
	at org.testng.Assert.assertEqualsImpl(Assert.java:134)
	at org.testng.Assert.assertEquals(Assert.java:115)
	at org.testng.Assert.assertEquals(Assert.java:189)
	at com.crm.qa.testcases.CustomerLoginFunctionalitiesTest.transactionResetFunctionalities(CustomerLoginFunctionalitiesTest.java:92)
	at java.base/jdk.internal.reflect.NativeMethodAccessorImpl.invoke0(Native Method)
	at java.base/jdk.internal.reflect.NativeMethodAccessorImpl.invoke(NativeMethodAccessorImpl.java:77)
	at java.base/jdk.internal.reflect.DelegatingMethodAccessorImpl.invoke(DelegatingMethodAccessorImpl.java:43)
	at java.base/java.lang.reflect.Method.invoke(Method.java:568)
	at org.testng.internal.MethodInvocationHelper.invokeMethod(MethodInvocationHelper.java:108)
	at org.testng.internal.Invoker.invokeMethod(Invoker.java:661)
	at org.testng.internal.Invoker.invokeTestMethod(Invoker.java:869)
	at org.testng.internal.Invoker.invokeTestMethods(Invoker.java:1193)
	at org.testng.internal.TestMethodWorker.invokeTestMethods(TestMethodWorker.java:126)
	at org.testng.internal.TestMethodWorker.run(TestMethodWorker.java:109)
	at org.testng.TestRunner.privateRun(TestRunner.java:744)
	at org.testng.TestRunner.run(TestRunner.java:602)
	at org.testng.SuiteRunner.runTest(SuiteRunner.java:380)
	at org.testng.SuiteRunner.runSequentially(SuiteRunner.java:375)
	at org.testng.SuiteRunner.privateRun(SuiteRunner.java:340)
	at org.testng.SuiteRunner.run(SuiteRunner.java:289)
	at org.testng.SuiteRunnerWorker.runSuite(SuiteRunnerWorker.java:52)
	at org.testng.SuiteRunnerWorker.run(SuiteRunnerWorker.java:86)
	at org.testng.TestNG.runSuitesSequentially(TestNG.java:1301)
	at org.testng.TestNG.runSuitesLocally(TestNG.java:1226)
	at org.testng.TestNG.runSuites(TestNG.java:1144)
	at org.testng.TestNG.run(TestNG.java:1115)
	at org.testng.remote.AbstractRemoteTestNG.run(AbstractRemoteTestNG.java:115)
	at org.testng.remote.RemoteTestNG.initAndRun(RemoteTestNG.java:251)
	at org.testng.remote.RemoteTestNG.main(RemoteTestNG.java:77)
]]>
            </full-stacktrace>
          </exception> <!-- java.lang.AssertionError -->
          <reporter-output>
          </reporter-output>
        </test-method> <!-- transactionResetFunctionalities -->
        <test-method signature="transactionBackFunctionalities()[pri:30, instance:com.crm.qa.testcases.CustomerLoginFunctionalitiesTest@d771cc9]" started-at="2024-03-07T17:46:20Z" name="transactionBackFunctionalities" finished-at="2024-03-07T17:46:21Z" duration-ms="230" status="PASS">
          <reporter-output>
          </reporter-output>
        </test-method> <!-- transactionBackFunctionalities -->
        <test-method signature="VerifyLogoutFunctionality()[pri:31, instance:com.crm.qa.testcases.CustomerLoginFunctionalitiesTest@d771cc9]" started-at="2024-03-07T17:46:21Z" name="VerifyLogoutFunctionality" finished-at="2024-03-07T17:46:21Z" duration-ms="278" status="PASS">
          <reporter-output>
          </reporter-output>
        </test-method> <!-- VerifyLogoutFunctionality -->
        <test-method signature="VerifyPostLogoutFunctionality()[pri:32, instance:com.crm.qa.testcases.CustomerLoginFunctionalitiesTest@d771cc9]" started-at="2024-03-07T17:46:21Z" name="VerifyPostLogoutFunctionality" finished-at="2024-03-07T17:46:21Z" duration-ms="308" status="FAIL">
          <exception class="java.lang.AssertionError">
            <message>
              <![CDATA[Customer is able to visit the session after logging out. New issue expected [Customer is not able to visit the session after logging out.] but found [Customer is able to visit the session after logging out. New issue]]]>
            </message>
            <full-stacktrace>
              <![CDATA[java.lang.AssertionError: Customer is able to visit the session after logging out. New issue expected [Customer is not able to visit the session after logging out.] but found [Customer is able to visit the session after logging out. New issue]
	at org.testng.Assert.fail(Assert.java:93)
	at org.testng.Assert.failNotEquals(Assert.java:512)
	at org.testng.Assert.assertEqualsImpl(Assert.java:134)
	at org.testng.Assert.assertEquals(Assert.java:115)
	at org.testng.Assert.assertEquals(Assert.java:189)
	at com.crm.qa.testcases.CustomerLoginFunctionalitiesTest.VerifyPostLogoutFunctionality(CustomerLoginFunctionalitiesTest.java:110)
	at java.base/jdk.internal.reflect.NativeMethodAccessorImpl.invoke0(Native Method)
	at java.base/jdk.internal.reflect.NativeMethodAccessorImpl.invoke(NativeMethodAccessorImpl.java:77)
	at java.base/jdk.internal.reflect.DelegatingMethodAccessorImpl.invoke(DelegatingMethodAccessorImpl.java:43)
	at java.base/java.lang.reflect.Method.invoke(Method.java:568)
	at org.testng.internal.MethodInvocationHelper.invokeMethod(MethodInvocationHelper.java:108)
	at org.testng.internal.Invoker.invokeMethod(Invoker.java:661)
	at org.testng.internal.Invoker.invokeTestMethod(Invoker.java:869)
	at org.testng.internal.Invoker.invokeTestMethods(Invoker.java:1193)
	at org.testng.internal.TestMethodWorker.invokeTestMethods(TestMethodWorker.java:126)
	at org.testng.internal.TestMethodWorker.run(TestMethodWorker.java:109)
	at org.testng.TestRunner.privateRun(TestRunner.java:744)
	at org.testng.TestRunner.run(TestRunner.java:602)
	at org.testng.SuiteRunner.runTest(SuiteRunner.java:380)
	at org.testng.SuiteRunner.runSequentially(SuiteRunner.java:375)
	at org.testng.SuiteRunner.privateRun(SuiteRunner.java:340)
	at org.testng.SuiteRunner.run(SuiteRunner.java:289)
	at org.testng.SuiteRunnerWorker.runSuite(SuiteRunnerWorker.java:52)
	at org.testng.SuiteRunnerWorker.run(SuiteRunnerWorker.java:86)
	at org.testng.TestNG.runSuitesSequentially(TestNG.java:1301)
	at org.testng.TestNG.runSuitesLocally(TestNG.java:1226)
	at org.testng.TestNG.runSuites(TestNG.java:1144)
	at org.testng.TestNG.run(TestNG.java:1115)
	at org.testng.remote.AbstractRemoteTestNG.run(AbstractRemoteTestNG.java:115)
	at org.testng.remote.RemoteTestNG.initAndRun(RemoteTestNG.java:251)
	at org.testng.remote.RemoteTestNG.main(RemoteTestNG.java:77)
]]>
            </full-stacktrace>
          </exception> <!-- java.lang.AssertionError -->
          <reporter-output>
          </reporter-output>
        </test-method> <!-- VerifyPostLogoutFunctionality -->
        <test-method signature="VerifyredirectToNonaccessablePageFunctionality()[pri:33, instance:com.crm.qa.testcases.CustomerLoginFunctionalitiesTest@d771cc9]" started-at="2024-03-07T17:46:21Z" name="VerifyredirectToNonaccessablePageFunctionality" finished-at="2024-03-07T17:46:21Z" duration-ms="277" status="FAIL">
          <exception class="java.lang.AssertionError">
            <message>
              <![CDATA[Customer is able to access the account after logging out. New issue expected [Customer is not access the account after logging out.] but found [Customer is able to access the account after logging out. New issue]]]>
            </message>
            <full-stacktrace>
              <![CDATA[java.lang.AssertionError: Customer is able to access the account after logging out. New issue expected [Customer is not access the account after logging out.] but found [Customer is able to access the account after logging out. New issue]
	at org.testng.Assert.fail(Assert.java:93)
	at org.testng.Assert.failNotEquals(Assert.java:512)
	at org.testng.Assert.assertEqualsImpl(Assert.java:134)
	at org.testng.Assert.assertEquals(Assert.java:115)
	at org.testng.Assert.assertEquals(Assert.java:189)
	at com.crm.qa.testcases.CustomerLoginFunctionalitiesTest.VerifyredirectToNonaccessablePageFunctionality(CustomerLoginFunctionalitiesTest.java:115)
	at java.base/jdk.internal.reflect.NativeMethodAccessorImpl.invoke0(Native Method)
	at java.base/jdk.internal.reflect.NativeMethodAccessorImpl.invoke(NativeMethodAccessorImpl.java:77)
	at java.base/jdk.internal.reflect.DelegatingMethodAccessorImpl.invoke(DelegatingMethodAccessorImpl.java:43)
	at java.base/java.lang.reflect.Method.invoke(Method.java:568)
	at org.testng.internal.MethodInvocationHelper.invokeMethod(MethodInvocationHelper.java:108)
	at org.testng.internal.Invoker.invokeMethod(Invoker.java:661)
	at org.testng.internal.Invoker.invokeTestMethod(Invoker.java:869)
	at org.testng.internal.Invoker.invokeTestMethods(Invoker.java:1193)
	at org.testng.internal.TestMethodWorker.invokeTestMethods(TestMethodWorker.java:126)
	at org.testng.internal.TestMethodWorker.run(TestMethodWorker.java:109)
	at org.testng.TestRunner.privateRun(TestRunner.java:744)
	at org.testng.TestRunner.run(TestRunner.java:602)
	at org.testng.SuiteRunner.runTest(SuiteRunner.java:380)
	at org.testng.SuiteRunner.runSequentially(SuiteRunner.java:375)
	at org.testng.SuiteRunner.privateRun(SuiteRunner.java:340)
	at org.testng.SuiteRunner.run(SuiteRunner.java:289)
	at org.testng.SuiteRunnerWorker.runSuite(SuiteRunnerWorker.java:52)
	at org.testng.SuiteRunnerWorker.run(SuiteRunnerWorker.java:86)
	at org.testng.TestNG.runSuitesSequentially(TestNG.java:1301)
	at org.testng.TestNG.runSuitesLocally(TestNG.java:1226)
	at org.testng.TestNG.runSuites(TestNG.java:1144)
	at org.testng.TestNG.run(TestNG.java:1115)
	at org.testng.remote.AbstractRemoteTestNG.run(AbstractRemoteTestNG.java:115)
	at org.testng.remote.RemoteTestNG.initAndRun(RemoteTestNG.java:251)
	at org.testng.remote.RemoteTestNG.main(RemoteTestNG.java:77)
]]>
            </full-stacktrace>
          </exception> <!-- java.lang.AssertionError -->
          <reporter-output>
          </reporter-output>
        </test-method> <!-- VerifyredirectToNonaccessablePageFunctionality -->
        <test-method is-config="true" signature="tearDown()[pri:0, instance:com.crm.qa.testcases.CustomerLoginFunctionalitiesTest@d771cc9]" started-at="2024-03-07T17:46:21Z" name="tearDown" finished-at="2024-03-07T17:46:22Z" duration-ms="522" status="PASS">
          <reporter-output>
          </reporter-output>
        </test-method> <!-- tearDown -->
      </class> <!-- com.crm.qa.testcases.CustomerLoginFunctionalitiesTest -->
      <class name="com.crm.qa.testcases.HomeDashBoardTest">
        <test-method is-config="true" signature="setUp()[pri:0, instance:com.crm.qa.testcases.HomeDashBoardTest@16eccb2e]" started-at="2024-03-07T17:45:42Z" name="setUp" finished-at="2024-03-07T17:45:48Z" duration-ms="5070" status="PASS">
          <reporter-output>
          </reporter-output>
        </test-method> <!-- setUp -->
        <test-method signature="VerifyTitle()[pri:1, instance:com.crm.qa.testcases.HomeDashBoardTest@16eccb2e]" started-at="2024-03-07T17:45:48Z" name="VerifyTitle" finished-at="2024-03-07T17:45:48Z" duration-ms="694" status="PASS">
          <reporter-output>
          </reporter-output>
        </test-method> <!-- VerifyTitle -->
        <test-method signature="VerifyHomeBtn()[pri:2, instance:com.crm.qa.testcases.HomeDashBoardTest@16eccb2e]" started-at="2024-03-07T17:45:48Z" name="VerifyHomeBtn" finished-at="2024-03-07T17:45:48Z" duration-ms="132" status="PASS">
          <reporter-output>
          </reporter-output>
        </test-method> <!-- VerifyHomeBtn -->
        <test-method signature="VerifycustLoginBtn()[pri:3, instance:com.crm.qa.testcases.HomeDashBoardTest@16eccb2e]" started-at="2024-03-07T17:45:48Z" name="VerifycustLoginBtn" finished-at="2024-03-07T17:45:48Z" duration-ms="98" status="PASS">
          <reporter-output>
          </reporter-output>
        </test-method> <!-- VerifycustLoginBtn -->
        <test-method signature="VerifybankManagerLoginBtn()[pri:4, instance:com.crm.qa.testcases.HomeDashBoardTest@16eccb2e]" started-at="2024-03-07T17:45:48Z" name="VerifybankManagerLoginBtn" finished-at="2024-03-07T17:45:49Z" duration-ms="70" status="PASS">
          <reporter-output>
          </reporter-output>
        </test-method> <!-- VerifybankManagerLoginBtn -->
        <test-method signature="VerifyHomeBtnFunctionality()[pri:5, instance:com.crm.qa.testcases.HomeDashBoardTest@16eccb2e]" started-at="2024-03-07T17:45:49Z" name="VerifyHomeBtnFunctionality" finished-at="2024-03-07T17:45:49Z" duration-ms="285" status="PASS">
          <reporter-output>
          </reporter-output>
        </test-method> <!-- VerifyHomeBtnFunctionality -->
        <test-method signature="VerifycustLoginBtnFunctionality()[pri:6, instance:com.crm.qa.testcases.HomeDashBoardTest@16eccb2e]" started-at="2024-03-07T17:45:49Z" name="VerifycustLoginBtnFunctionality" finished-at="2024-03-07T17:45:49Z" duration-ms="569" status="PASS">
          <reporter-output>
          </reporter-output>
        </test-method> <!-- VerifycustLoginBtnFunctionality -->
        <test-method signature="VerifybankManagerLoginBtnFunctionality()[pri:7, instance:com.crm.qa.testcases.HomeDashBoardTest@16eccb2e]" started-at="2024-03-07T17:45:49Z" name="VerifybankManagerLoginBtnFunctionality" finished-at="2024-03-07T17:45:50Z" duration-ms="572" status="PASS">
          <reporter-output>
          </reporter-output>
        </test-method> <!-- VerifybankManagerLoginBtnFunctionality -->
        <test-method is-config="true" signature="tearDown()[pri:0, instance:com.crm.qa.testcases.HomeDashBoardTest@16eccb2e]" started-at="2024-03-07T17:45:50Z" name="tearDown" finished-at="2024-03-07T17:45:50Z" duration-ms="416" status="PASS">
          <reporter-output>
          </reporter-output>
        </test-method> <!-- tearDown -->
      </class> <!-- com.crm.qa.testcases.HomeDashBoardTest -->
      <class name="com.crm.qa.testcases.BankManagerLoginFunctionalitiesTest">
        <test-method is-config="true" signature="setUp()[pri:0, instance:com.crm.qa.testcases.BankManagerLoginFunctionalitiesTest@5ef5c734]" started-at="2024-03-07T17:45:50Z" name="setUp" finished-at="2024-03-07T17:45:54Z" duration-ms="3338" status="PASS">
          <reporter-output>
          </reporter-output>
        </test-method> <!-- setUp -->
        <test-method signature="VerifyBankManagerLoginBtnFunctionality()[pri:8, instance:com.crm.qa.testcases.BankManagerLoginFunctionalitiesTest@5ef5c734]" started-at="2024-03-07T17:45:54Z" name="VerifyBankManagerLoginBtnFunctionality" finished-at="2024-03-07T17:45:55Z" duration-ms="1304" status="PASS">
          <reporter-output>
          </reporter-output>
        </test-method> <!-- VerifyBankManagerLoginBtnFunctionality -->
        <test-method signature="VerifyBankManagerLogin()[pri:9, instance:com.crm.qa.testcases.BankManagerLoginFunctionalitiesTest@5ef5c734]" started-at="2024-03-07T17:45:55Z" name="VerifyBankManagerLogin" finished-at="2024-03-07T17:45:56Z" duration-ms="1411" status="PASS">
          <reporter-output>
          </reporter-output>
        </test-method> <!-- VerifyBankManagerLogin -->
        <test-method signature="VerifyInvalidFnameBankManagerLogin()[pri:10, instance:com.crm.qa.testcases.BankManagerLoginFunctionalitiesTest@5ef5c734]" started-at="2024-03-07T17:45:56Z" name="VerifyInvalidFnameBankManagerLogin" finished-at="2024-03-07T17:45:57Z" duration-ms="989" status="FAIL">
          <exception class="java.lang.AssertionError">
            <message>
              <![CDATA[First name is containing special characters and numbers. New issue expected [Pop-up validation: Unexpected or no success message] but found [Pop-up validation: Customer added successfully]]]>
            </message>
            <full-stacktrace>
              <![CDATA[java.lang.AssertionError: First name is containing special characters and numbers. New issue expected [Pop-up validation: Unexpected or no success message] but found [Pop-up validation: Customer added successfully]
	at org.testng.Assert.fail(Assert.java:93)
	at org.testng.Assert.failNotEquals(Assert.java:512)
	at org.testng.Assert.assertEqualsImpl(Assert.java:134)
	at org.testng.Assert.assertEquals(Assert.java:115)
	at org.testng.Assert.assertEquals(Assert.java:189)
	at com.crm.qa.testcases.BankManagerLoginFunctionalitiesTest.VerifyInvalidFnameBankManagerLogin(BankManagerLoginFunctionalitiesTest.java:41)
	at java.base/jdk.internal.reflect.NativeMethodAccessorImpl.invoke0(Native Method)
	at java.base/jdk.internal.reflect.NativeMethodAccessorImpl.invoke(NativeMethodAccessorImpl.java:77)
	at java.base/jdk.internal.reflect.DelegatingMethodAccessorImpl.invoke(DelegatingMethodAccessorImpl.java:43)
	at java.base/java.lang.reflect.Method.invoke(Method.java:568)
	at org.testng.internal.MethodInvocationHelper.invokeMethod(MethodInvocationHelper.java:108)
	at org.testng.internal.Invoker.invokeMethod(Invoker.java:661)
	at org.testng.internal.Invoker.invokeTestMethod(Invoker.java:869)
	at org.testng.internal.Invoker.invokeTestMethods(Invoker.java:1193)
	at org.testng.internal.TestMethodWorker.invokeTestMethods(TestMethodWorker.java:126)
	at org.testng.internal.TestMethodWorker.run(TestMethodWorker.java:109)
	at org.testng.TestRunner.privateRun(TestRunner.java:744)
	at org.testng.TestRunner.run(TestRunner.java:602)
	at org.testng.SuiteRunner.runTest(SuiteRunner.java:380)
	at org.testng.SuiteRunner.runSequentially(SuiteRunner.java:375)
	at org.testng.SuiteRunner.privateRun(SuiteRunner.java:340)
	at org.testng.SuiteRunner.run(SuiteRunner.java:289)
	at org.testng.SuiteRunnerWorker.runSuite(SuiteRunnerWorker.java:52)
	at org.testng.SuiteRunnerWorker.run(SuiteRunnerWorker.java:86)
	at org.testng.TestNG.runSuitesSequentially(TestNG.java:1301)
	at org.testng.TestNG.runSuitesLocally(TestNG.java:1226)
	at org.testng.TestNG.runSuites(TestNG.java:1144)
	at org.testng.TestNG.run(TestNG.java:1115)
	at org.testng.remote.AbstractRemoteTestNG.run(AbstractRemoteTestNG.java:115)
	at org.testng.remote.RemoteTestNG.initAndRun(RemoteTestNG.java:251)
	at org.testng.remote.RemoteTestNG.main(RemoteTestNG.java:77)
]]>
            </full-stacktrace>
          </exception> <!-- java.lang.AssertionError -->
          <reporter-output>
          </reporter-output>
        </test-method> <!-- VerifyInvalidFnameBankManagerLogin -->
        <test-method signature="VerifyInvalidLnameBankManagerLogin()[pri:11, instance:com.crm.qa.testcases.BankManagerLoginFunctionalitiesTest@5ef5c734]" started-at="2024-03-07T17:45:57Z" name="VerifyInvalidLnameBankManagerLogin" finished-at="2024-03-07T17:45:58Z" duration-ms="993" status="FAIL">
          <exception class="java.lang.AssertionError">
            <message>
              <![CDATA[Last name is containing special characters and numbers. New issue expected [Pop-up validation: Unexpected or no success message] but found [Pop-up validation: Customer added successfully]]]>
            </message>
            <full-stacktrace>
              <![CDATA[java.lang.AssertionError: Last name is containing special characters and numbers. New issue expected [Pop-up validation: Unexpected or no success message] but found [Pop-up validation: Customer added successfully]
	at org.testng.Assert.fail(Assert.java:93)
	at org.testng.Assert.failNotEquals(Assert.java:512)
	at org.testng.Assert.assertEqualsImpl(Assert.java:134)
	at org.testng.Assert.assertEquals(Assert.java:115)
	at org.testng.Assert.assertEquals(Assert.java:189)
	at com.crm.qa.testcases.BankManagerLoginFunctionalitiesTest.VerifyInvalidLnameBankManagerLogin(BankManagerLoginFunctionalitiesTest.java:46)
	at java.base/jdk.internal.reflect.NativeMethodAccessorImpl.invoke0(Native Method)
	at java.base/jdk.internal.reflect.NativeMethodAccessorImpl.invoke(NativeMethodAccessorImpl.java:77)
	at java.base/jdk.internal.reflect.DelegatingMethodAccessorImpl.invoke(DelegatingMethodAccessorImpl.java:43)
	at java.base/java.lang.reflect.Method.invoke(Method.java:568)
	at org.testng.internal.MethodInvocationHelper.invokeMethod(MethodInvocationHelper.java:108)
	at org.testng.internal.Invoker.invokeMethod(Invoker.java:661)
	at org.testng.internal.Invoker.invokeTestMethod(Invoker.java:869)
	at org.testng.internal.Invoker.invokeTestMethods(Invoker.java:1193)
	at org.testng.internal.TestMethodWorker.invokeTestMethods(TestMethodWorker.java:126)
	at org.testng.internal.TestMethodWorker.run(TestMethodWorker.java:109)
	at org.testng.TestRunner.privateRun(TestRunner.java:744)
	at org.testng.TestRunner.run(TestRunner.java:602)
	at org.testng.SuiteRunner.runTest(SuiteRunner.java:380)
	at org.testng.SuiteRunner.runSequentially(SuiteRunner.java:375)
	at org.testng.SuiteRunner.privateRun(SuiteRunner.java:340)
	at org.testng.SuiteRunner.run(SuiteRunner.java:289)
	at org.testng.SuiteRunnerWorker.runSuite(SuiteRunnerWorker.java:52)
	at org.testng.SuiteRunnerWorker.run(SuiteRunnerWorker.java:86)
	at org.testng.TestNG.runSuitesSequentially(TestNG.java:1301)
	at org.testng.TestNG.runSuitesLocally(TestNG.java:1226)
	at org.testng.TestNG.runSuites(TestNG.java:1144)
	at org.testng.TestNG.run(TestNG.java:1115)
	at org.testng.remote.AbstractRemoteTestNG.run(AbstractRemoteTestNG.java:115)
	at org.testng.remote.RemoteTestNG.initAndRun(RemoteTestNG.java:251)
	at org.testng.remote.RemoteTestNG.main(RemoteTestNG.java:77)
]]>
            </full-stacktrace>
          </exception> <!-- java.lang.AssertionError -->
          <reporter-output>
          </reporter-output>
        </test-method> <!-- VerifyInvalidLnameBankManagerLogin -->
        <test-method signature="VerifyEmptyFieldBankManagerLogin()[pri:12, instance:com.crm.qa.testcases.BankManagerLoginFunctionalitiesTest@5ef5c734]" started-at="2024-03-07T17:45:58Z" name="VerifyEmptyFieldBankManagerLogin" finished-at="2024-03-07T17:46:01Z" duration-ms="2179" status="PASS">
          <reporter-output>
          </reporter-output>
        </test-method> <!-- VerifyEmptyFieldBankManagerLogin -->
        <test-method signature="VerifyDuplicateBankManagerLogin()[pri:13, instance:com.crm.qa.testcases.BankManagerLoginFunctionalitiesTest@5ef5c734]" started-at="2024-03-07T17:46:01Z" name="VerifyDuplicateBankManagerLogin" finished-at="2024-03-07T17:46:02Z" duration-ms="951" status="FAIL">
          <exception class="java.lang.AssertionError">
            <message>
              <![CDATA[Mandatory fields are not working. New issue. expected [Pop-up validation: Customer may be duplicate.] but found [Pop-up validation: Customer added successfully]]]>
            </message>
            <full-stacktrace>
              <![CDATA[java.lang.AssertionError: Mandatory fields are not working. New issue. expected [Pop-up validation: Customer may be duplicate.] but found [Pop-up validation: Customer added successfully]
	at org.testng.Assert.fail(Assert.java:93)
	at org.testng.Assert.failNotEquals(Assert.java:512)
	at org.testng.Assert.assertEqualsImpl(Assert.java:134)
	at org.testng.Assert.assertEquals(Assert.java:115)
	at org.testng.Assert.assertEquals(Assert.java:189)
	at com.crm.qa.testcases.BankManagerLoginFunctionalitiesTest.VerifyDuplicateBankManagerLogin(BankManagerLoginFunctionalitiesTest.java:57)
	at java.base/jdk.internal.reflect.NativeMethodAccessorImpl.invoke0(Native Method)
	at java.base/jdk.internal.reflect.NativeMethodAccessorImpl.invoke(NativeMethodAccessorImpl.java:77)
	at java.base/jdk.internal.reflect.DelegatingMethodAccessorImpl.invoke(DelegatingMethodAccessorImpl.java:43)
	at java.base/java.lang.reflect.Method.invoke(Method.java:568)
	at org.testng.internal.MethodInvocationHelper.invokeMethod(MethodInvocationHelper.java:108)
	at org.testng.internal.Invoker.invokeMethod(Invoker.java:661)
	at org.testng.internal.Invoker.invokeTestMethod(Invoker.java:869)
	at org.testng.internal.Invoker.invokeTestMethods(Invoker.java:1193)
	at org.testng.internal.TestMethodWorker.invokeTestMethods(TestMethodWorker.java:126)
	at org.testng.internal.TestMethodWorker.run(TestMethodWorker.java:109)
	at org.testng.TestRunner.privateRun(TestRunner.java:744)
	at org.testng.TestRunner.run(TestRunner.java:602)
	at org.testng.SuiteRunner.runTest(SuiteRunner.java:380)
	at org.testng.SuiteRunner.runSequentially(SuiteRunner.java:375)
	at org.testng.SuiteRunner.privateRun(SuiteRunner.java:340)
	at org.testng.SuiteRunner.run(SuiteRunner.java:289)
	at org.testng.SuiteRunnerWorker.runSuite(SuiteRunnerWorker.java:52)
	at org.testng.SuiteRunnerWorker.run(SuiteRunnerWorker.java:86)
	at org.testng.TestNG.runSuitesSequentially(TestNG.java:1301)
	at org.testng.TestNG.runSuitesLocally(TestNG.java:1226)
	at org.testng.TestNG.runSuites(TestNG.java:1144)
	at org.testng.TestNG.run(TestNG.java:1115)
	at org.testng.remote.AbstractRemoteTestNG.run(AbstractRemoteTestNG.java:115)
	at org.testng.remote.RemoteTestNG.initAndRun(RemoteTestNG.java:251)
	at org.testng.remote.RemoteTestNG.main(RemoteTestNG.java:77)
]]>
            </full-stacktrace>
          </exception> <!-- java.lang.AssertionError -->
          <reporter-output>
          </reporter-output>
        </test-method> <!-- VerifyDuplicateBankManagerLogin -->
        <test-method signature="VerifyOpenAccountFunctionality()[pri:14, instance:com.crm.qa.testcases.BankManagerLoginFunctionalitiesTest@5ef5c734]" started-at="2024-03-07T17:46:02Z" name="VerifyOpenAccountFunctionality" finished-at="2024-03-07T17:46:03Z" duration-ms="1779" status="PASS">
          <reporter-output>
          </reporter-output>
        </test-method> <!-- VerifyOpenAccountFunctionality -->
        <test-method signature="searchCustomersFunctionalityByName()[pri:15, instance:com.crm.qa.testcases.BankManagerLoginFunctionalitiesTest@5ef5c734]" started-at="2024-03-07T17:46:03Z" name="searchCustomersFunctionalityByName" finished-at="2024-03-07T17:46:04Z" duration-ms="957" status="PASS">
          <reporter-output>
          </reporter-output>
        </test-method> <!-- searchCustomersFunctionalityByName -->
        <test-method signature="searchCustomersFunctionalityByID()[pri:16, instance:com.crm.qa.testcases.BankManagerLoginFunctionalitiesTest@5ef5c734]" started-at="2024-03-07T17:46:04Z" name="searchCustomersFunctionalityByID" finished-at="2024-03-07T17:46:05Z" duration-ms="568" status="PASS">
          <reporter-output>
          </reporter-output>
        </test-method> <!-- searchCustomersFunctionalityByID -->
        <test-method signature="searchCustomersFunctionalityByPostCode()[pri:17, instance:com.crm.qa.testcases.BankManagerLoginFunctionalitiesTest@5ef5c734]" started-at="2024-03-07T17:46:05Z" name="searchCustomersFunctionalityByPostCode" finished-at="2024-03-07T17:46:05Z" duration-ms="580" status="PASS">
          <reporter-output>
          </reporter-output>
        </test-method> <!-- searchCustomersFunctionalityByPostCode -->
        <test-method signature="deleteCustomerFunctionality()[pri:18, instance:com.crm.qa.testcases.BankManagerLoginFunctionalitiesTest@5ef5c734]" started-at="2024-03-07T17:46:05Z" name="deleteCustomerFunctionality" finished-at="2024-03-07T17:46:07Z" duration-ms="1343" status="PASS">
          <reporter-output>
          </reporter-output>
        </test-method> <!-- deleteCustomerFunctionality -->
        <test-method is-config="true" signature="tearDown()[pri:0, instance:com.crm.qa.testcases.BankManagerLoginFunctionalitiesTest@5ef5c734]" started-at="2024-03-07T17:46:07Z" name="tearDown" finished-at="2024-03-07T17:46:07Z" duration-ms="410" status="PASS">
          <reporter-output>
          </reporter-output>
        </test-method> <!-- tearDown -->
      </class> <!-- com.crm.qa.testcases.BankManagerLoginFunctionalitiesTest -->
    </test> <!-- GWB-Tests -->
  </suite> <!-- Gringotts Wizarding Bank -->
</testng-results>
